Workbook
Name AA: recibos!$W$4
Name ABR_2013: recibos!$B$978:$AI$1162
Name AGO: 8
Name AGO_2013: recibos!$B$1763:$AI$1933
Name AGO_2013_A: recibos!$B$4:$AI$1933
Name BASE_A: base!$B$5:$K$446
Name BASE_B: base!$A$5:$B$446
Name BCO_ABR13: chequera!$B$52:$J$59
Name BCO_AGO13: chequera!$B$91:$J$96
Name BCO_AGO13_A: chequera!$B$3:$J$96
Name BCO_ENE13: chequera!$B$3:$J$22
Name BCO_FEB13: chequera!$B$23:$J$39
Name BCO_JUL13: chequera!$B$83:$J$90
Name BCO_JUL13_A: chequera!$B$3:$J$90
Name BCO_JUN13: chequera!$B$74:$J$82
Name BCO_JUN13_A: chequera!$B$3:$J$82
Name BCO_MAR13: chequera!$B$40:$J$51
Name BCO_MAY13: chequera!$B$61:$J$73
Name BCO_MAY13_A: chequera!$B$3:$J$73
Name BCO_SEP13: chequera!$B$97:$J$100
Name BCO_SEP13_A: chequera!$B$3:$J$100
Name Cafetales: criterios!$D$135:$E$136
Name CALLES: 'cobranza 2013'!$B$6:$J$448
Name Calzada_del_Hueso: criterios!$D$138:$E$139
Name Carmel: criterios!$FI$8:$FI$9
Name CL: criterios!$HS$2:$HS$3
Name CL_101_: criterios!$FF$2:$FG$3
Name CL_107_: criterios!$FH$2:$FI$3
Name CL_11_: criterios!$N$2:$O$3
Name CL_110_: criterios!$FJ$2:$FK$3
Name CL_111_: criterios!$FL$2:$FM$3
Name CL_112_PA: criterios!$FN$2:$FO$3
Name CL_112_PB: criterios!$FP$2:$FQ$3
Name CL_115_: criterios!$FR$2:$FS$3
Name CL_116_: criterios!$FT$2:$FU$3
Name CL_117_: criterios!$FV$2:$FW$3
Name CL_118_: criterios!$FX$2:$FY$3
Name CL_119_: criterios!$FZ$2:$GA$3
Name CL_12_: criterios!$P$2:$Q$3
Name CL_120_: criterios!$GB$2:$GC$3
Name CL_121_: criterios!$GD$2:$GE$3
Name CL_122_: criterios!$GF$2:$GG$3
Name CL_125_: criterios!$GH$2:$GI$3
Name CL_127_: criterios!$GJ$2:$GK$3
Name CL_129_: criterios!$GL$2:$GM$3
Name CL_13_: criterios!$R$2:$S$3
Name CL_130_: criterios!$GN$2:$GO$3
Name CL_131_: criterios!$GP$2:$GQ$3
Name CL_132_: criterios!$GR$2:$GS$3
Name CL_133_: criterios!$GT$2:$GU$3
Name CL_134_: criterios!$GV$2:$GW$3
Name CL_135_: criterios!$GX$2:$GY$3
Name CL_137_: criterios!$GZ$2:$HA$3
Name CL_139_: criterios!$HB$2:$HC$3
Name CL_14_: criterios!$T$2:$U$3
Name CL_141_: criterios!$HD$2:$HE$3
Name CL_144_: criterios!$HF$2:$HG$3
Name CL_145_: criterios!$HH$2:$HI$3
Name CL_147_: criterios!$HJ$2:$HK$3
Name CL_148_: criterios!$HL$2:$HM$3

Sheet base
B4: 1 | C4: 2 | D4: 3 | E4: 4 | F4: 5 | G4: 6 | H4: 7 | I4: 8 | J4: 9
A5: N° | B5: CASA | C5: CALLE | D5: N° | E5: INT | G5: DOMICILIO | H5: Domicilio | I5: FAMILIA | J5: CUOTA
A6: 1 | B6: =CONCATENATE(C6,"_",D6,"_",E6) -> CL_7_101 | C6: CL | D6: 7 | E6: 101 | F6: Rancho La Cuchilla | G6: =IF(E6=0,CONCATENATE(F6," No. ",D6),CONCATENATE(F6," No. ",D6,", ",E6)) -> Rancho La Cuchilla No. 7, 101 | H6: Cuchil 7-101 | I6: Olivares | J6: 100
A7: 2 | B7: =CONCATENATE(C7,"_",D7,"_",E7) -> CL_7_102 | C7: CL | D7: 7 | E7: 102 | F7: Rancho La Cuchilla | G7: =IF(E7=0,CONCATENATE(F7," No. ",D7),CONCATENATE(F7," No. ",D7,", ",E7)) -> Rancho La Cuchilla No. 7, 102 | H7: Cuhill 7- 102 | I7: García Moreno | J7: 100
A8: 3 | B8: =CONCATENATE(C8,"_",D8,"_",E8) -> CL_7_201 | C8: CL | D8: 7 | E8: 201 | F8: Rancho La Cuchilla | G8: =IF(E8=0,CONCATENATE(F8," No. ",D8),CONCATENATE(F8," No. ",D8,", ",E8)) -> Rancho La Cuchilla No. 7, 201 | H8: Cuchil 7-201 | I8: Solís Susana | J8: 100
A9: 4 | B9: =CONCATENATE(C9,"_",D9,"_",E9) -> CL_7_202 | C9: CL | D9: 7 | E9: 202 | F9: Rancho La Cuchilla | G9: =IF(E9=0,CONCATENATE(F9," No. ",D9),CONCATENATE(F9," No. ",D9,", ",E9)) -> Rancho La Cuchilla No. 7, 202 | H9: Cuc 7-202 | I9: Carbajal Zayas | J9: 100
A10: 5 | B10: =CONCATENATE(C10,"_",D10,"_",E10) -> CL_9_ | C10: CL | D10: 9 | F10: Rancho La Cuchilla | G10: =IF(E10=0,CONCATENATE(F10," No. ",D10),CONCATENATE(F10," No. ",D10,", ",E10)) -> Rancho La Cuchilla No. 9 | H10: Cuchi 9 | I10: Martín del Campo | J10: 300
A11: 6 | B11: =CONCATENATE(C11,"_",D11,"_",E11) -> CL_11_ | C11: CL | D11: 11 | F11: Rancho La Cuchilla | G11: =IF(E11=0,CONCATENATE(F11," No. ",D11),CONCATENATE(F11," No. ",D11,", ",E11)) -> Rancho La Cuchilla No. 11 | H11: Cuchi 11 | I11: Santiago | J11: 300
A12: 7 | B12: =CONCATENATE(C12,"_",D12,"_",E12) -> CL_12_ | C12: CL | D12: 12 | F12: Rancho La Cuchilla | G12: =IF(E12=0,CONCATENATE(F12," No. ",D12),CONCATENATE(F12," No. ",D12,", ",E12)) -> Rancho La Cuchilla No. 12 | H12: Cuchi 12C.E | I12: Rivera Flores | J12: 300
A13: 8 | B13: =CONCATENATE(C13,"_",D13,"_",E13) -> CL_13_ | C13: CL | D13: 13 | F13: Rancho La Cuchilla | G13: =IF(E13=0,CONCATENATE(F13," No. ",D13),CONCATENATE(F13," No. ",D13,", ",E13)) -> Rancho La Cuchilla No. 13 | H13: Cuchi 13 | I13: Torres | J13: 300
A14: 9 | B14: =CONCATENATE(C14,"_",D14,"_",E14) -> CL_14_ | C14: CL | D14: 14 | F14: Rancho La Cuchilla | G14: =IF(E14=0,CONCATENATE(F14," No. ",D14),CONCATENATE(F14," No. ",D14,", ",E14)) -> Rancho La Cuchilla No. 14 | H14: Cuchi 14 | I14: Chávez Lara | J14: 300
A15: 10 | B15: =CONCATENATE(C15,"_",D15,"_",E15) -> CL_15_ | C15: CL | D15: 15 | F15: Rancho La Cuchilla | G15: =IF(E15=0,CONCATENATE(F15," No. ",D15),CONCATENATE(F15," No. ",D15,", ",E15)) -> Rancho La Cuchilla No. 15 | H15: Cuchi 15 | I15: Guerrero Ponce | J15: 300
A16: 11 | B16: =CONCATENATE(C16,"_",D16,"_",E16) -> CL_18_ | C16: CL | D16: 18 | F16: Rancho La Cuchilla | G16: =IF(E16=0,CONCATENATE(F16," No. ",D16),CONCATENATE(F16," No. ",D16,", ",E16)) -> Rancho La Cuchilla No. 18 | H16: Cuc 18 C.E | I16: Aldana Sánchez | J16: 300
A17: 12 | B17: =CONCATENATE(C17,"_",D17,"_",E17) -> CL_19_ | C17: CL | D17: 19 | F17: Rancho La Cuchilla | G17: =IF(E17=0,CONCATENATE(F17," No. ",D17),CONCATENATE(F17," No. ",D17,", ",E17)) -> Rancho La Cuchilla No. 19 | H17: Cuchi 19 | I17: Tapia Vázquez | J17: 300
A18: 13 | B18: =CONCATENATE(C18,"_",D18,"_",E18) -> CL_20_ | C18: CL | D18: 20 | F18: Rancho La Cuchilla | G18: =IF(E18=0,CONCATENATE(F18," No. ",D18),CONCATENATE(F18," No. ",D18,", ",E18)) -> Rancho La Cuchilla No. 20 | H18: Cuc 20 C.EX | I18: Sánchez López | J18: 300
A19: 14 | B19: =CONCATENATE(C19,"_",D19,"_",E19) -> CL_21_ | C19: CL | D19: 21 | F19: Rancho La Cuchilla | G19: =IF(E19=0,CONCATENATE(F19," No. ",D19),CONCATENATE(F19," No. ",D19,", ",E19)) -> Rancho La Cuchilla No. 21 | H19: Cuch 21 C.E | I19: Solórzano Calderón | J19: 300
A20: 15 | B20: =CONCATENATE(C20,"_",D20,"_",E20) -> CL_23_ | C20: CL | D20: 23 | F20: Rancho La Cuchilla | G20: =IF(E20=0,CONCATENATE(F20," No. ",D20),CONCATENATE(F20," No. ",D20,", ",E20)) -> Rancho La Cuchilla No. 23 | H20: Cuchil 23 | I20: Ocampo | J20: 200
A21: 16 | B21: =CONCATENATE(C21,"_",D21,"_",E21) -> CL_25_ | C21: CL | D21: 25 | F21: Rancho La Cuchilla | G21: =IF(E21=0,CONCATENATE(F21," No. ",D21),CONCATENATE(F21," No. ",D21,", ",E21)) -> Rancho La Cuchilla No. 25 | H21: Cuchi 25 | I21: García de León | J21: 300
A22: 17 | B22: =CONCATENATE(C22,"_",D22,"_",E22) -> CL_27_ | C22: CL | D22: 27 | F22: Rancho La Cuchilla | G22: =IF(E22=0,CONCATENATE(F22," No. ",D22),CONCATENATE(F22," No. ",D22,", ",E22)) -> Rancho La Cuchilla No. 27 | H22: Cuchi 27 | I22: Montoya | J22: 300
A23: 18 | B23: =CONCATENATE(C23,"_",D23,"_",E23) -> CL_28_ | C23: CL | D23: 28 | F23: Rancho La Cuchilla | G23: =IF(E23=0,CONCATENATE(F23," No. ",D23),CONCATENATE(F23," No. ",D23,", ",E23)) -> Rancho La Cuchilla No. 28 | H23: Cuc 2 C. E | I23: Prado de los S. | J23: 300 | K23: Cambio de número de vivienda de 2 a 28. BS 14JUN13
A24: 19 | B24: =CONCATENATE(C24,"_",D24,"_",E24) -> CL_29_ | C24: CL | D24: 29 | F24: Rancho La Cuchilla | G24: =IF(E24=0,CONCATENATE(F24," No. ",D24),CONCATENATE(F24," No. ",D24,", ",E24)) -> Rancho La Cuchilla No. 29 | H24: Cuch 29 C.E | I24: Vega Sánchez C. | J24: 300
A25: 20 | B25: =CONCATENATE(C25,"_",D25,"_",E25) -> CL_30_ | C25: CL | D25: 30 | F25: Rancho La Cuchilla | G25: =IF(E25=0,CONCATENATE(F25," No. ",D25),CONCATENATE(F25," No. ",D25,", ",E25)) -> Rancho La Cuchilla No. 30 | H25: Cuchil 30 | I25: Ruiz Navarrete | J25: 300
A26: 21 | B26: =CONCATENATE(C26,"_",D26,"_",E26) -> CL_31_ | C26: CL | D26: 31 | F26: Rancho La Cuchilla | G26: =IF(E26=0,CONCATENATE(F26," No. ",D26),CONCATENATE(F26," No. ",D26,", ",E26)) -> Rancho La Cuchilla No. 31 | H26: Cuch 31 | I26: Espinoza Serrano | J26: 300
A27: 22 | B27: =CONCATENATE(C27,"_",D27,"_",E27) -> CL_32_ | C27: CL | D27: 32 | F27: Rancho La Cuchilla | G27: =IF(E27=0,CONCATENATE(F27," No. ",D27),CONCATENATE(F27," No. ",D27,", ",E27)) -> Rancho La Cuchilla No. 32 | H27: Cuchi 32 | I27: Hernández | J27: 300
A28: 23 | B28: =CONCATENATE(C28,"_",D28,"_",E28) -> CL_33_ | C28: CL | D28: 33 | F28: Rancho La Cuchilla | G28: =IF(E28=0,CONCATENATE(F28," No. ",D28),CONCATENATE(F28," No. ",D28,", ",E28)) -> Rancho La Cuchilla No. 33 | H28: Cuchi 33 C.E | I28: Tanús | J28: 300
A29: 24 | B29: =CONCATENATE(C29,"_",D29,"_",E29) -> CL_35_ | C29: CL | D29: 35 | F29: Rancho La Cuchilla | G29: =IF(E29=0,CONCATENATE(F29," No. ",D29),CONCATENATE(F29," No. ",D29,", ",E29)) -> Rancho La Cuchilla No. 35 | H29: Cuchill 35 | I29: Mendoza | J29: 150
A30: 25 | B30: =CONCATENATE(C30,"_",D30,"_",E30) -> CL_36_ | C30: CL | D30: 36 | F30: Rancho La Cuchilla | G30: =IF(E30=0,CONCATENATE(F30," No. ",D30),CONCATENATE(F30," No. ",D30,", ",E30)) -> Rancho La Cuchilla No. 36 | H30: Cuch 36 C.E | I30: Castillo | J30: 300
A31: 26 | B31: =CONCATENATE(C31,"_",D31,"_",E31) -> CL_38_ | C31: CL | D31: 38 | F31: Rancho La Cuchilla | G31: =IF(E31=0,CONCATENATE(F31," No. ",D31),CONCATENATE(F31," No. ",D31,", ",E31)) -> Rancho La Cuchilla No. 38 | H31: Cuchill 38 | I31: Cerecedo | J31: 300
A32: 27 | B32: =CONCATENATE(C32,"_",D32,"_",E32) -> CL_39_ | C32: CL | D32: 39 | F32: Rancho La Cuchilla | G32: =IF(E32=0,CONCATENATE(F32," No. ",D32),CONCATENATE(F32," No. ",D32,", ",E32)) -> Rancho La Cuchilla No. 39 | H32: Cuchill 39 | I32: Arenas | J32: 300
A33: 28 | B33: =CONCATENATE(C33,"_",D33,"_",E33) -> CL_40_ | C33: CL | D33: 40 | F33: Rancho La Cuchilla | G33: =IF(E33=0,CONCATENATE(F33," No. ",D33),CONCATENATE(F33," No. ",D33,", ",E33)) -> Rancho La Cuchilla No. 40 | H33: Cuchil 40 C.E | I33: López Pico | J33: 300
A34: 29 | B34: =CONCATENATE(C34,"_",D34,"_",E34) -> CL_41_ | C34: CL | D34: 41 | F34: Rancho La Cuchilla | G34: =IF(E34=0,CONCATENATE(F34," No. ",D34),CONCATENATE(F34," No. ",D34,", ",E34)) -> Rancho La Cuchilla No. 41 | H34: Cuchill 41C.E | I34: Arriaga Lemus | J34: 250
A35: 30 | B35: =CONCATENATE(C35,"_",D35,"_",E35) -> CL_42_ | C35: CL | D35: 42 | F35: Rancho La Cuchilla | G35: =IF(E35=0,CONCATENATE(F35," No. ",D35),CONCATENATE(F35," No. ",D35,", ",E35)) -> Rancho La Cuchilla No. 42 | H35: Cuchi 42 C.E | I35: Mac Kinney | J35: 300
A36: 31 | B36: =CONCATENATE(C36,"_",D36,"_",E36) -> CL_43_A | C36: CL | D36: 43 | E36: A | F36: Rancho La Cuchilla | G36: =IF(E36=0,CONCATENATE(F36," No. ",D36),CONCATENATE(F36," No. ",D36,", ",E36)) -> Rancho La Cuchilla No. 43, A | H36: Cuchi 43-A | I36: De la Rosa | J36: 200
A37: 32 | B37: =CONCATENATE(C37,"_",D37,"_",E37) -> CL_43_B | C37: CL | D37: 43 | E37: B | F37: Rancho La Cuchilla | G37: =IF(E37=0,CONCATENATE(F37," No. ",D37),CONCATENATE(F37," No. ",D37,", ",E37)) -> Rancho La Cuchilla No. 43, B | H37: Cuchil 43-B | I37: Luna Albertano | J37: 125
A38: 33 | B38: =CONCATENATE(C38,"_",D38,"_",E38) -> CL_44_ | C38: CL | D38: 44 | F38: Rancho La Cuchilla | G38: =IF(E38=0,CONCATENATE(F38," No. ",D38),CONCATENATE(F38," No. ",D38,", ",E38)) -> Rancho La Cuchilla No. 44 | H38: Cuchill 44 | I38: Garduño | J38: 300
A39: 34 | B39: =CONCATENATE(C39,"_",D39,"_",E39) -> CL_45_ | C39: CL | D39: 45 | F39: Rancho La Cuchilla | G39: =IF(E39=0,CONCATENATE(F39," No. ",D39),CONCATENATE(F39," No. ",D39,", ",E39)) -> Rancho La Cuchilla No. 45 | H39: Cuchill 45 | I39: Estévez Hernández | J39: 300
A40: 35 | B40: =CONCATENATE(C40,"_",D40,"_",E40) -> CL_46_ | C40: CL | D40: 46 | F40: Rancho La Cuchilla | G40: =IF(E40=0,CONCATENATE(F40," No. ",D40),CONCATENATE(F40," No. ",D40,", ",E40)) -> Rancho La Cuchilla No. 46 | H40: Cuch 46 C.E | I40: Cruz López | J40: 300
A41: 36 | B41: =CONCATENATE(C41,"_",D41,"_",E41) -> CL_47_ | C41: CL | D41: 47 | F41: Rancho La Cuchilla | G41: =IF(E41=0,CONCATENATE(F41," No. ",D41),CONCATENATE(F41," No. ",D41,", ",E41)) -> Rancho La Cuchilla No. 47 | H41: Cuch 47 C.E | I41: López | J41: 300
A42: 37 | B42: =CONCATENATE(C42,"_",D42,"_",E42) -> CL_49_ | C42: CL | D42: 49 | F42: Rancho La Cuchilla | G42: =IF(E42=0,CONCATENATE(F42," No. ",D42),CONCATENATE(F42," No. ",D42,", ",E42)) -> Rancho La Cuchilla No. 49 | H42: Cuchi 49 | I42: Orozco Castelazo | J42: 300
A43: 38 | B43: =CONCATENATE(C43,"_",D43,"_",E43) -> CL_52_ | C43: CL | D43: 52 | F43: Rancho La Cuchilla | G43: =IF(E43=0,CONCATENATE(F43," No. ",D43),CONCATENATE(F43," No. ",D43,", ",E43)) -> Rancho La Cuchilla No. 52 | H43: Cuchi 52 | I43: Velázquez | J43: 300
...

Sheet recibos
H1: =SUBTOTAL(9,H5:H2054) -> 796280.71
B2: 1 | C2: 2 | D2: 3 | E2: 4 | F2: 5 | G2: 6 | H2: 7 | I2: 8 | J2: 9 | K2: 10 | L2: 11 | M2: 12 | N2: 13 | O2: 14 | P2: 15 | Q2: 16 | R2: 17 | S2: 18 | T2: 19 | U2: 20 | V2: 21 | W2: 22 | X2: 23 | Y2: 24 | Z2: 25 | AA2: 26 | AB2: 27 | AC2: 28 | AD2: 29 | AE2: 30 | AF2: 31 | AG2: 32 | AH2: 33 | AI2: 34 | AJ2: 35 | AK2: 36 | AL2: 64
K3: 2012 | X3: 2013
A4: CALLE | B4: NÚMERO | C4: CASA | D4: DOMICILIO | E4: FAMILIA | F4: CUOTA | G4: C_ING | H4: IMPORTE | I4: FECHA | J4: CHK | K4: ENE | L4: FEB | M4: MAR | N4: ABR | O4: MAY | P4: JUN | Q4: JUL | R4: AGO | S4: SEP | T4: OCT | U4: NOV | V4: DIC | W4: 2012 | X4: ENE | Y4: FEB | Z4: MAR | AA4: ABR | AB4: MAY | AC4: JUN | AD4: JUL | AE4: AGO | AF4: SEP | AG4: OCT | AH4: NOV | AI4: DIC | AJ4: 2013 | AK4: OBSERVACIONES
A5: Rancho Upácuaro | B5: 3698 | C5: UP_32_ | D5: Rancho Upácuaro No. 32 | E5: Sairafi Carmen | F5: 300 | G5: 1 | H5: 300 | I5: 41245 | J5: =IF(OR(G5<>1,SUM(W5,AJ5)=H5),"ok","error") -> ok | V5: 300 | W5: =SUM(K5:V5) -> 300 | AJ5: =SUM(X5:AI5) -> 0 | AL5: ok
A6: Rancho Upácuaro | B6: 3699 | C6: UP_118_ | D6: Rancho Upácuaro No. 118 | E6: Siegrist | F6: 300 | G6: 1 | H6: 600 | I6: 41245 | J6: =IF(OR(G6<>1,SUM(W6,AJ6)=H6),"ok","error") -> ok | U6: 300 | V6: 300 | W6: =SUM(K6:V6) -> 600 | AJ6: =SUM(X6:AI6) -> 0 | AL6: ok
A7: Rancho Estanzuela | B7: 3700 | C7: EZ_115_ | D7: Rancho Estanzuela No. 115 | E7: Frías Solórzano | F7: 200 | G7: 1 | H7: 400 | I7: 41245 | J7: =IF(OR(G7<>1,SUM(W7,AJ7)=H7),"ok","error") -> ok | U7: 200 | V7: 200 | W7: =SUM(K7:V7) -> 400 | AJ7: =SUM(X7:AI7) -> 0 | AL7: ok
A8: Rancho Landero | B8: 3701 | C8: LD_31_ | D8: Rancho Landero No. 31 | E8: Díaz Hernández | F8: 200 | G8: 1 | H8: 200 | I8: 41245 | J8: =IF(OR(G8<>1,SUM(W8,AJ8)=H8),"ok","error") -> ok | V8: 200 | W8: =SUM(K8:V8) -> 200 | AJ8: =SUM(X8:AI8) -> 0 | AL8: ok
A9: Rancho Landero | B9: 3702 | C9: LD_24_ | D9: Rancho Landero No. 24 | E9: Vázquez Peralta | F9: 300 | G9: 1 | H9: 300 | I9: 41245 | J9: =IF(OR(G9<>1,SUM(W9,AJ9)=H9),"ok","error") -> ok | V9: 300 | W9: =SUM(K9:V9) -> 300 | AJ9: =SUM(X9:AI9) -> 0 | AL9: ok
A10: Rancho Upácuaro | B10: 3703 | C10: UP_142_ | D10: Rancho Upácuaro No. 142 | E10: Fierro Villaneda | F10: 300 | G10: 1 | H10: 300 | I10: 41245 | J10: =IF(OR(G10<>1,SUM(W10,AJ10)=H10),"ok","error") -> ok | V10: 300 | W10: =SUM(K10:V10) -> 300 | AJ10: =SUM(X10:AI10) -> 0 | AL10: ok
A11: Rancho Estanzuela | B11: 3704 | C11: EZ_161_1 | D11: Rancho Estanzuela No. 161, 1 | E11: Guevara | F11: 150 | G11: 1 | H11: 450 | I11: 41245 | J11: =IF(OR(G11<>1,SUM(W11,AJ11)=H11),"ok","error") -> ok | S11: 150 | T11: 150 | U11: 150 | W11: =SUM(K11:V11) -> 450 | AJ11: =SUM(X11:AI11) -> 0 | AL11: ok
A12: Rancho Zinamba | B12: 3705 | C12: ZB_34_ | D12: Rancho Zinamba No. 34 | E12: Torres Zavala | F12: 300 | G12: 1 | H12: 300 | I12: 41244 | J12: =IF(OR(G12<>1,SUM(W12,AJ12)=H12),"ok","error") -> ok | V12: 300 | W12: =SUM(K12:V12) -> 300 | AJ12: =SUM(X12:AI12) -> 0 | AL12: ok
A13: Rancho Zinamba | B13: 3705 | C13: ZB_34_ | D13: Rancho Zinamba No. 34 | E13: Torres Zavala | F13: 300 | G13: 4 | H13: 160 | I13: 41244 | J13: =IF(OR(G13<>1,SUM(W13,AJ13)=H13),"ok","error") -> ok | W13: =SUM(K13:V13) -> 0 | AJ13: =SUM(X13:AI13) -> 0 | AL13: error
A14: Rancho Upácuaro | B14: 3706 | C14: UP_106_ | D14: Rancho Upácuaro No. 106 | E14: Hernández Sánchez | F14: 300 | G14: 1 | H14: 900 | I14: 41246 | J14: =IF(OR(G14<>1,SUM(W14,AJ14)=H14),"ok","error") -> ok | T14: 300 | U14: 300 | V14: 300 | W14: =SUM(K14:V14) -> 900 | AJ14: =SUM(X14:AI14) -> 0 | AL14: ok
A15: Rancho Upácuaro | B15: 3707 | C15: UP_30_ | D15: Rancho Upácuaro No. 30 | E15: Dorantes | F15: 300 | G15: 1 | H15: 300 | I15: 41244 | J15: =IF(OR(G15<>1,SUM(W15,AJ15)=H15),"ok","error") -> ok | V15: 300 | W15: =SUM(K15:V15) -> 300 | AJ15: =SUM(X15:AI15) -> 0 | AL15: ok
A16: Rancho Upácuaro | B16: 3707 | C16: UP_30_ | D16: Rancho Upácuaro No. 30 | E16: Dorantes | F16: 300 | G16: 4 | H16: 160 | I16: 41244 | J16: =IF(OR(G16<>1,SUM(W16,AJ16)=H16),"ok","error") -> ok | W16: =SUM(K16:V16) -> 0 | AJ16: =SUM(X16:AI16) -> 0 | AL16: error
A17: Rancho Upácuaro | B17: 3708 | C17: UP_106_ | D17: Rancho Upácuaro No. 106 | E17: Hernández Sánchez | F17: 300 | G17: 5 | H17: 40 | I17: 41244 | J17: =IF(OR(G17<>1,SUM(W17,AJ17)=H17),"ok","error") -> ok | W17: =SUM(K17:V17) -> 0 | AJ17: =SUM(X17:AI17) -> 0 | AL17: error
A18: Rancho Estanzuela | B18: 3709 | C18: EZ_9_A | D18: Rancho Estanzuela No. 9, A | E18: Castañeda | F18: 100 | G18: 1 | H18: 400 | I18: 41244 | J18: =IF(OR(G18<>1,SUM(W18,AJ18)=H18),"ok","error") -> ok | S18: 100 | T18: 100 | U18: 100 | V18: 100 | W18: =SUM(K18:V18) -> 400 | AJ18: =SUM(X18:AI18) -> 0 | AL18: ok
A19: Rancho Landero | B19: 3710 | C19: LD_20_ | D19: Rancho Landero No. 20 | E19: Velasco | F19: 300 | G19: 1 | H19: 900 | I19: 41244 | J19: =IF(OR(G19<>1,SUM(W19,AJ19)=H19),"ok","error") -> ok | R19: 300 | S19: 300 | T19: 300 | W19: =SUM(K19:V19) -> 900 | AJ19: =SUM(X19:AI19) -> 0 | AL19: ok
A20: Rancho Romeral | B20: 3711 | C20: RM_9_A | D20: Rancho Romeral No. 9, A | E20: Quiñones Hernández | F20: 300 | G20: 1 | H20: 600 | I20: 41244 | J20: =IF(OR(G20<>1,SUM(W20,AJ20)=H20),"ok","error") -> ok | U20: 300 | V20: 300 | W20: =SUM(K20:V20) -> 600 | AJ20: =SUM(X20:AI20) -> 0 | AL20: ok
A21: Rancho Upácuaro | B21: 3712 | C21: UP_110_ | D21: Rancho Upácuaro No. 110 | E21: Ruiz Mijangos | F21: 300 | G21: 1 | H21: 300 | I21: 41244 | J21: =IF(OR(G21<>1,SUM(W21,AJ21)=H21),"ok","error") -> ok | V21: 300 | W21: =SUM(K21:V21) -> 300 | AJ21: =SUM(X21:AI21) -> 0 | AL21: ok
A22: Rancho Upácuaro | B22: 3713 | C22: UP_114_ | D22: Rancho Upácuaro No. 114 | E22: Hernández Cornejo | F22: 300 | G22: 1 | H22: 300 | I22: 41244 | J22: =IF(OR(G22<>1,SUM(W22,AJ22)=H22),"ok","error") -> ok | V22: 300 | W22: =SUM(K22:V22) -> 300 | AJ22: =SUM(X22:AI22) -> 0 | AL22: ok
A23: Rancho Upácuaro | B23: 3714 | C23: UP_93_ | D23: Rancho Upácuaro No. 93 | E23: Valdés | F23: 300 | G23: 1 | H23: 300 | I23: 41244 | J23: =IF(OR(G23<>1,SUM(W23,AJ23)=H23),"ok","error") -> ok | V23: 300 | W23: =SUM(K23:V23) -> 300 | AJ23: =SUM(X23:AI23) -> 0 | AL23: ok
A24: Rancho Upácuaro | B24: 3715 | C24: UP_76_ | D24: Rancho Upácuaro No. 76 | E24: Ruiz de San Pedro | F24: 300 | G24: 1 | H24: 300 | I24: 41244 | J24: =IF(OR(G24<>1,SUM(W24,AJ24)=H24),"ok","error") -> ok | V24: 300 | W24: =SUM(K24:V24) -> 300 | AJ24: =SUM(X24:AI24) -> 0 | AL24: ok
A25: Rancho La Cuchilla | B25: 3716 | C25: CL_71_ | D25: Rancho La Cuchilla No. 71 | E25: Pulido | F25: 300 | G25: 1 | H25: 300 | I25: 41245 | J25: =IF(OR(G25<>1,SUM(W25,AJ25)=H25),"ok","error") -> ok | V25: 300 | W25: =SUM(K25:V25) -> 300 | AJ25: =SUM(X25:AI25) -> 0 | AL25: ok
A26: Rancho La Cuchilla | B26: 3717 | C26: CL_7_202 | D26: Rancho La Cuchilla No. 7, 202 | E26: Carbajal Zayas | F26: 100 | G26: 1 | H26: 400 | I26: 41244 | J26: =IF(OR(G26<>1,SUM(W26,AJ26)=H26),"ok","error") -> ok | S26: 100 | T26: 100 | U26: 100 | V26: 100 | W26: =SUM(K26:V26) -> 400 | AJ26: =SUM(X26:AI26) -> 0 | AL26: ok
A27: Rancho Upácuaro | B27: 3718 | C27: UP_85_ | D27: Rancho Upácuaro No. 85 | E27: Del Toro Huerta | F27: 300 | G27: 1 | H27: 300 | I27: 41244 | J27: =IF(OR(G27<>1,SUM(W27,AJ27)=H27),"ok","error") -> ok | V27: 300 | W27: =SUM(K27:V27) -> 300 | AJ27: =SUM(X27:AI27) -> 0 | AL27: ok
A28: Rancho Upácuaro | B28: 3719 | C28: UP_85_ | D28: Rancho Upácuaro No. 85 | E28: Del Toro Huerta | F28: 300 | G28: 2 | H28: 300 | I28: 41244 | J28: =IF(OR(G28<>1,SUM(W28,AJ28)=H28),"ok","error") -> ok | W28: =SUM(K28:V28) -> 0 | AJ28: =SUM(X28:AI28) -> 0 | AL28: error
A29: Rancho La Cuchilla | B29: 3720 | C29: CL_89_ | D29: Rancho La Cuchilla No. 89 | E29: Gálvez | F29: 300 | G29: 1 | H29: 300 | I29: 41244 | J29: =IF(OR(G29<>1,SUM(W29,AJ29)=H29),"ok","error") -> ok | V29: 300 | W29: =SUM(K29:V29) -> 300 | AJ29: =SUM(X29:AI29) -> 0 | AL29: ok
A30: Rancho Recoveco | B30: 3721 | C30: RV_175_0 | D30: Rancho Recoveco No. 175 | E30: Ramírez | F30: 300 | G30: 1 | H30: 300 | I30: 41244 | J30: =IF(OR(G30<>1,SUM(W30,AJ30)=H30),"ok","error") -> ok | V30: 300 | W30: =SUM(K30:V30) -> 300 | AJ30: =SUM(X30:AI30) -> 0 | AL30: ok
A31: Rancho Landero | B31: 3722 | C31: LD_42_ | D31: Rancho Landero No. 42 | E31: Ávila Fidel | F31: 300 | G31: 1 | H31: 300 | I31: 41244 | J31: =IF(OR(G31<>1,SUM(W31,AJ31)=H31),"ok","error") -> ok | V31: 300 | W31: =SUM(K31:V31) -> 300 | AJ31: =SUM(X31:AI31) -> 0 | AL31: ok
A32: Rancho Landero | B32: 3723 | C32: LD_21_ | D32: Rancho Landero No. 21 | E32: Meza | F32: 300 | G32: 1 | H32: 300 | I32: 41244 | J32: =IF(OR(G32<>1,SUM(W32,AJ32)=H32),"ok","error") -> ok | V32: 300 | W32: =SUM(K32:V32) -> 300 | AJ32: =SUM(X32:AI32) -> 0 | AL32: ok
A33: Rancho Landero | B33: 3724 | C33: LD_21_ | D33: Rancho Landero No. 21 | E33: Meza | F33: 300 | G33: 2 | H33: 300 | I33: 41244 | J33: =IF(OR(G33<>1,SUM(W33,AJ33)=H33),"ok","error") -> ok | W33: =SUM(K33:V33) -> 0 | AJ33: =SUM(X33:AI33) -> 0 | AL33: error
A34: Rancho Estanzuela | B34: 3725 | C34: EZ_89_ | D34: Rancho Estanzuela No. 89 | E34: Romero Ortiz | F34: 300 | G34: 1 | H34: 300 | I34: 41244 | J34: =IF(OR(G34<>1,SUM(W34,AJ34)=H34),"ok","error") -> ok | V34: 300 | W34: =SUM(K34:V34) -> 300 | AJ34: =SUM(X34:AI34) -> 0 | AL34: ok
A35: Rancho Upácuaro | B35: 3726 | C35: UP_18_ | D35: Rancho Upácuaro No. 18 | E35: Guzmán | F35: 300 | G35: 1 | H35: 300 | I35: 41244 | J35: =IF(OR(G35<>1,SUM(W35,AJ35)=H35),"ok","error") -> ok | V35: 300 | W35: =SUM(K35:V35) -> 300 | AJ35: =SUM(X35:AI35) -> 0 | AL35: ok
A36: Rancho Upácuaro | B36: 3727 | C36: UP_108_ | D36: Rancho Upácuaro No. 108 | E36: Mejía | F36: 300 | G36: 1 | H36: 300 | I36: 41244 | J36: =IF(OR(G36<>1,SUM(W36,AJ36)=H36),"ok","error") -> ok | U36: 300 | W36: =SUM(K36:V36) -> 300 | AJ36: =SUM(X36:AI36) -> 0 | AL36: ok
A37: Rancho La Cuchilla | B37: 3728 | C37: CL_53_ | D37: Rancho La Cuchilla No. 53 | E37: Loyo Ochoa | F37: 300 | G37: 1 | H37: 600 | I37: 41244 | J37: =IF(OR(G37<>1,SUM(W37,AJ37)=H37),"ok","error") -> ok | T37: 300 | U37: 300 | W37: =SUM(K37:V37) -> 600 | AJ37: =SUM(X37:AI37) -> 0 | AL37: ok
A38: Rancho Upácuaro | B38: 3729 | C38: UP_87_ | D38: Rancho Upácuaro No. 87 | E38: Rodríguez Parés | F38: 300 | G38: 1 | H38: 300 | I38: 41244 | J38: =IF(OR(G38<>1,SUM(W38,AJ38)=H38),"ok","error") -> ok | V38: 300 | W38: =SUM(K38:V38) -> 300 | AJ38: =SUM(X38:AI38) -> 0 | AL38: ok
A39: Rancho Upácuaro | B39: 3730 | C39: UP_47_ | D39: Rancho Upácuaro No. 47 | E39: Flores Muñoz | F39: 300 | G39: 1 | H39: 600 | I39: 41244 | J39: =IF(OR(G39<>1,SUM(W39,AJ39)=H39),"ok","error") -> ok | U39: 300 | V39: 300 | W39: =SUM(K39:V39) -> 600 | AJ39: =SUM(X39:AI39) -> 0 | AL39: ok
A40: Rancho Upácuaro | B40: 3730 | C40: UP_47_ | D40: Rancho Upácuaro No. 47 | E40: Flores Muñoz | F40: 300 | G40: 2 | H40: 300 | I40: 41244 | J40: =IF(OR(G40<>1,SUM(W40,AJ40)=H40),"ok","error") -> ok | W40: =SUM(K40:V40) -> 0 | AJ40: =SUM(X40:AI40) -> 0 | AL40: error
...

Sheet criterios
D1: Casas / código de cobranza
A2: Calles | D2: CASA | E2: C_ING | F2: CASA | G2: C_ING | H2: CASA | I2: C_ING | J2: CASA | K2: C_ING | L2: CASA | M2: C_ING | N2: CASA | O2: C_ING | P2: CASA | Q2: C_ING | R2: CASA | S2: C_ING | T2: CASA | U2: C_ING | V2: CASA | W2: C_ING | X2: CASA | Y2: C_ING | Z2: CASA | AA2: C_ING | AB2: CASA | AC2: C_ING | AD2: CASA | AE2: C_ING | AF2: CASA | AG2: C_ING | AH2: CASA | AI2: C_ING | AJ2: CASA | AK2: C_ING | AL2: CASA | AM2: C_ING | AN2: CASA | AO2: C_ING | AP2: CASA | AQ2: C_ING | AR2: CASA | AS2: C_ING | AT2: CASA | AU2: C_ING | AV2: CASA | AW2: C_ING | AX2: CASA | AY2: C_ING | AZ2: CASA | BA2: C_ING | BB2: CASA | BC2: C_ING | BD2: CASA | BE2: C_ING | BF2: CASA | BG2: C_ING | BH2: CASA | BI2: C_ING | BJ2: CASA | BK2: C_ING | BL2: CASA | BM2: C_ING | BN2: CASA | BO2: C_ING | BP2: CASA | BQ2: C_ING | BR2: CASA | BS2: C_ING | BT2: CASA | BU2: C_ING | BV2: CASA | BW2: C_ING | BX2: CASA | BY2: C_ING | BZ2: CASA | CA2: C_ING | CB2: CASA | CC2: C_ING | CD2: CASA | CE2: C_ING | CF2: CASA | CG2: C_ING | CH2: CASA | CI2: C_ING | CJ2: CASA | CK2: C_ING | CL2: CASA | CM2: C_ING | CN2: CASA | CO2: C_ING | CP2: CASA | CQ2: C_ING | CR2: CASA | CS2: C_ING | CT2: CASA | CU2: C_ING | CV2: CASA | CW2: C_ING | CX2: CASA | CY2: C_ING | CZ2: CASA | DA2: C_ING | DB2: CASA | DC2: C_ING | DD2: CASA | DE2: C_ING | DF2: CASA | DG2: C_ING | DH2: CASA | DI2: C_ING | DJ2: CASA | DK2: C_ING | DL2: CASA | DM2: C_ING | DN2: CASA | DO2: C_ING | DP2: CASA | DQ2: C_ING | DR2: CASA | DS2: C_ING | DT2: CASA | DU2: C_ING | DV2: CASA | DW2: C_ING | DX2: CASA | DY2: C_ING | DZ2: CASA | EA2: C_ING | EB2: CASA | EC2: C_ING | ED2: CASA | EE2: C_ING | EF2: CASA | EG2: C_ING | EH2: CASA | EI2: C_ING | EJ2: CASA | EK2: C_ING | EL2: CASA | EM2: C_ING | EN2: CASA | EO2: C_ING | EP2: CASA | EQ2: C_ING | ER2: CASA | ES2: C_ING | ET2: CASA | EU2: C_ING | EV2: CASA | EW2: C_ING | EX2: CASA | EY2: C_ING | EZ2: CASA | FA2: C_ING | FB2: CASA | FC2: C_ING | FD2: CASA | FE2: C_ING | FF2: CASA | FG2: C_ING | FH2: CASA | FI2: C_ING | FJ2: CASA | FK2: C_ING | FL2: CASA | FM2: C_ING | FN2: CASA | FO2: C_ING | FP2: CASA | FQ2: C_ING | FR2: CASA | FS2: C_ING | FT2: CASA | FU2: C_ING | FV2: CASA | FW2: C_ING | FX2: CASA | FY2: C_ING | FZ2: CASA | GA2: C_ING | GB2: CASA | GC2: C_ING | GD2: CASA | GE2: C_ING | GF2: CASA | GG2: C_ING | GH2: CASA | GI2: C_ING | GJ2: CASA | GK2: C_ING | GL2: CASA | GM2: C_ING | GN2: CASA | GO2: C_ING | GP2: CASA | GQ2: C_ING | GR2: CASA | GS2: C_ING | GT2: CASA | GU2: C_ING | GV2: CASA | GW2: C_ING | GX2: CASA | GY2: C_ING | GZ2: CASA | HA2: C_ING | HB2: CASA | HC2: C_ING | HD2: CASA | HE2: C_ING | HF2: CASA | HG2: C_ING | HH2: CASA | HI2: C_ING | HJ2: CASA | HK2: C_ING | HL2: CASA | HM2: C_ING | HN2: CASA | HO2: C_ING | HP2: CASA | HQ2: C_ING | HR2: CALLE | HS2: calle
A3: CL | B3: Rancho La Cuchilla | D3: CL_7_101 | E3: 1 | F3: CL_7_102 | G3: 1 | H3: CL_7_201 | I3: 1 | J3: CL_7_202 | K3: 1 | L3: CL_9_ | M3: 1 | N3: CL_11_ | O3: 1 | P3: CL_12_ | Q3: 1 | R3: CL_13_ | S3: 1 | T3: CL_14_ | U3: 1 | V3: CL_15_ | W3: 1 | X3: CL_18_ | Y3: 1 | Z3: CL_19_ | AA3: 1 | AB3: CL_20_ | AC3: 1 | AD3: CL_21_ | AE3: 1 | AF3: CL_23_ | AG3: 1 | AH3: CL_25_ | AI3: 1 | AJ3: CL_27_ | AK3: 1 | AL3: CL_28_ | AM3: 1 | AN3: CL_29_ | AO3: 1 | AP3: CL_30_ | AQ3: 1 | AR3: CL_31_ | AS3: 1 | AT3: CL_32_ | AU3: 1 | AV3: CL_33_ | AW3: 1 | AX3: CL_35_ | AY3: 1 | AZ3: CL_36_ | BA3: 1 | BB3: CL_38_ | BC3: 1 | BD3: CL_39_ | BE3: 1 | BF3: CL_40_ | BG3: 1 | BH3: CL_41_ | BI3: 1 | BJ3: CL_42_ | BK3: 1 | BL3: CL_43_A | BM3: 1 | BN3: CL_43_B | BO3: 1 | BP3: CL_44_ | BQ3: 1 | BR3: CL_45_ | BS3: 1 | BT3: CL_46_ | BU3: 1 | BV3: CL_47_ | BW3: 1 | BX3: CL_49_ | BY3: 1 | BZ3: CL_52_ | CA3: 1 | CB3: CL_54_ | CC3: 1 | CD3: CL_53_ | CE3: 1 | CF3: CL_55_ | CG3: 1 | CH3: CL_57_ | CI3: 1 | CJ3: CL_58_ | CK3: 1 | CL3: CL_59_ | CM3: 1 | CN3: CL_60_ | CO3: 1 | CP3: CL_61_ | CQ3: 1 | CR3: CL_62_ | CS3: 1 | CT3: CL_63_ | CU3: 1 | CV3: CL_65_ | CW3: 1 | CX3: CL_66_ | CY3: 1 | CZ3: CL_67_ | DA3: 1 | DB3: CL_68_ | DC3: 1 | DD3: CL_69_ | DE3: 1 | DF3: CL_70_ | DG3: 1 | DH3: CL_71_ | DI3: 1 | DJ3: CL_72_ | DK3: 1 | DL3: CL_73_ | DM3: 1 | DN3: CL_74_ | DO3: 1 | DP3: CL_75_ | DQ3: 1 | DR3: CL_76_ | DS3: 1 | DT3: CL_77_ | DU3: 1 | DV3: CL_79_ | DW3: 1 | DX3: CL_80_ | DY3: 1 | DZ3: CL_81_A | EA3: 1 | EB3: CL_81_B | EC3: 1 | ED3: CL_82_ | EE3: 1 | EF3: CL_83_ | EG3: 1 | EH3: CL_86_ | EI3: 1 | EJ3: CL_87_ | EK3: 1 | EL3: CL_88_ | EM3: 1 | EN3: CL_89_ | EO3: 1 | EP3: CL_90_ | EQ3: 1 | ER3: CL_91_ | ES3: 1 | ET3: CL_92_ | EU3: 1 | EV3: CL_93_ | EW3: 1 | EX3: CL_94_ | EY3: 1 | EZ3: CL_95_ | FA3: 1 | FB3: CL_96_ | FC3: 1 | FD3: CL_97_ | FE3: 1 | FF3: CL_101_ | FG3: 1 | FH3: CL_107_ | FI3: 1 | FJ3: CL_110_ | FK3: 1 | FL3: CL_111_ | FM3: 1 | FN3: CL_112_PA | FO3: 1 | FP3: CL_112_PB | FQ3: 1 | FR3: CL_115_ | FS3: 1 | FT3: CL_116_ | FU3: 1 | FV3: CL_117_ | FW3: 1 | FX3: CL_118_ | FY3: 1 | FZ3: CL_119_ | GA3: 1 | GB3: CL_120_ | GC3: 1 | GD3: CL_121_ | GE3: 1 | GF3: CL_122_ | GG3: 1 | GH3: CL_125_ | GI3: 1 | GJ3: CL_127_ | GK3: 1 | GL3: CL_129_ | GM3: 1 | GN3: CL_130_ | GO3: 1 | GP3: CL_131_ | GQ3: 1 | GR3: CL_132_ | GS3: 1 | GT3: CL_133_ | GU3: 1 | GV3: CL_134_ | GW3: 1 | GX3: CL_135_ | GY3: 1 | GZ3: CL_137_ | HA3: 1 | HB3: CL_139_ | HC3: 1 | HD3: CL_141_ | HE3: 1 | HF3: CL_144_ | HG3: 1 | HH3: CL_145_ | HI3: 1 | HJ3: CL_147_ | HK3: 1 | HL3: CL_148_ | HM3: 1 | HN3: CL_149_ | HO3: 1 | HP3: CL_terreno_ | HQ3: 1 | HR3: CL | HS3: Cuchilla
A4: CT | B4: Cafetales
A5: EP | B5: Rancho Estopila | D5: CASA | E5: C_ING | F5: CASA | G5: C_ING | H5: CASA | I5: C_ING | J5: CASA | K5: C_ING | L5: CASA | M5: C_ING | N5: calle | O5: CALLE
A6: EZ | B6: Rancho Estanzuela | D6: EP_15_ | E6: 1 | F6: EP_18_ | G6: 1 | H6: EP_22_A | I6: 1 | J6: EP_22_B | K6: 1 | L6: EP_44_ | M6: 1 | N6: Estopila | O6: EP
A7: HS | B7: Calzada del Hueso
A8: LD | B8: Rancho Landero | D8: CASA | E8: C_ING | F8: CASA | G8: C_ING | H8: CASA | I8: C_ING | J8: CASA | K8: C_ING | L8: CASA | M8: C_ING | N8: CASA | O8: C_ING | P8: CASA | Q8: C_ING | R8: CASA | S8: C_ING | T8: CASA | U8: C_ING | V8: CASA | W8: C_ING | X8: CASA | Y8: C_ING | Z8: CASA | AA8: C_ING | AB8: CASA | AC8: C_ING | AD8: CASA | AE8: C_ING | AF8: CASA | AG8: C_ING | AH8: CASA | AI8: C_ING | AJ8: CASA | AK8: C_ING | AL8: CASA | AM8: C_ING | AN8: CASA | AO8: C_ING | AP8: CASA | AQ8: C_ING | AR8: CASA | AS8: C_ING | AT8: CASA | AU8: C_ING | AV8: CASA | AW8: C_ING | AX8: CASA | AY8: C_ING | AZ8: CASA | BA8: C_ING | BB8: CASA | BC8: C_ING | BD8: CASA | BE8: C_ING | BF8: CASA | BG8: C_ING | BH8: CASA | BI8: C_ING | BJ8: CASA | BK8: C_ING | BL8: CASA | BM8: C_ING | BN8: CASA | BO8: C_ING | BP8: CASA | BQ8: C_ING | BR8: CASA | BS8: C_ING | BT8: CASA | BU8: C_ING | BV8: CASA | BW8: C_ING | BX8: CASA | BY8: C_ING | BZ8: CASA | CA8: C_ING | CB8: CASA | CC8: C_ING | CD8: CASA | CE8: C_ING | CF8: CASA | CG8: C_ING | CH8: CASA | CI8: C_ING | CJ8: CASA | CK8: C_ING | CL8: CASA | CM8: C_ING | CN8: CASA | CO8: C_ING | CP8: CASA | CQ8: C_ING | CR8: CASA | CS8: C_ING | CT8: CASA | CU8: C_ING | CV8: CASA | CW8: C_ING | CX8: CASA | CY8: C_ING | CZ8: CASA | DA8: C_ING | DB8: CASA | DC8: C_ING | DD8: CASA | DE8: C_ING | DF8: CASA | DG8: C_ING | DH8: CASA | DI8: C_ING | DJ8: CASA | DK8: C_ING | DL8: CASA | DM8: C_ING | DN8: CASA | DO8: C_ING | DP8: CASA | DQ8: C_ING | DR8: CASA | DS8: C_ING | DT8: CASA | DU8: C_ING | DV8: CASA | DW8: C_ING | DX8: CASA | DY8: C_ING | DZ8: CASA | EA8: C_ING | EB8: CASA | EC8: C_ING | ED8: CASA | EE8: C_ING | EF8: CASA | EG8: C_ING | EH8: CASA | EI8: C_ING | EJ8: CASA | EK8: C_ING | EL8: CASA | EM8: C_ING | EN8: CASA | EO8: C_ING | EP8: CASA | EQ8: C_ING | ER8: CASA | ES8: C_ING | ET8: CASA | EU8: C_ING | EV8: CASA | EW8: C_ING | EX8: CASA | EY8: C_ING | EZ8: CASA | FA8: C_ING | FB8: CASA | FC8: C_ING | FD8: CASA | FE8: C_ING | FF8: calle | FG8: CALLE | FH8: calle | FI8: CALLE
A9: RM | B9: Rancho Romeral | D9: EZ_3_ | E9: 1 | F9: EZ_5_A | G9: 1 | H9: EZ_5_B | I9: 1 | J9: EZ_7_A | K9: 1 | L9: EZ_7_B | M9: 1 | N9: EZ_9_A | O9: 1 | P9: EZ_9_B | Q9: 1 | R9: EZ_11_A | S9: 1 | T9: EZ_11_B | U9: 1 | V9: EZ_15_A | W9: 1 | X9: EZ_15_B | Y9: 1 | Z9: EZ_17_ | AA9: 1 | AB9: EZ_19_ | AC9: 1 | AD9: EZ_21_ | AE9: 1 | AF9: EZ_25_ | AG9: 1 | AH9: EZ_31_ | AI9: 1 | AJ9: EZ_33_ | AK9: 1 | AL9: EZ_35_ | AM9: 1 | AN9: EZ_37_ | AO9: 1 | AP9: EZ_41_ | AQ9: 1 | AR9: EZ_43_ | AS9: 1 | AT9: EZ_45_ | AU9: 1 | AV9: EZ_47_ | AW9: 1 | AX9: EZ_49_ | AY9: 1 | AZ9: EZ_53_ | BA9: 1 | BB9: EZ_55_ | BC9: 1 | BD9: EZ_57_ | BE9: 1 | BF9: EZ_59_ | BG9: 1 | BH9: EZ_61_ | BI9: 1 | BJ9: EZ_63_ | BK9: 1 | BL9: EZ_65_ | BM9: 1 | BN9: EZ_67_ | BO9: 1 | BP9: EZ_69_ | BQ9: 1 | BR9: EZ_71_ | BS9: 1 | BT9: EZ_73_ | BU9: 1 | BV9: EZ_75_ | BW9: 1 | BX9: EZ_77_ | BY9: 1 | BZ9: EZ_79_ | CA9: 1 | CB9: EZ_89_ | CC9: 1 | CD9: EZ_91_ | CE9: 1 | CF9: EZ_93_ | CG9: 1 | CH9: EZ_95_ | CI9: 1 | CJ9: EZ_97_ | CK9: 1 | CL9: EZ_99_ | CM9: 1 | CN9: EZ_100_ | CO9: 1 | CP9: EZ_101_ | CQ9: 1 | CR9: EZ_103_ | CS9: 1 | CT9: EZ_105_ | CU9: 1 | CV9: EZ_111_ | CW9: 1 | CX9: EZ_115_ | CY9: 1 | CZ9: EZ_117_ | DA9: 1 | DB9: EZ_119_2 | DC9: 1 | DD9: EZ_119_0 | DE9: 1 | DF9: EZ_121_ | DG9: 1 | DH9: EZ_123_ | DI9: 1 | DJ9: EZ_127_ | DK9: 1 | DL9: EZ_129_ | DM9: 1 | DN9: CM_130_A | DO9: 1 | DP9: EZ_130_B | DQ9: 1 | DR9: EZ_133_ | DS9: 1 | DT9: EZ_135_ | DU9: 1 | DV9: EZ_139_ | DW9: 1 | DX9: EZ_141_ | DY9: 1 | DZ9: EZ_147_1 | EA9: 1 | EB9: EZ_147_2 | EC9: 1 | ED9: EZ_147_3 | EE9: 1 | EF9: EZ_149_ | EG9: 1 | EH9: EZ_151_ | EI9: 1 | EJ9: EZ_153_ | EK9: 1 | EL9: EZ_155_ | EM9: 1 | EN9: EZ_157_1 | EO9: 1 | EP9: EZ_157_2 | EQ9: 1 | ER9: EZ_157_3 | ES9: 1 | ET9: EZ_159_ | EU9: 1 | EV9: EZ_161_1 | EW9: 1 | EX9: EZ_161_B | EY9: 1 | EZ9: EZ_163_ | FA9: 1 | FB9: EZ_165_A | FC9: 1 | FD9: EZ_165_B | FE9: 1 | FF9: Estanzuela | FG9: EZ | FH9: Carmel | FI9: CM
A10: RV | B10: Rancho Recoveco
A11: UP | B11: Rancho Upácuaro | D11: CASA | E11: C_ING | F11: CASA | G11: C_ING | H11: CASA | I11: C_ING | J11: CASA | K11: C_ING | L11: CASA | M11: C_ING | N11: calle | O11: CALLE
A12: ZB | B12: Rancho Zinamba | D12: HS_828_ | E12: 1 | F12: HS_840_ | G12: 1 | H12: HS_A_ | I12: 1 | J12: HS_B_ | K12: 1 | L12: HS_C_ | M12: 1 | N12: Hueso | O12: HS
D14: CASA | E14: C_ING | F14: CASA | G14: C_ING | H14: CASA | I14: C_ING | J14: CASA | K14: C_ING | L14: CASA | M14: C_ING | N14: CASA | O14: C_ING | P14: CASA | Q14: C_ING | R14: CASA | S14: C_ING | T14: CASA | U14: C_ING | V14: CASA | W14: C_ING | X14: CASA | Y14: C_ING | Z14: CASA | AA14: C_ING | AB14: CASA | AC14: C_ING | AD14: CASA | AE14: C_ING | AF14: CASA | AG14: C_ING | AH14: CASA | AI14: C_ING | AJ14: CASA | AK14: C_ING | AL14: CASA | AM14: C_ING | AN14: CASA | AO14: C_ING | AP14: CASA | AQ14: C_ING | AR14: CASA | AS14: C_ING | AT14: CASA | AU14: C_ING | AV14: CASA | AW14: C_ING | AX14: CASA | AY14: C_ING | AZ14: CASA | BA14: C_ING | BB14: CASA | BC14: C_ING | BD14: CASA | BE14: C_ING | BF14: CASA | BG14: C_ING | BH14: CASA | BI14: C_ING | BJ14: CASA | BK14: C_ING | BL14: CASA | BM14: C_ING | BN14: CASA | BO14: C_ING | BP14: CASA | BQ14: C_ING | BR14: CASA | BS14: C_ING | BT14: CASA | BU14: C_ING | BV14: CASA | BW14: C_ING | BX14: CASA | BY14: C_ING | BZ14: CASA | CA14: C_ING | CB14: CASA | CC14: C_ING | CD14: CASA | CE14: C_ING | CF14: CASA | CG14: C_ING | CH14: CASA | CI14: C_ING | CJ14: CASA | CK14: C_ING | CL14: CASA | CM14: C_ING | CN14: CASA | CO14: C_ING | CP14: CASA | CQ14: C_ING | CR14: CASA | CS14: C_ING | CT14: CASA | CU14: C_ING | CV14: CASA | CW14: C_ING | CX14: CASA | CY14: C_ING | CZ14: CASA | DA14: C_ING | DB14: CASA | DC14: C_ING | DD14: CASA | DE14: C_ING | DF14: CASA | DG14: C_ING | DH14: CASA | DI14: C_ING | DJ14: CASA | DK14: C_ING | DL14: CASA | DM14: C_ING | DN14: CASA | DO14: C_ING | DP14: CASA | DQ14: C_ING | DR14: CASA | DS14: C_ING | DT14: CASA | DU14: C_ING | DV14: CASA | DW14: C_ING | DX14: CASA | DY14: C_ING | DZ14: CASA | EA14: C_ING | EB14: CASA | EC14: C_ING | ED14: CASA | EE14: C_ING | EF14: CASA | EG14: C_ING | EH14: CASA | EI14: C_ING | EJ14: CASA | EK14: C_ING | EL14: CASA | EM14: C_ING | EN14: CASA | EO14: C_ING | EP14: CASA | EQ14: C_ING | ER14: CASA | ES14: C_ING | ET14: CASA | EU14: C_ING | EV14: CASA | EW14: C_ING | EX14: CASA | EY14: C_ING | EZ14: CASA | FA14: C_ING | FB14: CASA | FC14: C_ING | FD14: CASA | FE14: C_ING | FF14: CASA | FG14: C_ING | FH14: CASA | FI14: C_ING | FJ14: CASA | FK14: C_ING | FL14: calle | FM14: CALLE
D15: LD_1_ | E15: 1 | F15: LD_1_ | G15: 1 | H15: LD_2_3 | I15: 1 | J15: LD_2_A | K15: 1 | L15: LD_2_B | M15: 1 | N15: LD_7_ | O15: 1 | P15: LD_8_ | Q15: 1 | R15: LD_10_ | S15: 1 | T15: LD_11_ | U15: 1 | V15: LD_12_ | W15: 1 | X15: LD_13_ | Y15: 1 | Z15: LD_14_ | AA15: 1 | AB15: LD_15_ | AC15: 1 | AD15: LD_17_ | AE15: 1 | AF15: LD_18_ | AG15: 1 | AH15: LD_19_ | AI15: 1 | AJ15: LD_20_ | AK15: 1 | AL15: LD_21_ | AM15: 1 | AN15: LD_22_ | AO15: 1 | AP15: LD_24_ | AQ15: 1 | AR15: LD_25_ | AS15: 1 | AT15: LD_26_ | AU15: 1 | AV15: LD_28_ | AW15: 1 | AX15: LD_29_ | AY15: 1 | AZ15: LD_30_ | BA15: 1 | BB15: LD_31_ | BC15: 1 | BD15: LD_33_ | BE15: 1 | BF15: LD_34_ | BG15: 1 | BH15: LD_35_ | BI15: 1 | BJ15: LD_36_ | BK15: 1 | BL15: LD_37_ | BM15: 1 | BN15: LD_38_ | BO15: 1 | BP15: LD_39_ | BQ15: 1 | BR15: LD_40_ | BS15: 1 | BT15: LD_41_ | BU15: 1 | BV15: LD_42_ | BW15: 1 | BX15: LD_44_ | BY15: 1 | BZ15: LD_45_ | CA15: 1 | CB15: LD_47_ | CC15: 1 | CD15: LD_49_ | CE15: 1 | CF15: LD_50_ | CG15: 1 | CH15: LD_51_ | CI15: 1 | CJ15: LD_52_ | CK15: 1 | CL15: LD_54_1 | CM15: 1 | CN15: LD_54_2 | CO15: 1 | CP15: LD_58_ | CQ15: 1 | CR15: LD_60_ | CS15: 1 | CT15: LD_61_ | CU15: 1 | CV15: LD_62_ | CW15: 1 | CX15: LD_63_ | CY15: 1 | CZ15: LD_64_ | DA15: 1 | DB15: LD_65_ | DC15: 1 | DD15: LD_66_ | DE15: 1 | DF15: LD_68_ | DG15: 1 | DH15: LD_69_ | DI15: 1 | DJ15: LD_70_ | DK15: 1 | DL15: LD_71_ | DM15: 1 | DN15: LD_72_ | DO15: 1 | DP15: LD_73_ | DQ15: 1 | DR15: LD_74_ | DS15: 1 | DT15: LD_75_ | DU15: 1 | DV15: LD_76_ | DW15: 1 | DX15: LD_77_ | DY15: 1 | DZ15: LD_80_ | EA15: 1 | EB15: LD_81_ | EC15: 1 | ED15: LD_83_ | EE15: 1 | EF15: LD_84_ | EG15: 1 | EH15: LD_85_ | EI15: 1 | EJ15: LD_86_ | EK15: 1 | EL15: LD_87_ | EM15: 1 | EN15: LD_88_ | EO15: 1 | EP15: LD_89_ | EQ15: 1 | ER15: LD_90_ | ES15: 1 | ET15: LD_91_ | EU15: 1 | EV15: LD_92_ | EW15: 1 | EX15: LD_93_ | EY15: 1 | EZ15: LD_94_ | FA15: 1 | FB15: LD_95_ | FC15: 1 | FD15: LD_96_ | FE15: 1 | FF15: LD_99_ | FG15: 1 | FH15: LD_100_ | FI15: 1 | FJ15: LD_101_ | FK15: 1 | FL15: Landero | FM15: LD
D17: CASA | E17: C_ING | F17: CASA | G17: C_ING | H17: CASA | I17: C_ING | J17: CASA | K17: C_ING | L17: CASA | M17: C_ING | N17: CASA | O17: C_ING | P17: CASA | Q17: C_ING | R17: CASA | S17: C_ING | T17: CASA | U17: C_ING | V17: CASA | W17: C_ING | X17: calle | Y17: CALLE
D18: RM_9_A | E18: 1 | F18: RM_9_B | G18: 1 | H18: RM_10_A | I18: 1 | J18: RM_10_B | K18: 1 | L18: RM_17_ | M18: 1 | N18: RM_23_A | O18: 1 | P18: RM_23_B | Q18: 1 | R18: RM_30_ | S18: 1 | T18: RM_33_ | U18: 1 | V18: RM_58_ | W18: 1 | X18: Romeral | Y18: RM
D20: CASA | E20: C_ING | F20: CASA | G20: C_ING | H20: CASA | I20: C_ING | J20: CASA | K20: C_ING | L20: CASA | M20: C_ING | N20: CASA | O20: C_ING | P20: CASA | Q20: C_ING | R20: CASA | S20: C_ING | T20: CASA | U20: C_ING | V20: CASA | W20: C_ING | X20: CASA | Y20: C_ING | Z20: CASA | AA20: C_ING | AB20: CASA | AC20: C_ING | AD20: CASA | AE20: C_ING | AF20: CASA | AG20: C_ING | AH20: calle | AI20: CALLE
D21: RV_1_ | E21: 1 | F21: RV_2_ | G21: 1 | H21: RV_3_ | I21: 1 | J21: RV_173_ | K21: 1 | L21: RV_175_A | M21: 1 | N21: RV_175_B | O21: 1 | P21: RV_175_0 | Q21: 1 | R21: RV_179_ | S21: 1 | T21: RV_181_ | U21: 1 | V21: RV_183_ | W21: 1 | X21: RV_187_ | Y21: 1 | Z21: RV_189_ | AA21: 1 | AB21: RV_193_ | AC21: 1 | AD21: RV_195_ | AE21: 1 | AF21: RV_197_ | AG21: 1 | AH21: Recoveco | AI21: RV
D23: CASA | E23: C_ING | F23: CASA | G23: C_ING | H23: CASA | I23: C_ING | J23: CASA | K23: C_ING | L23: CASA | M23: C_ING | N23: CASA | O23: C_ING | P23: CASA | Q23: C_ING | R23: CASA | S23: C_ING | T23: CASA | U23: C_ING | V23: CASA | W23: C_ING | X23: CASA | Y23: C_ING | Z23: CASA | AA23: C_ING | AB23: CASA | AC23: C_ING | AD23: CASA | AE23: C_ING | AF23: CASA | AG23: C_ING | AH23: CASA | AI23: C_ING | AJ23: CASA | AK23: C_ING | AL23: CASA | AM23: C_ING | AN23: CASA | AO23: C_ING | AP23: CASA | AQ23: C_ING | AR23: CASA | AS23: C_ING | AT23: CASA | AU23: C_ING | AV23: CASA | AW23: C_ING | AX23: CASA | AY23: C_ING | AZ23: CASA | BA23: C_ING | BB23: CASA | BC23: C_ING | BD23: CASA | BE23: C_ING | BF23: CASA | BG23: C_ING | BH23: CASA | BI23: C_ING | BJ23: CASA | BK23: C_ING | BL23: CASA | BM23: C_ING | BN23: CASA | BO23: C_ING | BP23: CASA | BQ23: C_ING | BR23: CASA | BS23: C_ING | BT23: CASA | BU23: C_ING | BV23: CASA | BW23: C_ING | BX23: CASA | BY23: C_ING | BZ23: CASA | CA23: C_ING | CB23: CASA | CC23: C_ING | CD23: CASA | CE23: C_ING | CF23: CASA | CG23: C_ING | CH23: CASA | CI23: C_ING | CJ23: CASA | CK23: C_ING | CL23: CASA | CM23: C_ING | CN23: CASA | CO23: C_ING | CP23: CASA | CQ23: C_ING | CR23: CASA | CS23: C_ING | CT23: CASA | CU23: C_ING | CV23: CASA | CW23: C_ING | CX23: CASA | CY23: C_ING | CZ23: CASA | DA23: C_ING | DB23: CASA | DC23: C_ING | DD23: CASA | DE23: C_ING | DF23: CASA | DG23: C_ING | DH23: CASA | DI23: C_ING | DJ23: CASA | DK23: C_ING | DL23: CASA | DM23: C_ING | DN23: CASA | DO23: C_ING | DP23: CASA | DQ23: C_ING | DR23: CASA | DS23: C_ING | DT23: CASA | DU23: C_ING | DV23: CASA | DW23: C_ING | DX23: CASA | DY23: C_ING | DZ23: CASA | EA23: C_ING | EB23: CASA | EC23: C_ING | ED23: CASA | EE23: C_ING | EF23: CASA | EG23: C_ING | EH23: CASA | EI23: C_ING | EJ23: CASA | EK23: C_ING | EL23: CASA | EM23: C_ING | EN23: CASA | EO23: C_ING | EP23: CASA | EQ23: C_ING | ER23: CASA | ES23: C_ING | ET23: CASA | EU23: C_ING | EV23: CASA | EW23: C_ING | EX23: CASA | EY23: C_ING | EZ23: CASA | FA23: C_ING | FB23: CASA | FC23: C_ING | FD23: CASA | FE23: C_ING | FF23: CASA | FG23: C_ING | FH23: CASA | FI23: C_ING | FJ23: CASA | FK23: C_ING | FL23: CASA | FM23: C_ING | FN23: CASA | FO23: C_ING | FP23: CASA | FQ23: C_ING | FR23: CASA | FS23: C_ING | FT23: CASA | FU23: C_ING | FV23: CASA | FW23: C_ING | FX23: CASA | FY23: C_ING | FZ23: CASA | GA23: C_ING | GB23: CASA | GC23: C_ING | GD23: CASA | GE23: C_ING | GF23: CASA | GG23: C_ING | GH23: CASA | GI23: C_ING | GJ23: CASA | GK23: C_ING | GL23: CASA | GM23: C_ING | GN23: CASA | GO23: C_ING | GP23: CASA | GQ23: C_ING | GR23: CASA | GS23: C_ING | GT23: CASA | GU23: C_ING | GV23: CASA | GW23: C_ING | GX23: calle | GY23: CALLE
D24: UP_5_B | E24: 1 | F24: UP_7_ | G24: 1 | H24: UP_8_ | I24: 1 | J24: UP_9_ | K24: 1 | L24: UP_10_ | M24: 1 | N24: UP_11_ | O24: 1 | P24: UP_12_ | Q24: 1 | R24: UP_14_ | S24: 1 | T24: UP_15_ | U24: 1 | V24: UP_16_ | W24: 1 | X24: UP_18_ | Y24: 1 | Z24: UP_19_ | AA24: 1 | AB24: UP_20_ | AC24: 1 | AD24: UP_21_ | AE24: 1 | AF24: UP_23_ | AG24: 1 | AH24: UP_24_ | AI24: 1 | AJ24: UP_26_ | AK24: 1 | AL24: UP_30_ | AM24: 1 | AN24: UP_31_ | AO24: 1 | AP24: UP_32_ | AQ24: 1 | AR24: UP_33_ | AS24: 1 | AT24: UP_34_ | AU24: 1 | AV24: UP_35_ | AW24: 1 | AX24: UP_36_ | AY24: 1 | AZ24: UP_37_ | BA24: 1 | BB24: UP_39_ | BC24: 1 | BD24: UP_40_ | BE24: 1 | BF24: UP_42_ | BG24: 1 | BH24: UP_43_ | BI24: 1 | BJ24: UP_44_ | BK24: 1 | BL24: UP_45_ | BM24: 1 | BN24: UP_46_ | BO24: 1 | BP24: UP_47_ | BQ24: 1 | BR24: UP_48_ | BS24: 1 | BT24: UP_49_ | BU24: 1 | BV24: UP_50_ | BW24: 1 | BX24: UP_51_1 | BY24: 1 | BZ24: UP_51_2 | CA24: 1 | CB24: UP_52_ | CC24: 1 | CD24: UP_54_ | CE24: 1 | CF24: UP_55_ | CG24: 1 | CH24: UP_56_ | CI24: 1 | CJ24: UP_57_ | CK24: 1 | CL24: UP_60_ | CM24: 1 | CN24: UP_61_ | CO24: 1 | CP24: UP_62_ | CQ24: 1 | CR24: UP_63_ | CS24: 1 | CT24: UP_64_ | CU24: 1 | CV24: UP_65_ | CW24: 1 | CX24: UP_68_ | CY24: 1 | CZ24: UP_69_ | DA24: 1 | DB24: UP_70_ | DC24: 1 | DD24: UP_72_ | DE24: 1 | DF24: UP_71_ | DG24: 1 | DH24: UP_73_A | DI24: 1 | DJ24: UP_73_B | DK24: 1 | DL24: UP_74_ | DM24: 1 | DN24: UP_75_ | DO24: 1 | DP24: UP_76_ | DQ24: 1 | DR24: UP_77_ | DS24: 1 | DT24: UP_78_ | DU24: 1 | DV24: UP_79_ | DW24: 1 | DX24: UP_80_ | DY24: 1 | DZ24: UP_85_ | EA24: 1 | EB24: UP_86_ | EC24: 1 | ED24: UP_87_ | EE24: 1 | EF24: UP_88_ | EG24: 1 | EH24: UP_89_ | EI24: 1 | EJ24: UP_90_ | EK24: 1 | EL24: UP_91_ | EM24: 1 | EN24: UP_92_ | EO24: 1 | EP24: UP_93_ | EQ24: 1 | ER24: UP_94_ | ES24: 1 | ET24: UP_95_ | EU24: 1 | EV24: UP_96_ | EW24: 1 | EX24: UP_99_ | EY24: 1 | EZ24: UP_100_ | FA24: 1 | FB24: UP_101_ | FC24: 1 | FD24: UP_102_ | FE24: 1 | FF24: UP_103_ | FG24: 1 | FH24: UP_104_ | FI24: 1 | FJ24: UP_106_ | FK24: 1 | FL24: UP_108_ | FM24: 1 | FN24: UP_110_ | FO24: 1 | FP24: UP_114_ | FQ24: 1 | FR24: UP_116_ | FS24: 1 | FT24: UP_118_ | FU24: 1 | FV24: UP_120_ | FW24: 1 | FX24: UP_122_ | FY24: 1 | FZ24: UP_124_ | GA24: 1 | GB24: UP_128_ | GC24: 1 | GD24: UP_130_ | GE24: 1 | GF24: UP_132_ | GG24: 1 | GH24: UP_134_ | GI24: 1 | GJ24: UP_136_ | GK24: 1 | GL24: UP_138_ | GM24: 1 | GN24: UP_140_ | GO24: 1 | GP24: UP_142_ | GQ24: 1 | GR24: UP_144_ | GS24: 1 | GT24: UP_146_ | GU24: 1 | GV24: UP_148_ | GW24: 1 | GX24: Upácuaro | GY24: UP
D26: CASA | E26: C_ING | F26: CASA | G26: C_ING | H26: CASA | I26: C_ING | J26: CASA | K26: C_ING | L26: CASA | M26: C_ING | N26: CASA | O26: C_ING | P26: CASA | Q26: C_ING | R26: CASA | S26: C_ING | T26: CASA | U26: C_ING | V26: CASA | W26: C_ING | X26: CASA | Y26: C_ING | Z26: CASA | AA26: C_ING | AB26: CASA | AC26: C_ING | AD26: CASA | AE26: C_ING | AF26: CASA | AG26: C_ING | AH26: CASA | AI26: C_ING | AJ26: CASA | AK26: C_ING | AL26: CASA | AM26: C_ING | AN26: CASA | AO26: C_ING | AP26: CASA | AQ26: C_ING | AR26: CASA | AS26: C_ING | AT26: CASA | AU26: C_ING | AV26: CASA | AW26: C_ING | AX26: CASA | AY26: C_ING | AZ26: CASA | BA26: C_ING | BB26: CASA | BC26: C_ING | BD26: CASA | BE26: C_ING | BF26: CASA | BG26: C_ING | BH26: CASA | BI26: C_ING | BJ26: CASA | BK26: C_ING | BL26: CASA | BM26: C_ING | BN26: CASA | BO26: C_ING | BP26: CASA | BQ26: C_ING | BR26: calle | BS26: CALLE
D27: ZB_6_ | E27: 1 | F27: ZB_8_ | G27: 1 | H27: ZB_10_ | I27: 1 | J27: ZB_12_ | K27: 1 | L27: ZB_14_ | M27: 1 | N27: ZB_18_ | O27: 1 | P27: ZB_20_ | Q27: 1 | R27: ZB_22_ | S27: 1 | T27: ZB_24_ | U27: 1 | V27: ZB_26_ | W27: 1 | X27: ZB_30_ | Y27: 1 | Z27: ZB_34_ | AA27: 1 | AB27: ZB_36_ | AC27: 1 | AD27: ZB_38_ | AE27: 1 | AF27: ZB_40_ | AG27: 1 | AH27: ZB_42_ | AI27: 1 | AJ27: ZB_44_ | AK27: 1 | AL27: ZB_46_ | AM27: 1 | AN27: ZB_50_ | AO27: 1 | AP27: ZB_54_ | AQ27: 1 | AR27: ZB_56_ | AS27: 1 | AT27: ZB_58_ | AU27: 1 | AV27: ZB_60_ | AW27: 1 | AX27: ZB_62_ | AY27: 1 | AZ27: ZB_66_ | BA27: 1 | BB27: ZB_68_ | BC27: 1 | BD27: ZB_72_ | BE27: 1 | BF27: ZB_74_ | BG27: 1 | BH27: ZB_76_ | BI27: 1 | BJ27: ZB_80_ | BK27: 1 | BL27: ZB_82_ | BM27: 1 | BN27: ZB_84_ | BO27: 1 | BP27: ZB_88_ | BQ27: 1 | BR27: Zinamba | BS27: ZB
D30: Ingresos / código de ingresos
D31: C_ING | E31: C_ING | F31: C_ING | G31: C_ING | H31: C_ING | I31: C_ING | J31: C_ING | K31: C_ING
D32: 1 | E32: 2 | F32: 3 | G32: 4 | H32: 5 | I32: 6 | J32: 7
A33: 1 | B33: Cuotas de vigilancia
A34: 2 | B34: Cuotas extraordinarias
A35: 3 | B35: Venta de llaves
A36: 4 | B36: Venta de tarjetas electrónicas
A37: 5 | B37: Venta de tarjetones
A38: 6 | B38: Aportación Colegio Carmel
A39: 7 | B39: Otros ingresos | D39: Criterios para índices de cobranza. Todas las viviendas
B40: Suma de ingresos | D40: calle | E40: factor | F40: calle | G40: factor | H40: calle | I40: factor | J40: calle | K40: factor | L40: calle | M40: factor | N40: calle | O40: factor | P40: calle | Q40: factor | R40: calle | S40: factor | T40: calle | U40: factor | V40: calle | W40: factor | X40: calle | Y40: factor
D41: Cuchilla | F41: Cafetales | H41: Estopila | J41: Estanzuela | L41: Hueso | N41: Landero | P41: Romeral | R41: Recoveco | T41: Upácuaro | V41: Zinamba | X41: Carmel
D43: Criterios para índices de cobranza. Viviendas con algún pago en el período.
D44: calle | E44: factor | F44: calle | G44: factor | H44: calle | I44: factor | J44: calle | K44: factor | L44: calle | M44: factor | N44: calle | O44: factor | P44: calle | Q44: factor | R44: calle | S44: factor | T44: calle | U44: factor | V44: calle | W44: factor | X44: calle | Y44: factor
D45: Cuchilla | E45: >0 | F45: Cafetales | G45: >0 | H45: Estopila | I45: >0 | J45: Estanzuela | K45: >0 | L45: Hueso | M45: >0 | N45: Landero | O45: >0 | P45: Romeral | Q45: >0 | R45: Recoveco | S45: >0 | T45: Upácuaro | U45: >0 | V45: Zinamba | W45: >0 | X45: Carmel | Y45: >0
D48: Criterios para localizar depósitos de cuotas en chequera
D49: CASA | E49: CASA | F49: CASA | G49: CASA | H49: CASA | I49: CASA | J49: CASA
D50: CM_130_A | E50: CL_29_ | F50: EZ_15_A | G50: UP_46_ | H50: UP_86_ | I50: LD_58_ | J50: CL_18_
...

Sheet cobranza 2013
B1: 1 | C1: 2 | D1: 3 | E1: 4 | F1: 5 | G1: 6 | H1: 7 | I1: 8 | J1: 9 | K1: 10 | L1: 11 | M1: 12 | N1: 13 | O1: 14 | P1: 15 | Q1: 16 | R1: 17 | S1: 18 | T1: 19 | U1: 20 | V1: 21
C2: Asociación de Colonos HACIENDAS DE COYOACÁN
C3: Reporte de cuotas de vigilancia recibidas
C4: Período: enero - septiembre de 2013
F5: =SUM(F8:F448) -> 102125 | G5: =SUM(G8:G448) -> 763495 | H5: =SUM(H8:H448) -> 865620 | K5: =SUM(K8:K448) -> 92475 | L5: =SUM(L8:L448) -> 93125.28 | M5: =SUM(M8:M448) -> 87725 | N5: =SUM(N8:N448) -> 75225 | O5: =SUM(O8:O448) -> 95645 | P5: =SUM(P8:P448) -> 83475 | Q5: =SUM(Q8:Q448) -> 79425 | R5: =SUM(R8:R448) -> 76875 | ... V5: =SUM(V8:V448) -> 3350
B6: CASA | C6: Domicilio | D6: Familia | E6: cuota | F6: 2012 | G6: 2013 | H6: importe | I6: factor | J6: calle | K6: ENE | L6: FEB | M6: MAR | N6: ABR | O6: MAY | P6: JUN | Q6: JUL | R6: AGO | S6: SEP | T6: OCT | U6: NOV | V6: DIC
B8: CL_7_101 | C8: =VLOOKUP(B8,BASE_A,6,FALSE) -> Rancho La Cuchilla No. 7, 101 | D8: =VLOOKUP(B8,BASE_A,8,FALSE) -> Olivares | E8: =VLOOKUP(B8,BASE_A,9,FALSE) -> 100 | F8: =DSUM(SEP_2013_A,AA,CL_7_101) -> 100 | G8: =H8-F8 -> 900 | H8: =DSUM(SEP_2013_A,importe,CL_7_101) -> 1000 | I8: =IF(VLOOKUP(B8,BASE_A,9,FALSE)=0,0,G8/VLOOKUP(B8,BASE_A,9,FALSE)) -> 9 | J8: Cuchilla | K8: =DSUM(SEP_2013_A,23,CL_7_101) -> 100 | L8: =DSUM(SEP_2013_A,24,CL_7_101) -> 100 | M8: =DSUM(SEP_2013_A,25,CL_7_101) -> 100 | N8: =DSUM(SEP_2013_A,26,CL_7_101) -> 100 | O8: =DSUM(SEP_2013_A,27,CL_7_101) -> 100 | P8: =DSUM(SEP_2013_A,28,CL_7_101) -> 100 | Q8: =DSUM(SEP_2013_A,29,CL_7_101) -> 100 | R8: =DSUM(SEP_2013_A,30,CL_7_101) -> 100 | S8: =DSUM(SEP_2013_A,31,CL_7_101) -> 100 | T8: =DSUM(SEP_2013_A,32,CL_7_101) -> 0 | U8: =DSUM(SEP_2013_A,33,CL_7_101) -> 0 | V8: =DSUM(SEP_2013_A,34,CL_7_101) -> 0
B9: CL_7_102 | C9: =VLOOKUP(B9,BASE_A,6,FALSE) -> Rancho La Cuchilla No. 7, 102 | D9: =VLOOKUP(B9,BASE_A,8,FALSE) -> García Moreno | E9: =VLOOKUP(B9,BASE_A,9,FALSE) -> 100 | F9: =DSUM(SEP_2013_A,AA,CL_7_102) -> 300 | G9: =H9-F9 -> 900 | H9: =DSUM(SEP_2013_A,importe,CL_7_102) -> 1200 | I9: =IF(VLOOKUP(B9,BASE_A,9,FALSE)=0,0,G9/VLOOKUP(B9,BASE_A,9,FALSE)) -> 9 | J9: Cuchilla | K9: =DSUM(SEP_2013_A,23,CL_7_102) -> 100 | L9: =DSUM(SEP_2013_A,24,CL_7_102) -> 100 | M9: =DSUM(SEP_2013_A,25,CL_7_102) -> 100 | N9: =DSUM(SEP_2013_A,26,CL_7_102) -> 100 | O9: =DSUM(SEP_2013_A,27,CL_7_102) -> 100 | P9: =DSUM(SEP_2013_A,28,CL_7_102) -> 100 | Q9: =DSUM(SEP_2013_A,29,CL_7_102) -> 100 | R9: =DSUM(SEP_2013_A,30,CL_7_102) -> 100 | S9: =DSUM(SEP_2013_A,31,CL_7_102) -> 100 | T9: =DSUM(SEP_2013_A,32,CL_7_102) -> 0 | U9: =DSUM(SEP_2013_A,33,CL_7_102) -> 0 | V9: =DSUM(SEP_2013_A,34,CL_7_102) -> 0
B10: CL_7_201 | C10: =VLOOKUP(B10,BASE_A,6,FALSE) -> Rancho La Cuchilla No. 7, 201 | D10: =VLOOKUP(B10,BASE_A,8,FALSE) -> Solís Susana | E10: =VLOOKUP(B10,BASE_A,9,FALSE) -> 100 | F10: =DSUM(SEP_2013_A,AA,CL_7_201) -> 0 | G10: =H10-F10 -> 0 | H10: =DSUM(SEP_2013_A,importe,CL_7_201) -> 0 | I10: =IF(VLOOKUP(B10,BASE_A,9,FALSE)=0,0,G10/VLOOKUP(B10,BASE_A,9,FALSE)) -> 0 | J10: Cuchilla | K10: =DSUM(SEP_2013_A,23,CL_7_201) -> 0 | L10: =DSUM(SEP_2013_A,24,CL_7_201) -> 0 | M10: =DSUM(SEP_2013_A,25,CL_7_201) -> 0 | N10: =DSUM(SEP_2013_A,26,CL_7_201) -> 0 | O10: =DSUM(SEP_2013_A,27,CL_7_201) -> 0 | P10: =DSUM(SEP_2013_A,28,CL_7_201) -> 0 | Q10: =DSUM(SEP_2013_A,29,CL_7_201) -> 0 | R10: =DSUM(SEP_2013_A,30,CL_7_201) -> 0 | S10: =DSUM(SEP_2013_A,31,CL_7_201) -> 0 | T10: =DSUM(SEP_2013_A,32,CL_7_201) -> 0 | U10: =DSUM(SEP_2013_A,33,CL_7_201) -> 0 | V10: =DSUM(SEP_2013_A,34,CL_7_201) -> 0
B11: CL_7_202 | C11: =VLOOKUP(B11,BASE_A,6,FALSE) -> Rancho La Cuchilla No. 7, 202 | D11: =VLOOKUP(B11,BASE_A,8,FALSE) -> Carbajal Zayas | E11: =VLOOKUP(B11,BASE_A,9,FALSE) -> 100 | F11: =DSUM(SEP_2013_A,AA,CL_7_202) -> 400 | G11: =H11-F11 -> 800 | H11: =DSUM(SEP_2013_A,importe,CL_7_202) -> 1200 | I11: =IF(VLOOKUP(B11,BASE_A,9,FALSE)=0,0,G11/VLOOKUP(B11,BASE_A,9,FALSE)) -> 8 | J11: Cuchilla | K11: =DSUM(SEP_2013_A,23,CL_7_202) -> 100 | L11: =DSUM(SEP_2013_A,24,CL_7_202) -> 100 | M11: =DSUM(SEP_2013_A,25,CL_7_202) -> 100 | N11: =DSUM(SEP_2013_A,26,CL_7_202) -> 100 | O11: =DSUM(SEP_2013_A,27,CL_7_202) -> 100 | P11: =DSUM(SEP_2013_A,28,CL_7_202) -> 100 | Q11: =DSUM(SEP_2013_A,29,CL_7_202) -> 100 | R11: =DSUM(SEP_2013_A,30,CL_7_202) -> 100 | S11: =DSUM(SEP_2013_A,31,CL_7_202) -> 0 | T11: =DSUM(SEP_2013_A,32,CL_7_202) -> 0 | U11: =DSUM(SEP_2013_A,33,CL_7_202) -> 0 | V11: =DSUM(SEP_2013_A,34,CL_7_202) -> 0
B12: CL_9_ | C12: =VLOOKUP(B12,BASE_A,6,FALSE) -> Rancho La Cuchilla No. 9 | D12: =VLOOKUP(B12,BASE_A,8,FALSE) -> Martín del Campo | E12: =VLOOKUP(B12,BASE_A,9,FALSE) -> 300 | F12: =DSUM(SEP_2013_A,AA,CL_9_) -> 600 | G12: =H12-F12 -> 300 | H12: =DSUM(SEP_2013_A,importe,CL_9_) -> 900 | I12: =IF(VLOOKUP(B12,BASE_A,9,FALSE)=0,0,G12/VLOOKUP(B12,BASE_A,9,FALSE)) -> 1 | J12: Cuchilla | K12: =DSUM(SEP_2013_A,23,CL_9_) -> 300 | L12: =DSUM(SEP_2013_A,24,CL_9_) -> 0 | M12: =DSUM(SEP_2013_A,25,CL_9_) -> 0 | N12: =DSUM(SEP_2013_A,26,CL_9_) -> 0 | O12: =DSUM(SEP_2013_A,27,CL_9_) -> 0 | P12: =DSUM(SEP_2013_A,28,CL_9_) -> 0 | Q12: =DSUM(SEP_2013_A,29,CL_9_) -> 0 | R12: =DSUM(SEP_2013_A,30,CL_9_) -> 0 | S12: =DSUM(SEP_2013_A,31,CL_9_) -> 0 | T12: =DSUM(SEP_2013_A,32,CL_9_) -> 0 | U12: =DSUM(SEP_2013_A,33,CL_9_) -> 0 | V12: =DSUM(SEP_2013_A,34,CL_9_) -> 0
B13: CL_11_ | C13: =VLOOKUP(B13,BASE_A,6,FALSE) -> Rancho La Cuchilla No. 11 | D13: =VLOOKUP(B13,BASE_A,8,FALSE) -> Santiago | E13: =VLOOKUP(B13,BASE_A,9,FALSE) -> 300 | F13: =DSUM(SEP_2013_A,AA,CL_11_) -> 0 | G13: =H13-F13 -> 0 | H13: =DSUM(SEP_2013_A,importe,CL_11_) -> 0 | I13: =IF(VLOOKUP(B13,BASE_A,9,FALSE)=0,0,G13/VLOOKUP(B13,BASE_A,9,FALSE)) -> 0 | J13: Cuchilla | K13: =DSUM(SEP_2013_A,23,CL_11_) -> 0 | L13: =DSUM(SEP_2013_A,24,CL_11_) -> 0 | M13: =DSUM(SEP_2013_A,25,CL_11_) -> 0 | N13: =DSUM(SEP_2013_A,26,CL_11_) -> 0 | O13: =DSUM(SEP_2013_A,27,CL_11_) -> 0 | P13: =DSUM(SEP_2013_A,28,CL_11_) -> 0 | Q13: =DSUM(SEP_2013_A,29,CL_11_) -> 0 | R13: =DSUM(SEP_2013_A,30,CL_11_) -> 0 | S13: =DSUM(SEP_2013_A,31,CL_11_) -> 0 | T13: =DSUM(SEP_2013_A,32,CL_11_) -> 0 | U13: =DSUM(SEP_2013_A,33,CL_11_) -> 0 | V13: =DSUM(SEP_2013_A,34,CL_11_) -> 0
B14: CL_12_ | C14: =VLOOKUP(B14,BASE_A,6,FALSE) -> Rancho La Cuchilla No. 12 | D14: =VLOOKUP(B14,BASE_A,8,FALSE) -> Rivera Flores | E14: =VLOOKUP(B14,BASE_A,9,FALSE) -> 300 | F14: =DSUM(SEP_2013_A,AA,CL_12_) -> 250 | G14: =H14-F14 -> 2700 | H14: =DSUM(SEP_2013_A,importe,CL_12_) -> 2950 | I14: =IF(VLOOKUP(B14,BASE_A,9,FALSE)=0,0,G14/VLOOKUP(B14,BASE_A,9,FALSE)) -> 9 | J14: Cuchilla | K14: =DSUM(SEP_2013_A,23,CL_12_) -> 300 | L14: =DSUM(SEP_2013_A,24,CL_12_) -> 300 | M14: =DSUM(SEP_2013_A,25,CL_12_) -> 300 | N14: =DSUM(SEP_2013_A,26,CL_12_) -> 300 | O14: =DSUM(SEP_2013_A,27,CL_12_) -> 300 | P14: =DSUM(SEP_2013_A,28,CL_12_) -> 300 | Q14: =DSUM(SEP_2013_A,29,CL_12_) -> 300 | R14: =DSUM(SEP_2013_A,30,CL_12_) -> 300 | S14: =DSUM(SEP_2013_A,31,CL_12_) -> 300 | T14: =DSUM(SEP_2013_A,32,CL_12_) -> 0 | U14: =DSUM(SEP_2013_A,33,CL_12_) -> 0 | V14: =DSUM(SEP_2013_A,34,CL_12_) -> 0
B15: CL_13_ | C15: =VLOOKUP(B15,BASE_A,6,FALSE) -> Rancho La Cuchilla No. 13 | D15: =VLOOKUP(B15,BASE_A,8,FALSE) -> Torres | E15: =VLOOKUP(B15,BASE_A,9,FALSE) -> 300 | F15: =DSUM(SEP_2013_A,AA,CL_13_) -> 0 | G15: =H15-F15 -> 0 | H15: =DSUM(SEP_2013_A,importe,CL_13_) -> 0 | I15: =IF(VLOOKUP(B15,BASE_A,9,FALSE)=0,0,G15/VLOOKUP(B15,BASE_A,9,FALSE)) -> 0 | J15: Cuchilla | K15: =DSUM(SEP_2013_A,23,CL_13_) -> 0 | L15: =DSUM(SEP_2013_A,24,CL_13_) -> 0 | M15: =DSUM(SEP_2013_A,25,CL_13_) -> 0 | N15: =DSUM(SEP_2013_A,26,CL_13_) -> 0 | O15: =DSUM(SEP_2013_A,27,CL_13_) -> 0 | P15: =DSUM(SEP_2013_A,28,CL_13_) -> 0 | Q15: =DSUM(SEP_2013_A,29,CL_13_) -> 0 | R15: =DSUM(SEP_2013_A,30,CL_13_) -> 0 | S15: =DSUM(SEP_2013_A,31,CL_13_) -> 0 | T15: =DSUM(SEP_2013_A,32,CL_13_) -> 0 | U15: =DSUM(SEP_2013_A,33,CL_13_) -> 0 | V15: =DSUM(SEP_2013_A,34,CL_13_) -> 0
B16: CL_14_ | C16: =VLOOKUP(B16,BASE_A,6,FALSE) -> Rancho La Cuchilla No. 14 | D16: =VLOOKUP(B16,BASE_A,8,FALSE) -> Chávez Lara | E16: =VLOOKUP(B16,BASE_A,9,FALSE) -> 300 | F16: =DSUM(SEP_2013_A,AA,CL_14_) -> 0 | G16: =H16-F16 -> 1200 | H16: =DSUM(SEP_2013_A,importe,CL_14_) -> 1200 | I16: =IF(VLOOKUP(B16,BASE_A,9,FALSE)=0,0,G16/VLOOKUP(B16,BASE_A,9,FALSE)) -> 4 | J16: Cuchilla | K16: =DSUM(SEP_2013_A,23,CL_14_) -> 0 | L16: =DSUM(SEP_2013_A,24,CL_14_) -> 0 | M16: =DSUM(SEP_2013_A,25,CL_14_) -> 0 | N16: =DSUM(SEP_2013_A,26,CL_14_) -> 0 | O16: =DSUM(SEP_2013_A,27,CL_14_) -> 300 | P16: =DSUM(SEP_2013_A,28,CL_14_) -> 300 | Q16: =DSUM(SEP_2013_A,29,CL_14_) -> 300 | R16: =DSUM(SEP_2013_A,30,CL_14_) -> 300 | S16: =DSUM(SEP_2013_A,31,CL_14_) -> 0 | T16: =DSUM(SEP_2013_A,32,CL_14_) -> 0 | U16: =DSUM(SEP_2013_A,33,CL_14_) -> 0 | V16: =DSUM(SEP_2013_A,34,CL_14_) -> 0
B17: CL_15_ | C17: =VLOOKUP(B17,BASE_A,6,FALSE) -> Rancho La Cuchilla No. 15 | D17: =VLOOKUP(B17,BASE_A,8,FALSE) -> Guerrero Ponce | E17: =VLOOKUP(B17,BASE_A,9,FALSE) -> 300 | F17: =DSUM(SEP_2013_A,AA,CL_15_) -> 900 | G17: =H17-F17 -> 2400 | H17: =DSUM(SEP_2013_A,importe,CL_15_) -> 3300 | I17: =IF(VLOOKUP(B17,BASE_A,9,FALSE)=0,0,G17/VLOOKUP(B17,BASE_A,9,FALSE)) -> 8 | J17: Cuchilla | K17: =DSUM(SEP_2013_A,23,CL_15_) -> 300 | L17: =DSUM(SEP_2013_A,24,CL_15_) -> 300 | M17: =DSUM(SEP_2013_A,25,CL_15_) -> 300 | N17: =DSUM(SEP_2013_A,26,CL_15_) -> 300 | O17: =DSUM(SEP_2013_A,27,CL_15_) -> 300 | P17: =DSUM(SEP_2013_A,28,CL_15_) -> 300 | Q17: =DSUM(SEP_2013_A,29,CL_15_) -> 300 | R17: =DSUM(SEP_2013_A,30,CL_15_) -> 300 | S17: =DSUM(SEP_2013_A,31,CL_15_) -> 0 | T17: =DSUM(SEP_2013_A,32,CL_15_) -> 0 | U17: =DSUM(SEP_2013_A,33,CL_15_) -> 0 | V17: =DSUM(SEP_2013_A,34,CL_15_) -> 0
B18: CL_18_ | C18: =VLOOKUP(B18,BASE_A,6,FALSE) -> Rancho La Cuchilla No. 18 | D18: =VLOOKUP(B18,BASE_A,8,FALSE) -> Aldana Sánchez | E18: =VLOOKUP(B18,BASE_A,9,FALSE) -> 300 | F18: =DSUM(SEP_2013_A,AA,CL_18_) -> 300 | G18: =H18-F18 -> 2700 | H18: =DSUM(SEP_2013_A,importe,CL_18_) -> 3000 | I18: =IF(VLOOKUP(B18,BASE_A,9,FALSE)=0,0,G18/VLOOKUP(B18,BASE_A,9,FALSE)) -> 9 | J18: Cuchilla | K18: =DSUM(SEP_2013_A,23,CL_18_) -> 300 | L18: =DSUM(SEP_2013_A,24,CL_18_) -> 300 | M18: =DSUM(SEP_2013_A,25,CL_18_) -> 300 | N18: =DSUM(SEP_2013_A,26,CL_18_) -> 300 | O18: =DSUM(SEP_2013_A,27,CL_18_) -> 300 | P18: =DSUM(SEP_2013_A,28,CL_18_) -> 300 | Q18: =DSUM(SEP_2013_A,29,CL_18_) -> 300 | R18: =DSUM(SEP_2013_A,30,CL_18_) -> 300 | S18: =DSUM(SEP_2013_A,31,CL_18_) -> 300 | T18: =DSUM(SEP_2013_A,32,CL_18_) -> 0 | U18: =DSUM(SEP_2013_A,33,CL_18_) -> 0 | V18: =DSUM(SEP_2013_A,34,CL_18_) -> 0
B19: CL_19_ | C19: =VLOOKUP(B19,BASE_A,6,FALSE) -> Rancho La Cuchilla No. 19 | D19: =VLOOKUP(B19,BASE_A,8,FALSE) -> Tapia Vázquez | E19: =VLOOKUP(B19,BASE_A,9,FALSE) -> 300 | F19: =DSUM(SEP_2013_A,AA,CL_19_) -> 300 | G19: =H19-F19 -> 2700 | H19: =DSUM(SEP_2013_A,importe,CL_19_) -> 3000 | I19: =IF(VLOOKUP(B19,BASE_A,9,FALSE)=0,0,G19/VLOOKUP(B19,BASE_A,9,FALSE)) -> 9 | J19: Cuchilla | K19: =DSUM(SEP_2013_A,23,CL_19_) -> 300 | L19: =DSUM(SEP_2013_A,24,CL_19_) -> 300 | M19: =DSUM(SEP_2013_A,25,CL_19_) -> 300 | N19: =DSUM(SEP_2013_A,26,CL_19_) -> 300 | O19: =DSUM(SEP_2013_A,27,CL_19_) -> 300 | P19: =DSUM(SEP_2013_A,28,CL_19_) -> 300 | Q19: =DSUM(SEP_2013_A,29,CL_19_) -> 300 | R19: =DSUM(SEP_2013_A,30,CL_19_) -> 300 | S19: =DSUM(SEP_2013_A,31,CL_19_) -> 300 | T19: =DSUM(SEP_2013_A,32,CL_19_) -> 0 | U19: =DSUM(SEP_2013_A,33,CL_19_) -> 0 | V19: =DSUM(SEP_2013_A,34,CL_19_) -> 0
