Workbook
Name ABR_2016: Recibos!$B$590:$H$785
Name ABR_2017: Recibos!$B$3786:$AX$4044
Name ABR_2018: Recibos!$B$6111:$AW$6361
Name AGO_2016: Recibos!$B$1806:$H$2081
Name AGO_2017: Recibos!$B$4571:$AX$4736
Name AGO_2018: Recibos!$B$6906:$AW$7093
Name BASE: base!$B$5:$D$469
Name DIC_2016: Recibos!$B$2779:$AJ$2975
Name DIC_2017: Recibos!$B$5278:$AW$5478
Name ENE_2016: Recibos!$B$24:$H$274
Name ENE_2017: Recibos!$B$2976:$AJ$3245
Name ENE_2018: Recibos!$B$5479:$AW$5691
Name FEB_2016: Recibos!$B$275:$H$432
Name FEB_2017: Recibos!$B$3246:$AJ$3491
Name FEB_2018: Recibos!$B$5692:$AW$5901
Name G_ABR_2016: Gasto!$B$321:$H$414
Name G_ABR_2017: Gasto!$B$1861:$H$2020
Name G_ABR_2018: Gasto!$B$3256:$H$3352
Name G_ADQ: criterios!$P$3:$P$4
Name G_AGO_2016: Gasto!$B$748:$H$875
Name G_AGO_2017: Gasto!$B$2361:$H$2497
Name G_AGO_2018: Gasto!$B$3681:$H$3780
Name G_AGUA: criterios!$Q$3:$Q$4
Name G_ALMVG: criterios!$R$3:$R$4
Name G_ASLE: criterios!$S$3:$S$4
Name G_CBR: criterios!$T$3:$T$4
Name G_DIC_2016: Gasto!$B$1277:$H$1434
Name G_DIC_2017: Gasto!$B$2802:$H$2932
Name G_DIF: criterios!$U$3:$U$4
Name G_ENE_2016: Gasto!$B$3:$H$96
Name G_ENE_2017: Gasto!$B$1435:$H$1569
Name G_ENE_2018: Gasto!$B$2933:$H$3058
Name G_FEB_2016: Gasto!$B$97:$H$204
Name G_FEB_2017: Gasto!$B$1570:$H$1710
Name G_FEB_2018: Gasto!$B$3059:$H$3156
Name G_HCTB: criterios!$V$3:$V$4
Name G_HJRD: criterios!$W$3:$W$4
Name G_INFRA: criterios!$X$3:$X$4
Name G_IVA: criterios!$Y$3:$Y$4
Name G_JDN: criterios!$Z$3:$Z$4
Name G_JUL_2016: Gasto!$B$629:$H$747
Name G_JUL_2017: Gasto!$B$2257:$H$2360
Name G_JUL_2018: Gasto!$B$3567:$H$3680
Name G_JUN_2016: Gasto!$B$514:$H$628
Name G_JUN_2017: Gasto!$B$2159:$H$2256
Name G_JUN_2018: Gasto!$B$3449:$H$3566
Name G_MAR_2016: Gasto!$B$205:$H$320
Name G_MAR_2017: Gasto!$B$1711:$H$1860
Name G_MAR_2018: Gasto!$B$3157:$H$3255
Name G_MAY_2016: Gasto!$B$415:$H$513
Name G_MAY_2017: Gasto!$B$2021:$H$2158
Name G_MAY_2018: Gasto!$B$3353:$H$3448
Name G_MDC: criterios!$AA$3:$AA$4
Name G_MTCBQ: criterios!$AB$3:$AB$4
Name G_MTCP: criterios!$AC$3:$AC$4
Name G_MTCST: criterios!$AD$3:$AD$4
Name G_MTCYP: criterios!$AE$3:$AE$4
Name G_MTILM: criterios!$AF$3:$AF$4
Name G_MTLPZ: criterios!$AG$3:$AG$4
Name G_MTPTA: criterios!$AH$3:$AH$4

Sheet base
B4: 1 | C4: 2 | D4: 3 | E4: 4 | F4: 5
A5: N° | B5: CASA | C5: DOMICILIO | D5: FAMILIA
A6: 1 | B6: CL_7_101 | C6: Rancho La Cuchilla No. 7, 101 | D6: Olivares
A7: 2 | B7: CL_7_102 | C7: Rancho La Cuchilla No. 7, 102 | D7: García Moreno
A8: 3 | B8: CL_7_201 | C8: Rancho La Cuchilla No. 7, 201 | D8: Solís Susana
A9: 4 | B9: CL_7_202 | C9: Rancho La Cuchilla No. 7, 202 | D9: Carbajal Zayas
A10: 5 | B10: CL_9_ | C10: Rancho La Cuchilla No. 9 | D10: Martín del Campo
A11: 6 | B11: CL_11_ | C11: Rancho La Cuchilla No. 11 | D11: Santiago
A12: 7 | B12: CL_12_ | C12: Rancho La Cuchilla No. 12 | D12: Rivera Flores
A13: 8 | B13: CL_13_ | C13: Rancho La Cuchilla No. 13 | D13: Torres
A14: 9 | B14: CL_14_ | C14: Rancho La Cuchilla No. 14 | D14: Chávez Lara
A15: 10 | B15: CL_15_ | C15: Rancho La Cuchilla No. 15 | D15: Guerrero Ponce
A16: 11 | B16: CL_17_A | C16: Rancho La Cuchilla No. 17, A
A17: 12 | B17: CL_18_ | C17: Rancho La Cuchilla No. 18 | D17: Aldana Sánchez
A18: 13 | B18: CL_19_ | C18: Rancho La Cuchilla No. 19 | D18: Tapia Vázquez
A19: 14 | B19: CL_20_ | C19: Rancho La Cuchilla No. 20 | D19: Sánchez López
A20: 15 | B20: CL_21_ | C20: Rancho La Cuchilla No. 21 | D20: Solórzano Calderón
A21: 16 | B21: CL_23_ | C21: Rancho La Cuchilla No. 23 | D21: Ocampo
A22: 17 | B22: CL_25_ | C22: Rancho La Cuchilla No. 25 | D22: García de León
A23: 18 | B23: CL_27_ | C23: Rancho La Cuchilla No. 27 | D23: Montoya
A24: 19 | B24: CL_28_ | C24: Rancho La Cuchilla No. 28 | D24: Prado de los S. | E24: Cambio de número de vivienda de 2 a 28. BS 14JUN13
A25: 20 | B25: CL_29_ | C25: Rancho La Cuchilla No. 29 | D25: Vega Sánchez C.
A26: 21 | B26: CL_30_ | C26: Rancho La Cuchilla No. 30 | D26: Ruiz Navarrete
A27: 22 | B27: CL_31_ | C27: Rancho La Cuchilla No. 31 | D27: Lince
A28: 23 | B28: CL_32_ | C28: Rancho La Cuchilla No. 32 | D28: Hernández
A29: 24 | B29: CL_33_ | C29: Rancho La Cuchilla No. 33 | D29: Tanús
A30: 25 | B30: CL_35_ | C30: Rancho La Cuchilla No. 35 | D30: Mendoza
A31: 26 | B31: CL_36_ | C31: Rancho La Cuchilla No. 36 | D31: Castillo
A32: 27 | B32: CL_38_ | C32: Rancho La Cuchilla No. 38 | D32: Cerecedo
A33: 28 | B33: CL_39_ | C33: Rancho La Cuchilla No. 39 | D33: Arenas
A34: 29 | B34: CL_40_ | C34: Rancho La Cuchilla No. 40 | D34: López Pico
A35: 30 | B35: CL_41_ | C35: Rancho La Cuchilla No. 41 | D35: Arriaga Lemus
A36: 31 | B36: CL_42_ | C36: Rancho La Cuchilla No. 42 | D36: Mac Kinney
... A38: 33 | B38: CL_43_B | C38: Rancho La Cuchilla No. 43, B | D38: Luna Albertano
A39: 34 | B39: CL_44_ | C39: Rancho La Cuchilla No. 44 | D39: García Osorio | E39: Agregado el 16/abr/18 GMS antes Garduño
A40: 35 | B40: CL_45_ | C40: Rancho La Cuchilla No. 45 | D40: Estévez Hernández
A41: 36 | B41: CL_46_ | C41: Rancho La Cuchilla No. 46 | D41: Cruz López
A42: 37 | B42: CL_47_ | C42: Rancho La Cuchilla No. 47 | D42: López
A43: 38 | B43: CL_49_ | C43: Rancho La Cuchilla No. 49 | D43: Orozco Castelazo
A44: 39 | B44: CL_52_ | C44: Rancho La Cuchilla No. 52 | D44: Velázquez
...

Sheet criterios
G2: INGRESOS | P2: EGRESOS
G3: C_ING | H3: C_ING | I3: C_ING | J3: C_ING | K3: C_ING | L3: C_ING | M3: C_ING | N3: C_ING | P3: clave | Q3: clave | R3: clave | S3: clave | T3: clave | U3: clave | V3: clave | W3: clave | X3: clave | Y3: clave | Z3: clave | AA3: clave | AB3: clave | AC3: clave | AD3: clave | AE3: clave | AF3: clave | AG3: clave | AH3: clave | AI3: clave | AJ3: clave | AK3: clave | AL3: clave | AM3: clave | AN3: clave | AO3: clave | AP3: clave | AQ3: clave | AR3: clave | AS3: clave | AT3: clave
G4: 1 | H4: 2 | I4: 3 | J4: 4 | K4: 5 | L4: 6 | M4: 7 | P4: G_ADQ | Q4: G_AGUA | R4: G_ALMVG | S4: G_ASLE | T4: G_CBR | U4: G_DIF | V4: G_HCTB | W4: G_HJRD | X4: G_INFRA | Y4: G_IVA | Z4: G_JDN | AA4: G_MDC | AB4: G_MTCBQ | AC4: G_MTCP | AD4: G_MTCST | AE4: G_MTCYP | AF4: G_MTILM | AG4: G_MTLPZ | AH4: G_MTPTA | AI4: G_NMNVG | AJ4: G_ORG | AK4: G_P_FIN | AL4: G_P_IVA | AM4: G_PAPE | AN4: G_SÑ | AO4: G_TLF | AP4: G_TRSP | AQ4: G_UNF | AR4: G_USB | AS4: G_VRS
B5: INGRESOS
B6: 1 | D6: ING_CUOTAS | E6: Cuotas de vigilancia
B7: 2 | D7: ING_EXTRA | E7: Cuotas extraordinarias
B8: 3 | D8: ING_LLAVES | E8: Venta de llaves
B9: 4 | D9: ING_TELE | E9: Venta de tarjetas electrónicas
B10: 5 | D10: ING_TAR | E10: Venta de tarjetones
B11: 6 | E11: Aportación Colegio Carmel
B12: 7 | D12: ING_OTROS | E12: Otros ingresos
B14: EGRESOS
C15: COSTO DE VIGILANCIA
D16: G_NMNVG | E16: Sueldos y bono de puntualidad
D17: G_AGUA | E17: Agua
D18: G_ALMVG | E18: Alimentos
D19: G_MTLPZ | E19: Artículos de limpieza
D20: G_MDC | E20: Atención médica
D21: G_TRSP | E21: Mantenimiento de bicicletas
D22: G_UNF | E22: Uniformes
C23: INFRAESTRUCTURA Y SUMINISTROS
D24: G_INFRA | E24: Cámaras de vigilancia
D25: G_USB | E25: Dispositivos, discos y USB
D26: G_ADQ | E26: Llaves electrónicas y de acceso peatonal
D27: G_SÑ | E27: Señalización en calles
C28: MANTENIMIENTO
D29: G_MTCBQ | E29: A calles y banquetas
D30: G_MTCYP | E30: A cámaras de vigilancia y plumas de acceso
D31: G_MTCST | E31: A casetas
D32: G_MTPTA | E32: A las puertas de acceso peatonal
D33: G_MTILM | E33: A luminarias
D34: G_JDN | E34: Al jardín, Kiosco, juegos y explanada
D35: G_VRS | E35: Varios
C36: GASTOS ADMINISTRATIVOS
D37: G_CBR | E37: Cobranza
D38: G_ORG | E38: Gastos de organización
D39: G_P_FIN | E39: Gastos y productos financieros
D40: G_HCTB | E40: Honorarios contables y captura
D41: G_HJRD | E41: Honorarios jurídicos
D42: G_ASLE | E42: Asesoría Legal
...

Sheet Comprobación
C2: 2016
B3: mes | C3: financiero | D3: distribución
D4: 2015 | E4: 2016 | F4: 2017
B5: enero | C5: =SUMIF(Recibos!G25:G274,1,Recibos!H25:H274) -> 213050 | E5: =-Recibos!H274 -> -38000
B6: febrero | C6: =SUMIF(Recibos!G276:G432,1,Recibos!H276:H432) -> 94750 | E6: =-Recibos!H432 -> -5600
B7: marzo | C7: =SUMIF(Recibos!G434:G589,1,Recibos!H434:H589) -> 82625 | E7: =-Recibos!H589 -> -1000
B8: abril | C8: =SUMIF(Recibos!G591:G785,1,Recibos!H591:H785) -> 102075 | E8: =-Recibos!H785 -> -1200
B9: mayo | C9: =SUMIF(Recibos!G787:G1018,1,Recibos!H787:H1018) -> 108875 | E9: =-Recibos!H1018 -> 0
B10: junio | C10: =SUMIF(Recibos!G1019:G1423,1,Recibos!H1019:H1423) -> 117275 | E10: =-Recibos!H1423 -> -2550
B11: julio | C11: =SUMIF(Recibos!G1425:G1805,1,Recibos!H1425:H1805) -> 104575 | D11: =Recibos!H5 -> 900
B12: agosto | C12: =SUMIF(Recibos!G1807:G2081,1,Recibos!H1807:H2081) -> 106275 | D12: =Recibos!H7 -> 150
B13: septiembre | C13: =SUMIF(Recibos!G2083:G2341,1,Recibos!H2083:H2341) -> 95625
B14: octubre | C14: =SUMIF(Recibos!G2342:G2560,1,Recibos!H2342:H2560) -> 88925
B15: noviembre | D15: =Recibos!H10 -> 800
B16: diciembre | D16: =Recibos!H23 -> 23950
B17: suma | C17: =SUM(C5:C16) -> 1114050 | E17: =Recibos!W2 -> 1087600 | F17: =SUM(C5:F16) -> 1091500
F18: =IF(E17=F17,"ok",E17-F17) -> -3900

Sheet Cobranza
B1: Haciendas de Coyoacán
B2: Cuotas de vigilancia y mantenimiento
B3: Período: julio de 2012 - junio de 2017
K4: =SUM(K6:K469) -> 102125 | X4: =SUM(X6:X469) -> 1071865 | AK4: =SUM(AK6:AK469) -> 1244640 | AX4: =SUM(AX6:AX469) -> 1281550 | BK4: =SUM(BK6:BK469) -> 1349200 | BX4: =SUM(BX6:BX469) -> 1337550
B5: CASA | C5: Domicilio | D5: Familia | E5: JUL 2012 | F5: AGO 2012 | G5: SEP 2012 | H5: OCT 2012 | I5: NOV 2012 | J5: DIC 2012 | K5: SUMA 2012 | L5: ENE 2013 | M5: FEB 2013 | N5: MAR 2013 | O5: ABR 2013 | P5: MAY 2013 | Q5: JUN 2013 | R5: JUL 2013 | S5: AGO 2013 | T5: SEP 2013 | U5: OCT 2013 | V5: NOV 2013 | W5: DIC 2013 | X5: SUMA 2013 | Y5: ENE 2014 | Z5: FEB 2014 | AA5: MAR 2014 | AB5: ABR 2014 | AC5: MAY 2014 | AD5: JUN 2014 | AE5: JUL 2014 | AF5: AGO 2014 | AG5: SEP 2014 | AH5: OCT 2014 | AI5: NOV 2014 | AJ5: DIC 2014 | AK5: SUMA 2014 | AL5: ENE 2015 | AM5: FEB 2015 | AN5: MAR 2015 | AO5: ABR 2015 | AP5: MAY 2015 | AQ5: JUN 2015 | AR5: JUL 2015 | AS5: AGO 2015 | AT5: SEP 2015 | AU5: OCT 2015 | AV5: NOV 2015 | AW5: DIC 2015 | AX5: SUMA 2015 | AY5: ENE 2016 | AZ5: FEB 2016 | BA5: MAR 2016 | BB5: ABR 2016 | BC5: MAY 2016 | BD5: JUN 2016 | BE5: JUL 2016 | BF5: AGO 2016 | BG5: SEP 2016 | BH5: OCT 2016 | BI5: NOV 2016 | BJ5: DIC 2016 | BK5: SUMA 2016 | BL5: ENE 2017 | BM5: FEB 2017 | BN5: MAR 2017 | BO5: ABR 2017 | BP5: MAY 2017 | BQ5: JUN 2017 | BR5: JUL 2017 | BS5: AGO 2017 | BT5: SEP 2017 | BU5: OCT 2017 | BV5: NOV 2017 | BW5: DIC 2017 | BX5: SUMA 2017 | BY5: ENE 2018 | BZ5: FEB 2018 | CA5: MAR 2018 | CB5: ABR 2018 | CC5: MAY 2018 | CD5: JUN 2018 | CE5: JUL 2018 | CF5: AGO 2018 | CG5: SEP 2018 | CH5: OCT 2018 | CI5: NOV 2018 | CJ5: DIC 2018 | CK5: SUMA 2018
B6: CL_7_101 | C6: Rancho La Cuchilla No. 7, 101 | D6: Olivares | E6: 0 | F6: 0 | G6: 0 | H6: 0 | I6: 0 | J6: 100 | K6: =SUM(E6:J6) -> 100 | L6: 100 | M6: 100 | N6: 100 | O6: 100 | P6: 100 | Q6: 100 | R6: 100 | S6: 100 | T6: 100 | U6: 0 | V6: 0 | W6: 0 | X6: =SUM(L6:W6) -> 900 | Y6: 100 | Z6: 100 | AA6: 100 | AB6: 100 | AC6: 100 | AD6: 100 | AE6: 100 | AF6: 100 | AG6: 100 | AH6: 100 | AI6: 100 | AJ6: 100 | AK6: =SUM(Y6:AJ6) -> 1200 | AL6: 100 | AM6: 100 | AN6: 0 | AO6: 0 | AP6: 0 | AQ6: 0 | AR6: 0 | AS6: 0 | AT6: 0 | AU6: 0 | AV6: 0 | AW6: 0 | AX6: =SUM(AL6:AW6) -> 200 | AY6: =SUMIF(Recibos!$D$4:$D$7493,Cobranza!$B6,Recibos!K$4:K$7493) -> 0 | AZ6: =SUMIF(Recibos!$D$4:$D$7493,Cobranza!$B6,Recibos!L$4:L$7493) -> 0 | BA6: =SUMIF(Recibos!$D$4:$D$7493,Cobranza!$B6,Recibos!M$4:M$7493) -> 0 | BB6: =SUMIF(Recibos!$D$4:$D$7493,Cobranza!$B6,Recibos!N$4:N$7493) -> 0 | BC6: =SUMIF(Recibos!$D$4:$D$7493,Cobranza!$B6,Recibos!O$4:O$7493) -> 0 | BD6: =SUMIF(Recibos!$D$4:$D$7493,Cobranza!$B6,Recibos!P$4:P$7493) -> 0 | BE6: =SUMIF(Recibos!$D$4:$D$7493,Cobranza!$B6,Recibos!Q$4:Q$7493) -> 0 | BF6: =SUMIF(Recibos!$D$4:$D$7493,Cobranza!$B6,Recibos!R$4:R$7493) -> 100 | ... BJ6: =SUMIF(Recibos!$D$4:$D$7493,Cobranza!$B6,Recibos!V$4:V$7493) -> 100 | BK6: =SUM(AY6:BJ6) -> 500 | BL6: =SUMIF(Recibos!$D$4:$D$7493,Cobranza!$B6,Recibos!X$4:X$7493) -> 100 | BM6: =SUMIF(Recibos!$D$4:$D$7493,Cobranza!$B6,Recibos!Y$4:Y$7493) -> 100 | BN6: =SUMIF(Recibos!$D$4:$D$7493,Cobranza!$B6,Recibos!Z$4:Z$7493) -> 0 | BO6: =SUMIF(Recibos!$D$4:$D$7493,Cobranza!$B6,Recibos!AA$4:AA$7493) -> 0 | BP6: =SUMIF(Recibos!$D$4:$D$7493,Cobranza!$B6,Recibos!AB$4:AB$7493) -> 0 | BQ6: =SUMIF(Recibos!$D$4:$D$7493,Cobranza!$B6,Recibos!AC$4:AC$7493) -> 0 | BR6: =SUMIF(Recibos!$D$4:$D$7493,Cobranza!$B6,Recibos!AD$4:AD$7493) -> 0 | BS6: =SUMIF(Recibos!$D$4:$D$7493,Cobranza!$B6,Recibos!AE$4:AE$7493) -> 0 | ... BW6: =SUMIF(Recibos!$D$4:$D$7493,Cobranza!$B6,Recibos!AI$4:AI$7493) -> 0 | BX6: =SUM(BL6:BW6) -> 200 | BY6: =SUMIF(Recibos!$D$4:$D$7493,Cobranza!$B6,Recibos!AK$4:AK$7493) -> 0 | BZ6: =SUMIF(Recibos!$D$4:$D$7493,Cobranza!$B6,Recibos!AL$4:AL$7493) -> 0 | CA6: =SUMIF(Recibos!$D$4:$D$7493,Cobranza!$B6,Recibos!AM$4:AM$7493) -> 0 | CB6: =SUMIF(Recibos!$D$4:$D$7493,Cobranza!$B6,Recibos!AN$4:AN$7493) -> 0 | CC6: =SUMIF(Recibos!$D$4:$D$7493,Cobranza!$B6,Recibos!AO$4:AO$7493) -> 0 | CD6: =SUMIF(Recibos!$D$4:$D$7493,Cobranza!$B6,Recibos!AP$4:AP$7493) -> 0 | CE6: =SUMIF(Recibos!$D$4:$D$7493,Cobranza!$B6,Recibos!AQ$4:AQ$7493) -> 0 | CF6: =SUMIF(Recibos!$D$4:$D$7493,Cobranza!$B6,Recibos!AR$4:AR$7493) -> 0 | ... CJ6: =SUMIF(Recibos!$D$4:$D$7493,Cobranza!$B6,Recibos!AV$4:AV$7493) -> 0 | CK6: =SUM(BY6:CJ6) -> 0
B7: CL_7_102 | C7: Rancho La Cuchilla No. 7, 102 | D7: García Moreno | E7: 0 | F7: 0 | G7: 0 | H7: 100 | I7: 100 | J7: 100 | K7: =SUM(E7:J7) -> 300 | L7: 100 | M7: 100 | N7: 100 | O7: 100 | P7: 100 | Q7: 100 | R7: 100 | S7: 100 | T7: 100 | U7: 100 | V7: 100 | W7: 100 | X7: =SUM(L7:W7) -> 1200 | Y7: 100 | Z7: 100 | AA7: 100 | AB7: 100 | AC7: 100 | AD7: 100 | AE7: 100 | AF7: 100 | AG7: 100 | AH7: 100 | AI7: 100 | AJ7: 100 | AK7: =SUM(Y7:AJ7) -> 1200 | AL7: 100 | AM7: 100 | AN7: 100 | AO7: 100 | AP7: 100 | AQ7: 100 | AR7: 100 | AS7: 100 | AT7: 0 | AU7: 0 | AV7: 0 | AW7: 0 | AX7: =SUM(AL7:AW7) -> 800 | AY7: =SUMIF(Recibos!$D$4:$D$7493,Cobranza!$B7,Recibos!K$4:K$7493) -> 100 | AZ7: =SUMIF(Recibos!$D$4:$D$7493,Cobranza!$B7,Recibos!L$4:L$7493) -> 100 | BA7: =SUMIF(Recibos!$D$4:$D$7493,Cobranza!$B7,Recibos!M$4:M$7493) -> 100 | BB7: =SUMIF(Recibos!$D$4:$D$7493,Cobranza!$B7,Recibos!N$4:N$7493) -> 100 | BC7: =SUMIF(Recibos!$D$4:$D$7493,Cobranza!$B7,Recibos!O$4:O$7493) -> 100 | BD7: =SUMIF(Recibos!$D$4:$D$7493,Cobranza!$B7,Recibos!P$4:P$7493) -> 100 | BE7: =SUMIF(Recibos!$D$4:$D$7493,Cobranza!$B7,Recibos!Q$4:Q$7493) -> 100 | BF7: =SUMIF(Recibos!$D$4:$D$7493,Cobranza!$B7,Recibos!R$4:R$7493) -> 100 | ... BJ7: =SUMIF(Recibos!$D$4:$D$7493,Cobranza!$B7,Recibos!V$4:V$7493) -> 100 | BK7: =SUM(AY7:BJ7) -> 1200 | BL7: =SUMIF(Recibos!$D$4:$D$7493,Cobranza!$B7,Recibos!X$4:X$7493) -> 100 | BM7: =SUMIF(Recibos!$D$4:$D$7493,Cobranza!$B7,Recibos!Y$4:Y$7493) -> 100 | BN7: =SUMIF(Recibos!$D$4:$D$7493,Cobranza!$B7,Recibos!Z$4:Z$7493) -> 100 | BO7: =SUMIF(Recibos!$D$4:$D$7493,Cobranza!$B7,Recibos!AA$4:AA$7493) -> 100 | BP7: =SUMIF(Recibos!$D$4:$D$7493,Cobranza!$B7,Recibos!AB$4:AB$7493) -> 100 | BQ7: =SUMIF(Recibos!$D$4:$D$7493,Cobranza!$B7,Recibos!AC$4:AC$7493) -> 100 | BR7: =SUMIF(Recibos!$D$4:$D$7493,Cobranza!$B7,Recibos!AD$4:AD$7493) -> 100 | BS7: =SUMIF(Recibos!$D$4:$D$7493,Cobranza!$B7,Recibos!AE$4:AE$7493) -> 100 | ... BW7: =SUMIF(Recibos!$D$4:$D$7493,Cobranza!$B7,Recibos!AI$4:AI$7493) -> 100 | BX7: =SUM(BL7:BW7) -> 1200 | BY7: =SUMIF(Recibos!$D$4:$D$7493,Cobranza!$B7,Recibos!AK$4:AK$7493) -> 100 | BZ7: =SUMIF(Recibos!$D$4:$D$7493,Cobranza!$B7,Recibos!AL$4:AL$7493) -> 100 | CA7: =SUMIF(Recibos!$D$4:$D$7493,Cobranza!$B7,Recibos!AM$4:AM$7493) -> 100 | CB7: =SUMIF(Recibos!$D$4:$D$7493,Cobranza!$B7,Recibos!AN$4:AN$7493) -> 100 | CC7: =SUMIF(Recibos!$D$4:$D$7493,Cobranza!$B7,Recibos!AO$4:AO$7493) -> 100 | CD7: =SUMIF(Recibos!$D$4:$D$7493,Cobranza!$B7,Recibos!AP$4:AP$7493) -> 100 | CE7: =SUMIF(Recibos!$D$4:$D$7493,Cobranza!$B7,Recibos!AQ$4:AQ$7493) -> 0 | CF7: =SUMIF(Recibos!$D$4:$D$7493,Cobranza!$B7,Recibos!AR$4:AR$7493) -> 0 | ... CJ7: =SUMIF(Recibos!$D$4:$D$7493,Cobranza!$B7,Recibos!AV$4:AV$7493) -> 0 | CK7: =SUM(BY7:CJ7) -> 600
B8: CL_7_201 | C8: Rancho La Cuchilla No. 7, 201 | D8: Solís Susana | E8: 0 | F8: 0 | G8: 0 | H8: 0 | I8: 0 | J8: 0 | K8: =SUM(E8:J8) -> 0 | L8: 0 | M8: 0 | N8: 0 | O8: 0 | P8: 0 | Q8: 0 | R8: 0 | S8: 0 | T8: 0 | U8: 0 | V8: 0 | W8: 0 | X8: =SUM(L8:W8) -> 0 | Y8: 0 | Z8: 0 | AA8: 0 | AB8: 0 | AC8: 0 | AD8: 0 | AE8: 0 | AF8: 0 | AG8: 0 | AH8: 0 | AI8: 0 | AJ8: 0 | AK8: =SUM(Y8:AJ8) -> 0 | AL8: 0 | AM8: 0 | AN8: 0 | AO8: 0 | AP8: 0 | AQ8: 0 | AR8: 0 | AS8: 0 | AT8: 0 | AU8: 0 | AV8: 0 | AW8: 0 | AX8: =SUM(AL8:AW8) -> 0 | AY8: =SUMIF(Recibos!$D$4:$D$7493,Cobranza!$B8,Recibos!K$4:K$7493) -> 0 | AZ8: =SUMIF(Recibos!$D$4:$D$7493,Cobranza!$B8,Recibos!L$4:L$7493) -> 0 | BA8: =SUMIF(Recibos!$D$4:$D$7493,Cobranza!$B8,Recibos!M$4:M$7493) -> 0 | BB8: =SUMIF(Recibos!$D$4:$D$7493,Cobranza!$B8,Recibos!N$4:N$7493) -> 0 | BC8: =SUMIF(Recibos!$D$4:$D$7493,Cobranza!$B8,Recibos!O$4:O$7493) -> 0 | BD8: =SUMIF(Recibos!$D$4:$D$7493,Cobranza!$B8,Recibos!P$4:P$7493) -> 0 | BE8: =SUMIF(Recibos!$D$4:$D$7493,Cobranza!$B8,Recibos!Q$4:Q$7493) -> 0 | BF8: =SUMIF(Recibos!$D$4:$D$7493,Cobranza!$B8,Recibos!R$4:R$7493) -> 100 | ... BJ8: =SUMIF(Recibos!$D$4:$D$7493,Cobranza!$B8,Recibos!V$4:V$7493) -> 0 | BK8: =SUM(AY8:BJ8) -> 100 | BL8: =SUMIF(Recibos!$D$4:$D$7493,Cobranza!$B8,Recibos!X$4:X$7493) -> 0 | BM8: =SUMIF(Recibos!$D$4:$D$7493,Cobranza!$B8,Recibos!Y$4:Y$7493) -> 0 | BN8: =SUMIF(Recibos!$D$4:$D$7493,Cobranza!$B8,Recibos!Z$4:Z$7493) -> 0 | BO8: =SUMIF(Recibos!$D$4:$D$7493,Cobranza!$B8,Recibos!AA$4:AA$7493) -> 0 | BP8: =SUMIF(Recibos!$D$4:$D$7493,Cobranza!$B8,Recibos!AB$4:AB$7493) -> 0 | BQ8: =SUMIF(Recibos!$D$4:$D$7493,Cobranza!$B8,Recibos!AC$4:AC$7493) -> 0 | BR8: =SUMIF(Recibos!$D$4:$D$7493,Cobranza!$B8,Recibos!AD$4:AD$7493) -> 0 | BS8: =SUMIF(Recibos!$D$4:$D$7493,Cobranza!$B8,Recibos!AE$4:AE$7493) -> 0 | ... BW8: =SUMIF(Recibos!$D$4:$D$7493,Cobranza!$B8,Recibos!AI$4:AI$7493) -> 0 | BX8: =SUM(BL8:BW8) -> 0 | BY8: =SUMIF(Recibos!$D$4:$D$7493,Cobranza!$B8,Recibos!AK$4:AK$7493) -> 0 | BZ8: =SUMIF(Recibos!$D$4:$D$7493,Cobranza!$B8,Recibos!AL$4:AL$7493) -> 0 | CA8: =SUMIF(Recibos!$D$4:$D$7493,Cobranza!$B8,Recibos!AM$4:AM$7493) -> 0 | CB8: =SUMIF(Recibos!$D$4:$D$7493,Cobranza!$B8,Recibos!AN$4:AN$7493) -> 0 | CC8: =SUMIF(Recibos!$D$4:$D$7493,Cobranza!$B8,Recibos!AO$4:AO$7493) -> 0 | CD8: =SUMIF(Recibos!$D$4:$D$7493,Cobranza!$B8,Recibos!AP$4:AP$7493) -> 0 | CE8: =SUMIF(Recibos!$D$4:$D$7493,Cobranza!$B8,Recibos!AQ$4:AQ$7493) -> 0 | CF8: =SUMIF(Recibos!$D$4:$D$7493,Cobranza!$B8,Recibos!AR$4:AR$7493) -> 0 | ... CJ8: =SUMIF(Recibos!$D$4:$D$7493,Cobranza!$B8,Recibos!AV$4:AV$7493) -> 0 | CK8: =SUM(BY8:CJ8) -> 0
B9: CL_7_202 | C9: Rancho La Cuchilla No. 7, 202 | D9: Carbajal Zayas | E9: 0 | F9: 0 | G9: 100 | H9: 100 | I9: 100 | J9: 100 | K9: =SUM(E9:J9) -> 400 | L9: 100 | M9: 100 | N9: 100 | O9: 100 | P9: 100 | Q9: 100 | R9: 100 | S9: 100 | T9: 100 | U9: 100 | V9: 100 | W9: 100 | X9: =SUM(L9:W9) -> 1200 | Y9: 100 | Z9: 100 | AA9: 0 | AB9: 0 | AC9: 100 | AD9: 100 | AE9: 100 | AF9: 100 | AG9: 100 | AH9: 100 | AI9: 100 | AJ9: 100 | AK9: =SUM(Y9:AJ9) -> 1000 | AL9: 100 | AM9: 100 | AN9: 100 | AO9: 100 | AP9: 100 | AQ9: 100 | AR9: 100 | AS9: 100 | AT9: 100 | AU9: 0 | AV9: 0 | AW9: 0 | AX9: =SUM(AL9:AW9) -> 900 | AY9: =SUMIF(Recibos!$D$4:$D$7493,Cobranza!$B9,Recibos!K$4:K$7493) -> 100 | AZ9: =SUMIF(Recibos!$D$4:$D$7493,Cobranza!$B9,Recibos!L$4:L$7493) -> 100 | BA9: =SUMIF(Recibos!$D$4:$D$7493,Cobranza!$B9,Recibos!M$4:M$7493) -> 100 | BB9: =SUMIF(Recibos!$D$4:$D$7493,Cobranza!$B9,Recibos!N$4:N$7493) -> 100 | BC9: =SUMIF(Recibos!$D$4:$D$7493,Cobranza!$B9,Recibos!O$4:O$7493) -> 100 | BD9: =SUMIF(Recibos!$D$4:$D$7493,Cobranza!$B9,Recibos!P$4:P$7493) -> 100 | BE9: =SUMIF(Recibos!$D$4:$D$7493,Cobranza!$B9,Recibos!Q$4:Q$7493) -> 100 | BF9: =SUMIF(Recibos!$D$4:$D$7493,Cobranza!$B9,Recibos!R$4:R$7493) -> 100 | ... BJ9: =SUMIF(Recibos!$D$4:$D$7493,Cobranza!$B9,Recibos!V$4:V$7493) -> 0 | BK9: =SUM(AY9:BJ9) -> 1100 | BL9: =SUMIF(Recibos!$D$4:$D$7493,Cobranza!$B9,Recibos!X$4:X$7493) -> 0 | BM9: =SUMIF(Recibos!$D$4:$D$7493,Cobranza!$B9,Recibos!Y$4:Y$7493) -> 0 | BN9: =SUMIF(Recibos!$D$4:$D$7493,Cobranza!$B9,Recibos!Z$4:Z$7493) -> 0 | BO9: =SUMIF(Recibos!$D$4:$D$7493,Cobranza!$B9,Recibos!AA$4:AA$7493) -> 0 | BP9: =SUMIF(Recibos!$D$4:$D$7493,Cobranza!$B9,Recibos!AB$4:AB$7493) -> 0 | BQ9: =SUMIF(Recibos!$D$4:$D$7493,Cobranza!$B9,Recibos!AC$4:AC$7493) -> 0 | BR9: =SUMIF(Recibos!$D$4:$D$7493,Cobranza!$B9,Recibos!AD$4:AD$7493) -> 0 | BS9: =SUMIF(Recibos!$D$4:$D$7493,Cobranza!$B9,Recibos!AE$4:AE$7493) -> 0 | ... BW9: =SUMIF(Recibos!$D$4:$D$7493,Cobranza!$B9,Recibos!AI$4:AI$7493) -> 0 | BX9: =SUM(BL9:BW9) -> 0 | BY9: =SUMIF(Recibos!$D$4:$D$7493,Cobranza!$B9,Recibos!AK$4:AK$7493) -> 0 | BZ9: =SUMIF(Recibos!$D$4:$D$7493,Cobranza!$B9,Recibos!AL$4:AL$7493) -> 0 | CA9: =SUMIF(Recibos!$D$4:$D$7493,Cobranza!$B9,Recibos!AM$4:AM$7493) -> 0 | CB9: =SUMIF(Recibos!$D$4:$D$7493,Cobranza!$B9,Recibos!AN$4:AN$7493) -> 0 | CC9: =SUMIF(Recibos!$D$4:$D$7493,Cobranza!$B9,Recibos!AO$4:AO$7493) -> 0 | CD9: =SUMIF(Recibos!$D$4:$D$7493,Cobranza!$B9,Recibos!AP$4:AP$7493) -> 0 | CE9: =SUMIF(Recibos!$D$4:$D$7493,Cobranza!$B9,Recibos!AQ$4:AQ$7493) -> 0 | CF9: =SUMIF(Recibos!$D$4:$D$7493,Cobranza!$B9,Recibos!AR$4:AR$7493) -> 0 | ... CJ9: =SUMIF(Recibos!$D$4:$D$7493,Cobranza!$B9,Recibos!AV$4:AV$7493) -> 0 | CK9: =SUM(BY9:CJ9) -> 0
B10: CL_9_ | C10: Rancho La Cuchilla No. 9 | D10: Martín del Campo | E10: 0 | F10: 0 | G10: 0 | H10: 0 | I10: 300 | J10: 300 | K10: =SUM(E10:J10) -> 600 | L10: 300 | M10: 0 | N10: 0 | O10: 0 | P10: 0 | Q10: 0 | R10: 0 | S10: 0 | T10: 0 | U10: 0 | V10: 0 | W10: 0 | X10: =SUM(L10:W10) -> 300 | Y10: 0 | Z10: 0 | AA10: 0 | AB10: 0 | AC10: 0 | AD10: 0 | AE10: 0 | AF10: 0 | AG10: 0 | AH10: 0 | AI10: 0 | AJ10: 0 | AK10: =SUM(Y10:AJ10) -> 0 | AL10: 0 | AM10: 0 | AN10: 0 | AO10: 0 | AP10: 0 | AQ10: 0 | AR10: 0 | AS10: 0 | AT10: 0 | AU10: 0 | AV10: 0 | AW10: 0 | AX10: =SUM(AL10:AW10) -> 0 | AY10: =SUMIF(Recibos!$D$4:$D$7493,Cobranza!$B10,Recibos!K$4:K$7493) -> 0 | AZ10: =SUMIF(Recibos!$D$4:$D$7493,Cobranza!$B10,Recibos!L$4:L$7493) -> 0 | BA10: =SUMIF(Recibos!$D$4:$D$7493,Cobranza!$B10,Recibos!M$4:M$7493) -> 0 | BB10: =SUMIF(Recibos!$D$4:$D$7493,Cobranza!$B10,Recibos!N$4:N$7493) -> 0 | BC10: =SUMIF(Recibos!$D$4:$D$7493,Cobranza!$B10,Recibos!O$4:O$7493) -> 0 | BD10: =SUMIF(Recibos!$D$4:$D$7493,Cobranza!$B10,Recibos!P$4:P$7493) -> 0 | BE10: =SUMIF(Recibos!$D$4:$D$7493,Cobranza!$B10,Recibos!Q$4:Q$7493) -> 0 | BF10: =SUMIF(Recibos!$D$4:$D$7493,Cobranza!$B10,Recibos!R$4:R$7493) -> 0 | ... BJ10: =SUMIF(Recibos!$D$4:$D$7493,Cobranza!$B10,Recibos!V$4:V$7493) -> 0 | BK10: =SUM(AY10:BJ10) -> 0 | BL10: =SUMIF(Recibos!$D$4:$D$7493,Cobranza!$B10,Recibos!X$4:X$7493) -> 0 | BM10: =SUMIF(Recibos!$D$4:$D$7493,Cobranza!$B10,Recibos!Y$4:Y$7493) -> 0 | BN10: =SUMIF(Recibos!$D$4:$D$7493,Cobranza!$B10,Recibos!Z$4:Z$7493) -> 0 | BO10: =SUMIF(Recibos!$D$4:$D$7493,Cobranza!$B10,Recibos!AA$4:AA$7493) -> 0 | BP10: =SUMIF(Recibos!$D$4:$D$7493,Cobranza!$B10,Recibos!AB$4:AB$7493) -> 0 | BQ10: =SUMIF(Recibos!$D$4:$D$7493,Cobranza!$B10,Recibos!AC$4:AC$7493) -> 0 | BR10: =SUMIF(Recibos!$D$4:$D$7493,Cobranza!$B10,Recibos!AD$4:AD$7493) -> 0 | BS10: =SUMIF(Recibos!$D$4:$D$7493,Cobranza!$B10,Recibos!AE$4:AE$7493) -> 0 | ... BW10: =SUMIF(Recibos!$D$4:$D$7493,Cobranza!$B10,Recibos!AI$4:AI$7493) -> 0 | BX10: =SUM(BL10:BW10) -> 0 | BY10: =SUMIF(Recibos!$D$4:$D$7493,Cobranza!$B10,Recibos!AK$4:AK$7493) -> 0 | BZ10: =SUMIF(Recibos!$D$4:$D$7493,Cobranza!$B10,Recibos!AL$4:AL$7493) -> 0 | CA10: =SUMIF(Recibos!$D$4:$D$7493,Cobranza!$B10,Recibos!AM$4:AM$7493) -> 0 | CB10: =SUMIF(Recibos!$D$4:$D$7493,Cobranza!$B10,Recibos!AN$4:AN$7493) -> 0 | CC10: =SUMIF(Recibos!$D$4:$D$7493,Cobranza!$B10,Recibos!AO$4:AO$7493) -> 0 | CD10: =SUMIF(Recibos!$D$4:$D$7493,Cobranza!$B10,Recibos!AP$4:AP$7493) -> 0 | CE10: =SUMIF(Recibos!$D$4:$D$7493,Cobranza!$B10,Recibos!AQ$4:AQ$7493) -> 0 | CF10: =SUMIF(Recibos!$D$4:$D$7493,Cobranza!$B10,Recibos!AR$4:AR$7493) -> 0 | ... CJ10: =SUMIF(Recibos!$D$4:$D$7493,Cobranza!$B10,Recibos!AV$4:AV$7493) -> 0 | CK10: =SUM(BY10:CJ10) -> 0
B11: CL_11_ | C11: Rancho La Cuchilla No. 11 | D11: Santiago | E11: 0 | F11: 0 | G11: 0 | H11: 0 | I11: 0 | J11: 0 | K11: =SUM(E11:J11) -> 0 | L11: 100 | M11: 100 | N11: 100 | O11: 100 | P11: 100 | Q11: 100 | R11: 100 | S11: 100 | T11: 100 | U11: 100 | V11: 0 | W11: 0 | X11: =SUM(L11:W11) -> 1000 | Y11: 0 | Z11: 100 | AA11: 100 | AB11: 100 | AC11: 100 | AD11: 100 | AE11: 100 | AF11: 100 | AG11: 100 | AH11: 100 | AI11: 100 | AJ11: 100 | AK11: =SUM(Y11:AJ11) -> 1100 | AL11: 100 | AM11: 100 | AN11: 100 | AO11: 0 | AP11: 0 | AQ11: 0 | AR11: 0 | AS11: 0 | AT11: 0 | AU11: 0 | AV11: 0 | AW11: 0 | AX11: =SUM(AL11:AW11) -> 300 | AY11: =SUMIF(Recibos!$D$4:$D$7493,Cobranza!$B11,Recibos!K$4:K$7493) -> 0 | AZ11: =SUMIF(Recibos!$D$4:$D$7493,Cobranza!$B11,Recibos!L$4:L$7493) -> 0 | BA11: =SUMIF(Recibos!$D$4:$D$7493,Cobranza!$B11,Recibos!M$4:M$7493) -> 0 | BB11: =SUMIF(Recibos!$D$4:$D$7493,Cobranza!$B11,Recibos!N$4:N$7493) -> 0 | BC11: =SUMIF(Recibos!$D$4:$D$7493,Cobranza!$B11,Recibos!O$4:O$7493) -> 0 | BD11: =SUMIF(Recibos!$D$4:$D$7493,Cobranza!$B11,Recibos!P$4:P$7493) -> 0 | BE11: =SUMIF(Recibos!$D$4:$D$7493,Cobranza!$B11,Recibos!Q$4:Q$7493) -> 0 | BF11: =SUMIF(Recibos!$D$4:$D$7493,Cobranza!$B11,Recibos!R$4:R$7493) -> 0 | ... BJ11: =SUMIF(Recibos!$D$4:$D$7493,Cobranza!$B11,Recibos!V$4:V$7493) -> 0 | BK11: =SUM(AY11:BJ11) -> 0 | BL11: =SUMIF(Recibos!$D$4:$D$7493,Cobranza!$B11,Recibos!X$4:X$7493) -> 0 | BM11: =SUMIF(Recibos!$D$4:$D$7493,Cobranza!$B11,Recibos!Y$4:Y$7493) -> 0 | BN11: =SUMIF(Recibos!$D$4:$D$7493,Cobranza!$B11,Recibos!Z$4:Z$7493) -> 0 | BO11: =SUMIF(Recibos!$D$4:$D$7493,Cobranza!$B11,Recibos!AA$4:AA$7493) -> 0 | BP11: =SUMIF(Recibos!$D$4:$D$7493,Cobranza!$B11,Recibos!AB$4:AB$7493) -> 0 | BQ11: =SUMIF(Recibos!$D$4:$D$7493,Cobranza!$B11,Recibos!AC$4:AC$7493) -> 0 | BR11: =SUMIF(Recibos!$D$4:$D$7493,Cobranza!$B11,Recibos!AD$4:AD$7493) -> 0 | BS11: =SUMIF(Recibos!$D$4:$D$7493,Cobranza!$B11,Recibos!AE$4:AE$7493) -> 0 | ... BW11: =SUMIF(Recibos!$D$4:$D$7493,Cobranza!$B11,Recibos!AI$4:AI$7493) -> 0 | BX11: =SUM(BL11:BW11) -> 0 | BY11: =SUMIF(Recibos!$D$4:$D$7493,Cobranza!$B11,Recibos!AK$4:AK$7493) -> 0 | BZ11: =SUMIF(Recibos!$D$4:$D$7493,Cobranza!$B11,Recibos!AL$4:AL$7493) -> 0 | CA11: =SUMIF(Recibos!$D$4:$D$7493,Cobranza!$B11,Recibos!AM$4:AM$7493) -> 0 | CB11: =SUMIF(Recibos!$D$4:$D$7493,Cobranza!$B11,Recibos!AN$4:AN$7493) -> 400 | CC11: =SUMIF(Recibos!$D$4:$D$7493,Cobranza!$B11,Recibos!AO$4:AO$7493) -> 400 | CD11: =SUMIF(Recibos!$D$4:$D$7493,Cobranza!$B11,Recibos!AP$4:AP$7493) -> 400 | CE11: =SUMIF(Recibos!$D$4:$D$7493,Cobranza!$B11,Recibos!AQ$4:AQ$7493) -> 400 | CF11: =SUMIF(Recibos!$D$4:$D$7493,Cobranza!$B11,Recibos!AR$4:AR$7493) -> 400 | ... CJ11: =SUMIF(Recibos!$D$4:$D$7493,Cobranza!$B11,Recibos!AV$4:AV$7493) -> 0 | CK11: =SUM(BY11:CJ11) -> 2400
B12: CL_12_ | C12: Rancho La Cuchilla No. 12 | D12: Rivera Flores | E12: 0 | F12: 0 | G12: 0 | H12: 0 | I12: 0 | J12: 250 | K12: =SUM(E12:J12) -> 250 | L12: 300 | M12: 300 | N12: 300 | O12: 300 | P12: 300 | Q12: 300 | R12: 300 | S12: 300 | T12: 300 | U12: 350 | V12: 350 | W12: 350 | X12: =SUM(L12:W12) -> 3750 | Y12: 300 | Z12: 300 | AA12: 300 | AB12: 300 | AC12: 300 | AD12: 300 | AE12: 300 | AF12: 300 | AG12: 300 | AH12: 300 | AI12: 300 | AJ12: 300 | AK12: =SUM(Y12:AJ12) -> 3600 | AL12: 300 | AM12: 300 | AN12: 300 | AO12: 300 | AP12: 300 | AQ12: 300 | AR12: 300 | AS12: 300 | AT12: 300 | AU12: 300 | AV12: 300 | AW12: 300 | AX12: =SUM(AL12:AW12) -> 3600 | AY12: =SUMIF(Recibos!$D$4:$D$7493,Cobranza!$B12,Recibos!K$4:K$7493) -> 300 | AZ12: =SUMIF(Recibos!$D$4:$D$7493,Cobranza!$B12,Recibos!L$4:L$7493) -> 300 | BA12: =SUMIF(Recibos!$D$4:$D$7493,Cobranza!$B12,Recibos!M$4:M$7493) -> 300 | BB12: =SUMIF(Recibos!$D$4:$D$7493,Cobranza!$B12,Recibos!N$4:N$7493) -> 300 | BC12: =SUMIF(Recibos!$D$4:$D$7493,Cobranza!$B12,Recibos!O$4:O$7493) -> 300 | BD12: =SUMIF(Recibos!$D$4:$D$7493,Cobranza!$B12,Recibos!P$4:P$7493) -> 300 | BE12: =SUMIF(Recibos!$D$4:$D$7493,Cobranza!$B12,Recibos!Q$4:Q$7493) -> 300 | BF12: =SUMIF(Recibos!$D$4:$D$7493,Cobranza!$B12,Recibos!R$4:R$7493) -> 300 | ... BJ12: =SUMIF(Recibos!$D$4:$D$7493,Cobranza!$B12,Recibos!V$4:V$7493) -> 300 | BK12: =SUM(AY12:BJ12) -> 3600 | BL12: =SUMIF(Recibos!$D$4:$D$7493,Cobranza!$B12,Recibos!X$4:X$7493) -> 350 | BM12: =SUMIF(Recibos!$D$4:$D$7493,Cobranza!$B12,Recibos!Y$4:Y$7493) -> 350 | BN12: =SUMIF(Recibos!$D$4:$D$7493,Cobranza!$B12,Recibos!Z$4:Z$7493) -> 350 | BO12: =SUMIF(Recibos!$D$4:$D$7493,Cobranza!$B12,Recibos!AA$4:AA$7493) -> 350 | BP12: =SUMIF(Recibos!$D$4:$D$7493,Cobranza!$B12,Recibos!AB$4:AB$7493) -> 0 | BQ12: =SUMIF(Recibos!$D$4:$D$7493,Cobranza!$B12,Recibos!AC$4:AC$7493) -> 0 | BR12: =SUMIF(Recibos!$D$4:$D$7493,Cobranza!$B12,Recibos!AD$4:AD$7493) -> 0 | BS12: =SUMIF(Recibos!$D$4:$D$7493,Cobranza!$B12,Recibos!AE$4:AE$7493) -> 0 | ... BW12: =SUMIF(Recibos!$D$4:$D$7493,Cobranza!$B12,Recibos!AI$4:AI$7493) -> 0 | BX12: =SUM(BL12:BW12) -> 1400 | BY12: =SUMIF(Recibos!$D$4:$D$7493,Cobranza!$B12,Recibos!AK$4:AK$7493) -> 350 | BZ12: =SUMIF(Recibos!$D$4:$D$7493,Cobranza!$B12,Recibos!AL$4:AL$7493) -> 350 | CA12: =SUMIF(Recibos!$D$4:$D$7493,Cobranza!$B12,Recibos!AM$4:AM$7493) -> 350 | CB12: =SUMIF(Recibos!$D$4:$D$7493,Cobranza!$B12,Recibos!AN$4:AN$7493) -> 350 | CC12: =SUMIF(Recibos!$D$4:$D$7493,Cobranza!$B12,Recibos!AO$4:AO$7493) -> 350 | CD12: =SUMIF(Recibos!$D$4:$D$7493,Cobranza!$B12,Recibos!AP$4:AP$7493) -> 350 | CE12: =SUMIF(Recibos!$D$4:$D$7493,Cobranza!$B12,Recibos!AQ$4:AQ$7493) -> 350 | CF12: =SUMIF(Recibos!$D$4:$D$7493,Cobranza!$B12,Recibos!AR$4:AR$7493) -> 350 | ... CJ12: =SUMIF(Recibos!$D$4:$D$7493,Cobranza!$B12,Recibos!AV$4:AV$7493) -> 350 | CK12: =SUM(BY12:CJ12) -> 4200
B13: CL_13_ | C13: Rancho La Cuchilla No. 13 | D13: Torres | E13: 0 | F13: 0 | G13: 0 | H13: 0 | I13: 0 | J13: 0 | K13: =SUM(E13:J13) -> 0 | L13: 0 | M13: 0 | N13: 0 | O13: 0 | P13: 0 | Q13: 0 | R13: 0 | S13: 0 | T13: 0 | U13: 0 | V13: 0 | W13: 0 | X13: =SUM(L13:W13) -> 0 | Y13: 0 | Z13: 0 | AA13: 0 | AB13: 0 | AC13: 0 | AD13: 0 | AE13: 0 | AF13: 0 | AG13: 0 | AH13: 0 | AI13: 0 | AJ13: 0 | AK13: =SUM(Y13:AJ13) -> 0 | AL13: 0 | AM13: 0 | AN13: 0 | AO13: 0 | AP13: 0 | AQ13: 0 | AR13: 0 | AS13: 0 | AT13: 0 | AU13: 0 | AV13: 0 | AW13: 0 | AX13: =SUM(AL13:AW13) -> 0 | AY13: =SUMIF(Recibos!$D$4:$D$7493,Cobranza!$B13,Recibos!K$4:K$7493) -> 0 | AZ13: =SUMIF(Recibos!$D$4:$D$7493,Cobranza!$B13,Recibos!L$4:L$7493) -> 0 | BA13: =SUMIF(Recibos!$D$4:$D$7493,Cobranza!$B13,Recibos!M$4:M$7493) -> 0 | BB13: =SUMIF(Recibos!$D$4:$D$7493,Cobranza!$B13,Recibos!N$4:N$7493) -> 0 | BC13: =SUMIF(Recibos!$D$4:$D$7493,Cobranza!$B13,Recibos!O$4:O$7493) -> 0 | BD13: =SUMIF(Recibos!$D$4:$D$7493,Cobranza!$B13,Recibos!P$4:P$7493) -> 0 | BE13: =SUMIF(Recibos!$D$4:$D$7493,Cobranza!$B13,Recibos!Q$4:Q$7493) -> 0 | BF13: =SUMIF(Recibos!$D$4:$D$7493,Cobranza!$B13,Recibos!R$4:R$7493) -> 200 | ... BJ13: =SUMIF(Recibos!$D$4:$D$7493,Cobranza!$B13,Recibos!V$4:V$7493) -> 0 | BK13: =SUM(AY13:BJ13) -> 200 | BL13: =SUMIF(Recibos!$D$4:$D$7493,Cobranza!$B13,Recibos!X$4:X$7493) -> 0 | BM13: =SUMIF(Recibos!$D$4:$D$7493,Cobranza!$B13,Recibos!Y$4:Y$7493) -> 0 | BN13: =SUMIF(Recibos!$D$4:$D$7493,Cobranza!$B13,Recibos!Z$4:Z$7493) -> 0 | BO13: =SUMIF(Recibos!$D$4:$D$7493,Cobranza!$B13,Recibos!AA$4:AA$7493) -> 0 | BP13: =SUMIF(Recibos!$D$4:$D$7493,Cobranza!$B13,Recibos!AB$4:AB$7493) -> 0 | BQ13: =SUMIF(Recibos!$D$4:$D$7493,Cobranza!$B13,Recibos!AC$4:AC$7493) -> 0 | BR13: =SUMIF(Recibos!$D$4:$D$7493,Cobranza!$B13,Recibos!AD$4:AD$7493) -> 0 | BS13: =SUMIF(Recibos!$D$4:$D$7493,Cobranza!$B13,Recibos!AE$4:AE$7493) -> 0 | ... BW13: =SUMIF(Recibos!$D$4:$D$7493,Cobranza!$B13,Recibos!AI$4:AI$7493) -> 0 | BX13: =SUM(BL13:BW13) -> 0 | BY13: =SUMIF(Recibos!$D$4:$D$7493,Cobranza!$B13,Recibos!AK$4:AK$7493) -> 0 | BZ13: =SUMIF(Recibos!$D$4:$D$7493,Cobranza!$B13,Recibos!AL$4:AL$7493) -> 0 | CA13: =SUMIF(Recibos!$D$4:$D$7493,Cobranza!$B13,Recibos!AM$4:AM$7493) -> 0 | CB13: =SUMIF(Recibos!$D$4:$D$7493,Cobranza!$B13,Recibos!AN$4:AN$7493) -> 0 | CC13: =SUMIF(Recibos!$D$4:$D$7493,Cobranza!$B13,Recibos!AO$4:AO$7493) -> 0 | CD13: =SUMIF(Recibos!$D$4:$D$7493,Cobranza!$B13,Recibos!AP$4:AP$7493) -> 0 | CE13: =SUMIF(Recibos!$D$4:$D$7493,Cobranza!$B13,Recibos!AQ$4:AQ$7493) -> 0 | CF13: =SUMIF(Recibos!$D$4:$D$7493,Cobranza!$B13,Recibos!AR$4:AR$7493) -> 0 | ... CJ13: =SUMIF(Recibos!$D$4:$D$7493,Cobranza!$B13,Recibos!AV$4:AV$7493) -> 0 | CK13: =SUM(BY13:CJ13) -> 0
B14: CL_14_ | C14: Rancho La Cuchilla No. 14 | D14: Chávez Lara | E14: 0 | F14: 0 | G14: 0 | H14: 0 | I14: 0 | J14: 0 | K14: =SUM(E14:J14) -> 0 | L14: 0 | M14: 0 | N14: 0 | O14: 0 | P14: 300 | Q14: 300 | R14: 300 | S14: 300 | T14: 300 | U14: 300 | V14: 400 | W14: 400 | X14: =SUM(L14:W14) -> 2600 | Y14: 400 | Z14: 400 | AA14: 400 | AB14: 400 | AC14: 400 | AD14: 400 | AE14: 400 | AF14: 400 | AG14: 400 | AH14: 400 | AI14: 400 | AJ14: 400 | AK14: =SUM(Y14:AJ14) -> 4800 | AL14: 400 | AM14: 400 | AN14: 400 | AO14: 400 | AP14: 400 | AQ14: 400 | AR14: 400 | AS14: 400 | AT14: 400 | AU14: 400 | AV14: 400 | AW14: 400 | AX14: =SUM(AL14:AW14) -> 4800 | AY14: =SUMIF(Recibos!$D$4:$D$7493,Cobranza!$B14,Recibos!K$4:K$7493) -> 400 | AZ14: =SUMIF(Recibos!$D$4:$D$7493,Cobranza!$B14,Recibos!L$4:L$7493) -> 400 | BA14: =SUMIF(Recibos!$D$4:$D$7493,Cobranza!$B14,Recibos!M$4:M$7493) -> 400 | BB14: =SUMIF(Recibos!$D$4:$D$7493,Cobranza!$B14,Recibos!N$4:N$7493) -> 400 | BC14: =SUMIF(Recibos!$D$4:$D$7493,Cobranza!$B14,Recibos!O$4:O$7493) -> 400 | BD14: =SUMIF(Recibos!$D$4:$D$7493,Cobranza!$B14,Recibos!P$4:P$7493) -> 400 | BE14: =SUMIF(Recibos!$D$4:$D$7493,Cobranza!$B14,Recibos!Q$4:Q$7493) -> 400 | BF14: =SUMIF(Recibos!$D$4:$D$7493,Cobranza!$B14,Recibos!R$4:R$7493) -> 400 | ... BJ14: =SUMIF(Recibos!$D$4:$D$7493,Cobranza!$B14,Recibos!V$4:V$7493) -> 0 | BK14: =SUM(AY14:BJ14) -> 4400 | BL14: =SUMIF(Recibos!$D$4:$D$7493,Cobranza!$B14,Recibos!X$4:X$7493) -> 400 | BM14: =SUMIF(Recibos!$D$4:$D$7493,Cobranza!$B14,Recibos!Y$4:Y$7493) -> 400 | BN14: =SUMIF(Recibos!$D$4:$D$7493,Cobranza!$B14,Recibos!Z$4:Z$7493) -> 400 | BO14: =SUMIF(Recibos!$D$4:$D$7493,Cobranza!$B14,Recibos!AA$4:AA$7493) -> 400 | BP14: =SUMIF(Recibos!$D$4:$D$7493,Cobranza!$B14,Recibos!AB$4:AB$7493) -> 400 | BQ14: =SUMIF(Recibos!$D$4:$D$7493,Cobranza!$B14,Recibos!AC$4:AC$7493) -> 400 | BR14: =SUMIF(Recibos!$D$4:$D$7493,Cobranza!$B14,Recibos!AD$4:AD$7493) -> 400 | BS14: =SUMIF(Recibos!$D$4:$D$7493,Cobranza!$B14,Recibos!AE$4:AE$7493) -> 400 | ... BW14: =SUMIF(Recibos!$D$4:$D$7493,Cobranza!$B14,Recibos!AI$4:AI$7493) -> 0 | BX14: =SUM(BL14:BW14) -> 4400 | BY14: =SUMIF(Recibos!$D$4:$D$7493,Cobranza!$B14,Recibos!AK$4:AK$7493) -> 400 | BZ14: =SUMIF(Recibos!$D$4:$D$7493,Cobranza!$B14,Recibos!AL$4:AL$7493) -> 400 | CA14: =SUMIF(Recibos!$D$4:$D$7493,Cobranza!$B14,Recibos!AM$4:AM$7493) -> 400 | CB14: =SUMIF(Recibos!$D$4:$D$7493,Cobranza!$B14,Recibos!AN$4:AN$7493) -> 400 | CC14: =SUMIF(Recibos!$D$4:$D$7493,Cobranza!$B14,Recibos!AO$4:AO$7493) -> 400 | CD14: =SUMIF(Recibos!$D$4:$D$7493,Cobranza!$B14,Recibos!AP$4:AP$7493) -> 400 | CE14: =SUMIF(Recibos!$D$4:$D$7493,Cobranza!$B14,Recibos!AQ$4:AQ$7493) -> 400 | CF14: =SUMIF(Recibos!$D$4:$D$7493,Cobranza!$B14,Recibos!AR$4:AR$7493) -> 400 | ... CJ14: =SUMIF(Recibos!$D$4:$D$7493,Cobranza!$B14,Recibos!AV$4:AV$7493) -> 0 | CK14: =SUM(BY14:CJ14) -> 4400
B15: CL_15_ | C15: Rancho La Cuchilla No. 15 | D15: Guerrero Ponce | E15: 0 | F15: 0 | G15: 0 | H15: 300 | I15: 300 | J15: 300 | K15: =SUM(E15:J15) -> 900 | L15: 300 | M15: 300 | N15: 300 | O15: 300 | P15: 300 | Q15: 300 | R15: 300 | S15: 300 | T15: 300 | U15: 300 | V15: 300 | W15: 300 | X15: =SUM(L15:W15) -> 3600 | Y15: 300 | Z15: 300 | AA15: 300 | AB15: 300 | AC15: 300 | AD15: 300 | AE15: 300 | AF15: 300 | AG15: 300 | AH15: 300 | AI15: 300 | AJ15: 300 | AK15: =SUM(Y15:AJ15) -> 3600 | AL15: 300 | AM15: 300 | AN15: 300 | AO15: 300 | AP15: 300 | AQ15: 300 | AR15: 300 | AS15: 300 | AT15: 300 | AU15: 300 | AV15: 300 | AW15: 300 | AX15: =SUM(AL15:AW15) -> 3600 | AY15: =SUMIF(Recibos!$D$4:$D$7493,Cobranza!$B15,Recibos!K$4:K$7493) -> 0 | AZ15: =SUMIF(Recibos!$D$4:$D$7493,Cobranza!$B15,Recibos!L$4:L$7493) -> 0 | BA15: =SUMIF(Recibos!$D$4:$D$7493,Cobranza!$B15,Recibos!M$4:M$7493) -> 300 | BB15: =SUMIF(Recibos!$D$4:$D$7493,Cobranza!$B15,Recibos!N$4:N$7493) -> 300 | BC15: =SUMIF(Recibos!$D$4:$D$7493,Cobranza!$B15,Recibos!O$4:O$7493) -> 0 | BD15: =SUMIF(Recibos!$D$4:$D$7493,Cobranza!$B15,Recibos!P$4:P$7493) -> 300 | BE15: =SUMIF(Recibos!$D$4:$D$7493,Cobranza!$B15,Recibos!Q$4:Q$7493) -> 300 | BF15: =SUMIF(Recibos!$D$4:$D$7493,Cobranza!$B15,Recibos!R$4:R$7493) -> 300 | ... BJ15: =SUMIF(Recibos!$D$4:$D$7493,Cobranza!$B15,Recibos!V$4:V$7493) -> 300 | BK15: =SUM(AY15:BJ15) -> 2700 | BL15: =SUMIF(Recibos!$D$4:$D$7493,Cobranza!$B15,Recibos!X$4:X$7493) -> 300 | BM15: =SUMIF(Recibos!$D$4:$D$7493,Cobranza!$B15,Recibos!Y$4:Y$7493) -> 300 | BN15: =SUMIF(Recibos!$D$4:$D$7493,Cobranza!$B15,Recibos!Z$4:Z$7493) -> 300 | BO15: =SUMIF(Recibos!$D$4:$D$7493,Cobranza!$B15,Recibos!AA$4:AA$7493) -> 300 | BP15: =SUMIF(Recibos!$D$4:$D$7493,Cobranza!$B15,Recibos!AB$4:AB$7493) -> 300 | BQ15: =SUMIF(Recibos!$D$4:$D$7493,Cobranza!$B15,Recibos!AC$4:AC$7493) -> 300 | BR15: =SUMIF(Recibos!$D$4:$D$7493,Cobranza!$B15,Recibos!AD$4:AD$7493) -> 300 | BS15: =SUMIF(Recibos!$D$4:$D$7493,Cobranza!$B15,Recibos!AE$4:AE$7493) -> 300 | ... BW15: =SUMIF(Recibos!$D$4:$D$7493,Cobranza!$B15,Recibos!AI$4:AI$7493) -> 300 | BX15: =SUM(BL15:BW15) -> 3600 | BY15: =SUMIF(Recibos!$D$4:$D$7493,Cobranza!$B15,Recibos!AK$4:AK$7493) -> 300 | BZ15: =SUMIF(Recibos!$D$4:$D$7493,Cobranza!$B15,Recibos!AL$4:AL$7493) -> 300 | CA15: =SUMIF(Recibos!$D$4:$D$7493,Cobranza!$B15,Recibos!AM$4:AM$7493) -> 300 | CB15: =SUMIF(Recibos!$D$4:$D$7493,Cobranza!$B15,Recibos!AN$4:AN$7493) -> 300 | CC15: =SUMIF(Recibos!$D$4:$D$7493,Cobranza!$B15,Recibos!AO$4:AO$7493) -> 300 | CD15: =SUMIF(Recibos!$D$4:$D$7493,Cobranza!$B15,Recibos!AP$4:AP$7493) -> 300 | CE15: =SUMIF(Recibos!$D$4:$D$7493,Cobranza!$B15,Recibos!AQ$4:AQ$7493) -> 300 | CF15: =SUMIF(Recibos!$D$4:$D$7493,Cobranza!$B15,Recibos!AR$4:AR$7493) -> 300 | ... CJ15: =SUMIF(Recibos!$D$4:$D$7493,Cobranza!$B15,Recibos!AV$4:AV$7493) -> 0 | CK15: =SUM(BY15:CJ15) -> 2400
B16: CL_17_A | E16: 0 | F16: 0 | G16: 0 | H16: 0 | I16: 0 | J16: 0 | K16: =SUM(E16:J16) -> 0 | L16: 0 | M16: 0 | N16: 0 | O16: 0 | P16: 0 | Q16: 0 | R16: 0 | S16: 0 | T16: 0 | U16: 0 | V16: 0 | W16: 0 | X16: =SUM(L16:W16) -> 0 | AX16: =SUM(AL16:AW16) -> 0 | AY16: =SUMIF(Recibos!$D$4:$D$7493,Cobranza!$B16,Recibos!K$4:K$7493) -> 0 | AZ16: =SUMIF(Recibos!$D$4:$D$7493,Cobranza!$B16,Recibos!L$4:L$7493) -> 0 | BA16: =SUMIF(Recibos!$D$4:$D$7493,Cobranza!$B16,Recibos!M$4:M$7493) -> 0 | BB16: =SUMIF(Recibos!$D$4:$D$7493,Cobranza!$B16,Recibos!N$4:N$7493) -> 0 | BC16: =SUMIF(Recibos!$D$4:$D$7493,Cobranza!$B16,Recibos!O$4:O$7493) -> 0 | BD16: =SUMIF(Recibos!$D$4:$D$7493,Cobranza!$B16,Recibos!P$4:P$7493) -> 0 | BE16: =SUMIF(Recibos!$D$4:$D$7493,Cobranza!$B16,Recibos!Q$4:Q$7493) -> 0 | BF16: =SUMIF(Recibos!$D$4:$D$7493,Cobranza!$B16,Recibos!R$4:R$7493) -> 0 | ... BJ16: =SUMIF(Recibos!$D$4:$D$7493,Cobranza!$B16,Recibos!V$4:V$7493) -> 0 | BK16: =SUM(AY16:BJ16) -> 0 | BL16: =SUMIF(Recibos!$D$4:$D$7493,Cobranza!$B16,Recibos!X$4:X$7493) -> 0 | BM16: =SUMIF(Recibos!$D$4:$D$7493,Cobranza!$B16,Recibos!Y$4:Y$7493) -> 0 | BN16: =SUMIF(Recibos!$D$4:$D$7493,Cobranza!$B16,Recibos!Z$4:Z$7493) -> 0 | BO16: =SUMIF(Recibos!$D$4:$D$7493,Cobranza!$B16,Recibos!AA$4:AA$7493) -> 0 | BP16: =SUMIF(Recibos!$D$4:$D$7493,Cobranza!$B16,Recibos!AB$4:AB$7493) -> 0 | BQ16: =SUMIF(Recibos!$D$4:$D$7493,Cobranza!$B16,Recibos!AC$4:AC$7493) -> 0 | BR16: =SUMIF(Recibos!$D$4:$D$7493,Cobranza!$B16,Recibos!AD$4:AD$7493) -> 0 | BS16: =SUMIF(Recibos!$D$4:$D$7493,Cobranza!$B16,Recibos!AE$4:AE$7493) -> 0 | ... BW16: =SUMIF(Recibos!$D$4:$D$7493,Cobranza!$B16,Recibos!AI$4:AI$7493) -> 0 | BX16: =SUM(BL16:BW16) -> 0 | BY16: =SUMIF(Recibos!$D$4:$D$7493,Cobranza!$B16,Recibos!AK$4:AK$7493) -> 0 | BZ16: =SUMIF(Recibos!$D$4:$D$7493,Cobranza!$B16,Recibos!AL$4:AL$7493) -> 0 | CA16: =SUMIF(Recibos!$D$4:$D$7493,Cobranza!$B16,Recibos!AM$4:AM$7493) -> 0 | CB16: =SUMIF(Recibos!$D$4:$D$7493,Cobranza!$B16,Recibos!AN$4:AN$7493) -> 0 | CC16: =SUMIF(Recibos!$D$4:$D$7493,Cobranza!$B16,Recibos!AO$4:AO$7493) -> 0 | CD16: =SUMIF(Recibos!$D$4:$D$7493,Cobranza!$B16,Recibos!AP$4:AP$7493) -> 0 | CE16: =SUMIF(Recibos!$D$4:$D$7493,Cobranza!$B16,Recibos!AQ$4:AQ$7493) -> 0 | CF16: =SUMIF(Recibos!$D$4:$D$7493,Cobranza!$B16,Recibos!AR$4:AR$7493) -> 0 | ... CJ16: =SUMIF(Recibos!$D$4:$D$7493,Cobranza!$B16,Recibos!AV$4:AV$7493) -> 0 | CK16: =SUM(BY16:CJ16) -> 0
B17: CL_18_ | C17: Rancho La Cuchilla No. 18 | D17: Aldana Sánchez | E17: 0 | F17: 0 | G17: 0 | H17: 0 | I17: 0 | J17: 300 | K17: =SUM(E17:J17) -> 300 | L17: 300 | M17: 300 | N17: 300 | O17: 300 | P17: 300 | Q17: 300 | R17: 300 | S17: 300 | T17: 300 | U17: 400 | V17: 400 | W17: 400 | X17: =SUM(L17:W17) -> 3900 | Y17: 400 | Z17: 400 | AA17: 400 | AB17: 400 | AC17: 400 | AD17: 400 | AE17: 400 | AF17: 400 | AG17: 400 | AH17: 400 | AI17: 400 | AJ17: 400 | AK17: =SUM(Y17:AJ17) -> 4800 | AL17: 400 | AM17: 400 | AN17: 400 | AO17: 400 | AP17: 400 | AQ17: 400 | AR17: 400 | AS17: 400 | AT17: 400 | AU17: 400 | AV17: 400 | AW17: 400 | AX17: =SUM(AL17:AW17) -> 4800 | AY17: =SUMIF(Recibos!$D$4:$D$7493,Cobranza!$B17,Recibos!K$4:K$7493) -> 400 | AZ17: =SUMIF(Recibos!$D$4:$D$7493,Cobranza!$B17,Recibos!L$4:L$7493) -> 400 | BA17: =SUMIF(Recibos!$D$4:$D$7493,Cobranza!$B17,Recibos!M$4:M$7493) -> 400 | BB17: =SUMIF(Recibos!$D$4:$D$7493,Cobranza!$B17,Recibos!N$4:N$7493) -> 400 | BC17: =SUMIF(Recibos!$D$4:$D$7493,Cobranza!$B17,Recibos!O$4:O$7493) -> 400 | BD17: =SUMIF(Recibos!$D$4:$D$7493,Cobranza!$B17,Recibos!P$4:P$7493) -> 400 | BE17: =SUMIF(Recibos!$D$4:$D$7493,Cobranza!$B17,Recibos!Q$4:Q$7493) -> 400 | BF17: =SUMIF(Recibos!$D$4:$D$7493,Cobranza!$B17,Recibos!R$4:R$7493) -> 400 | ... BJ17: =SUMIF(Recibos!$D$4:$D$7493,Cobranza!$B17,Recibos!V$4:V$7493) -> 400 | BK17: =SUM(AY17:BJ17) -> 4800 | BL17: =SUMIF(Recibos!$D$4:$D$7493,Cobranza!$B17,Recibos!X$4:X$7493) -> 400 | BM17: =SUMIF(Recibos!$D$4:$D$7493,Cobranza!$B17,Recibos!Y$4:Y$7493) -> 400 | BN17: =SUMIF(Recibos!$D$4:$D$7493,Cobranza!$B17,Recibos!Z$4:Z$7493) -> 400 | BO17: =SUMIF(Recibos!$D$4:$D$7493,Cobranza!$B17,Recibos!AA$4:AA$7493) -> 400 | BP17: =SUMIF(Recibos!$D$4:$D$7493,Cobranza!$B17,Recibos!AB$4:AB$7493) -> 400 | BQ17: =SUMIF(Recibos!$D$4:$D$7493,Cobranza!$B17,Recibos!AC$4:AC$7493) -> 400 | BR17: =SUMIF(Recibos!$D$4:$D$7493,Cobranza!$B17,Recibos!AD$4:AD$7493) -> 400 | BS17: =SUMIF(Recibos!$D$4:$D$7493,Cobranza!$B17,Recibos!AE$4:AE$7493) -> 400 | ... BW17: =SUMIF(Recibos!$D$4:$D$7493,Cobranza!$B17,Recibos!AI$4:AI$7493) -> 400 | BX17: =SUM(BL17:BW17) -> 4800 | BY17: =SUMIF(Recibos!$D$4:$D$7493,Cobranza!$B17,Recibos!AK$4:AK$7493) -> 400 | BZ17: =SUMIF(Recibos!$D$4:$D$7493,Cobranza!$B17,Recibos!AL$4:AL$7493) -> 400 | CA17: =SUMIF(Recibos!$D$4:$D$7493,Cobranza!$B17,Recibos!AM$4:AM$7493) -> 400 | CB17: =SUMIF(Recibos!$D$4:$D$7493,Cobranza!$B17,Recibos!AN$4:AN$7493) -> 400 | CC17: =SUMIF(Recibos!$D$4:$D$7493,Cobranza!$B17,Recibos!AO$4:AO$7493) -> 400 | CD17: =SUMIF(Recibos!$D$4:$D$7493,Cobranza!$B17,Recibos!AP$4:AP$7493) -> 400 | CE17: =SUMIF(Recibos!$D$4:$D$7493,Cobranza!$B17,Recibos!AQ$4:AQ$7493) -> 400 | CF17: =SUMIF(Recibos!$D$4:$D$7493,Cobranza!$B17,Recibos!AR$4:AR$7493) -> 400 | ... CJ17: =SUMIF(Recibos!$D$4:$D$7493,Cobranza!$B17,Recibos!AV$4:AV$7493) -> 0 | CK17: =SUM(BY17:CJ17) -> 4000
B18: CL_19_ | C18: Rancho La Cuchilla No. 19 | D18: Tapia Vázquez | E18: 0 | F18: 0 | G18: 0 | H18: 0 | I18: 0 | J18: 300 | K18: =SUM(E18:J18) -> 300 | L18: 300 | M18: 300 | N18: 300 | O18: 300 | P18: 300 | Q18: 300 | R18: 300 | S18: 300 | T18: 300 | U18: 300 | V18: 300 | W18: 300 | X18: =SUM(L18:W18) -> 3600 | Y18: 300 | Z18: 300 | AA18: 300 | AB18: 300 | AC18: 300 | AD18: 300 | AE18: 300 | AF18: 300 | AG18: 300 | AH18: 300 | AI18: 300 | AJ18: 300 | AK18: =SUM(Y18:AJ18) -> 3600 | AL18: 300 | AM18: 300 | AN18: 300 | AO18: 300 | AP18: 300 | AQ18: 300 | AR18: 300 | AS18: 300 | AT18: 300 | AU18: 300 | AV18: 300 | AW18: 300 | AX18: =SUM(AL18:AW18) -> 3600 | AY18: =SUMIF(Recibos!$D$4:$D$7493,Cobranza!$B18,Recibos!K$4:K$7493) -> 300 | AZ18: =SUMIF(Recibos!$D$4:$D$7493,Cobranza!$B18,Recibos!L$4:L$7493) -> 300 | BA18: =SUMIF(Recibos!$D$4:$D$7493,Cobranza!$B18,Recibos!M$4:M$7493) -> 300 | BB18: =SUMIF(Recibos!$D$4:$D$7493,Cobranza!$B18,Recibos!N$4:N$7493) -> 300 | BC18: =SUMIF(Recibos!$D$4:$D$7493,Cobranza!$B18,Recibos!O$4:O$7493) -> 300 | BD18: =SUMIF(Recibos!$D$4:$D$7493,Cobranza!$B18,Recibos!P$4:P$7493) -> 300 | BE18: =SUMIF(Recibos!$D$4:$D$7493,Cobranza!$B18,Recibos!Q$4:Q$7493) -> 300 | BF18: =SUMIF(Recibos!$D$4:$D$7493,Cobranza!$B18,Recibos!R$4:R$7493) -> 300 | ... BJ18: =SUMIF(Recibos!$D$4:$D$7493,Cobranza!$B18,Recibos!V$4:V$7493) -> 0 | BK18: =SUM(AY18:BJ18) -> 3300 | BL18: =SUMIF(Recibos!$D$4:$D$7493,Cobranza!$B18,Recibos!X$4:X$7493) -> 300 | BM18: =SUMIF(Recibos!$D$4:$D$7493,Cobranza!$B18,Recibos!Y$4:Y$7493) -> 300 | BN18: =SUMIF(Recibos!$D$4:$D$7493,Cobranza!$B18,Recibos!Z$4:Z$7493) -> 300 | BO18: =SUMIF(Recibos!$D$4:$D$7493,Cobranza!$B18,Recibos!AA$4:AA$7493) -> 300 | BP18: =SUMIF(Recibos!$D$4:$D$7493,Cobranza!$B18,Recibos!AB$4:AB$7493) -> 300 | BQ18: =SUMIF(Recibos!$D$4:$D$7493,Cobranza!$B18,Recibos!AC$4:AC$7493) -> 300 | BR18: =SUMIF(Recibos!$D$4:$D$7493,Cobranza!$B18,Recibos!AD$4:AD$7493) -> 300 | BS18: =SUMIF(Recibos!$D$4:$D$7493,Cobranza!$B18,Recibos!AE$4:AE$7493) -> 300 | ... BW18: =SUMIF(Recibos!$D$4:$D$7493,Cobranza!$B18,Recibos!AI$4:AI$7493) -> 0 | BX18: =SUM(BL18:BW18) -> 3300 | BY18: =SUMIF(Recibos!$D$4:$D$7493,Cobranza!$B18,Recibos!AK$4:AK$7493) -> 300 | BZ18: =SUMIF(Recibos!$D$4:$D$7493,Cobranza!$B18,Recibos!AL$4:AL$7493) -> 300 | CA18: =SUMIF(Recibos!$D$4:$D$7493,Cobranza!$B18,Recibos!AM$4:AM$7493) -> 300 | CB18: =SUMIF(Recibos!$D$4:$D$7493,Cobranza!$B18,Recibos!AN$4:AN$7493) -> 300 | CC18: =SUMIF(Recibos!$D$4:$D$7493,Cobranza!$B18,Recibos!AO$4:AO$7493) -> 300 | CD18: =SUMIF(Recibos!$D$4:$D$7493,Cobranza!$B18,Recibos!AP$4:AP$7493) -> 300 | CE18: =SUMIF(Recibos!$D$4:$D$7493,Cobranza!$B18,Recibos!AQ$4:AQ$7493) -> 300 | CF18: =SUMIF(Recibos!$D$4:$D$7493,Cobranza!$B18,Recibos!AR$4:AR$7493) -> 300 | ... CJ18: =SUMIF(Recibos!$D$4:$D$7493,Cobranza!$B18,Recibos!AV$4:AV$7493) -> 0 | CK18: =SUM(BY18:CJ18) -> 3300
B19: CL_20_ | C19: Rancho La Cuchilla No. 20 | D19: Sánchez López | E19: 0 | F19: 0 | G19: 0 | H19: 0 | I19: 0 | J19: 300 | K19: =SUM(E19:J19) -> 300 | L19: 300 | M19: 300 | N19: 300 | O19: 300 | P19: 300 | Q19: 300 | R19: 300 | S19: 300 | T19: 300 | U19: 400 | V19: 400 | W19: 400 | X19: =SUM(L19:W19) -> 3900 | Y19: 400 | Z19: 400 | AA19: 0 | AB19: 400 | AC19: 400 | AD19: 400 | AE19: 400 | AF19: 400 | AG19: 400 | AH19: 400 | AI19: 400 | AJ19: 400 | AK19: =SUM(Y19:AJ19) -> 4400 | AL19: 400 | AM19: 400 | AN19: 400 | AO19: 400 | AP19: 400 | AQ19: 400 | AR19: 400 | AS19: 400 | AT19: 400 | AU19: 400 | AV19: 400 | AW19: 400 | AX19: =SUM(AL19:AW19) -> 4800 | AY19: =SUMIF(Recibos!$D$4:$D$7493,Cobranza!$B19,Recibos!K$4:K$7493) -> 400 | AZ19: =SUMIF(Recibos!$D$4:$D$7493,Cobranza!$B19,Recibos!L$4:L$7493) -> 400 | BA19: =SUMIF(Recibos!$D$4:$D$7493,Cobranza!$B19,Recibos!M$4:M$7493) -> 400 | BB19: =SUMIF(Recibos!$D$4:$D$7493,Cobranza!$B19,Recibos!N$4:N$7493) -> 400 | BC19: =SUMIF(Recibos!$D$4:$D$7493,Cobranza!$B19,Recibos!O$4:O$7493) -> 400 | BD19: =SUMIF(Recibos!$D$4:$D$7493,Cobranza!$B19,Recibos!P$4:P$7493) -> 400 | BE19: =SUMIF(Recibos!$D$4:$D$7493,Cobranza!$B19,Recibos!Q$4:Q$7493) -> 400 | BF19: =SUMIF(Recibos!$D$4:$D$7493,Cobranza!$B19,Recibos!R$4:R$7493) -> 400 | ... BJ19: =SUMIF(Recibos!$D$4:$D$7493,Cobranza!$B19,Recibos!V$4:V$7493) -> 400 | BK19: =SUM(AY19:BJ19) -> 4800 | BL19: =SUMIF(Recibos!$D$4:$D$7493,Cobranza!$B19,Recibos!X$4:X$7493) -> 400 | BM19: =SUMIF(Recibos!$D$4:$D$7493,Cobranza!$B19,Recibos!Y$4:Y$7493) -> 400 | BN19: =SUMIF(Recibos!$D$4:$D$7493,Cobranza!$B19,Recibos!Z$4:Z$7493) -> 400 | BO19: =SUMIF(Recibos!$D$4:$D$7493,Cobranza!$B19,Recibos!AA$4:AA$7493) -> 400 | BP19: =SUMIF(Recibos!$D$4:$D$7493,Cobranza!$B19,Recibos!AB$4:AB$7493) -> 400 | BQ19: =SUMIF(Recibos!$D$4:$D$7493,Cobranza!$B19,Recibos!AC$4:AC$7493) -> 400 | BR19: =SUMIF(Recibos!$D$4:$D$7493,Cobranza!$B19,Recibos!AD$4:AD$7493) -> 400 | BS19: =SUMIF(Recibos!$D$4:$D$7493,Cobranza!$B19,Recibos!AE$4:AE$7493) -> 400 | ... BW19: =SUMIF(Recibos!$D$4:$D$7493,Cobranza!$B19,Recibos!AI$4:AI$7493) -> 400 | BX19: =SUM(BL19:BW19) -> 4800 | BY19: =SUMIF(Recibos!$D$4:$D$7493,Cobranza!$B19,Recibos!AK$4:AK$7493) -> 400 | BZ19: =SUMIF(Recibos!$D$4:$D$7493,Cobranza!$B19,Recibos!AL$4:AL$7493) -> 400 | CA19: =SUMIF(Recibos!$D$4:$D$7493,Cobranza!$B19,Recibos!AM$4:AM$7493) -> 400 | CB19: =SUMIF(Recibos!$D$4:$D$7493,Cobranza!$B19,Recibos!AN$4:AN$7493) -> 400 | CC19: =SUMIF(Recibos!$D$4:$D$7493,Cobranza!$B19,Recibos!AO$4:AO$7493) -> 400 | CD19: =SUMIF(Recibos!$D$4:$D$7493,Cobranza!$B19,Recibos!AP$4:AP$7493) -> 400 | CE19: =SUMIF(Recibos!$D$4:$D$7493,Cobranza!$B19,Recibos!AQ$4:AQ$7493) -> 400 | CF19: =SUMIF(Recibos!$D$4:$D$7493,Cobranza!$B19,Recibos!AR$4:AR$7493) -> 400 | ... CJ19: =SUMIF(Recibos!$D$4:$D$7493,Cobranza!$B19,Recibos!AV$4:AV$7493) -> 0 | CK19: =SUM(BY19:CJ19) -> 4000
B20: CL_21_ | C20: Rancho La Cuchilla No. 21 | D20: Solórzano Calderón | E20: 0 | F20: 0 | G20: 0 | H20: 0 | I20: 0 | J20: 0 | K20: =SUM(E20:J20) -> 0 | L20: 300 | M20: 300 | N20: 300 | O20: 300 | P20: 300 | Q20: 300 | R20: 300 | S20: 300 | T20: 300 | U20: 300 | V20: 300 | W20: 0 | X20: =SUM(L20:W20) -> 3300 | Y20: 400 | Z20: 400 | AA20: 400 | AB20: 400 | AC20: 400 | AD20: 400 | AE20: 400 | AF20: 400 | AG20: 800 | AH20: 400 | AI20: 400 | AJ20: 0 | AK20: =SUM(Y20:AJ20) -> 4800 | AL20: 400 | AM20: 400 | AN20: 400 | AO20: 400 | AP20: 400 | AQ20: 400 | AR20: 400 | AS20: 400 | AT20: 400 | AU20: 400 | AV20: 400 | AW20: 0 | AX20: =SUM(AL20:AW20) -> 4400 | AY20: =SUMIF(Recibos!$D$4:$D$7493,Cobranza!$B20,Recibos!K$4:K$7493) -> 400 | AZ20: =SUMIF(Recibos!$D$4:$D$7493,Cobranza!$B20,Recibos!L$4:L$7493) -> 400 | BA20: =SUMIF(Recibos!$D$4:$D$7493,Cobranza!$B20,Recibos!M$4:M$7493) -> 400 | BB20: =SUMIF(Recibos!$D$4:$D$7493,Cobranza!$B20,Recibos!N$4:N$7493) -> 400 | BC20: =SUMIF(Recibos!$D$4:$D$7493,Cobranza!$B20,Recibos!O$4:O$7493) -> 400 | BD20: =SUMIF(Recibos!$D$4:$D$7493,Cobranza!$B20,Recibos!P$4:P$7493) -> 400 | BE20: =SUMIF(Recibos!$D$4:$D$7493,Cobranza!$B20,Recibos!Q$4:Q$7493) -> 400 | BF20: =SUMIF(Recibos!$D$4:$D$7493,Cobranza!$B20,Recibos!R$4:R$7493) -> 400 | ... BJ20: =SUMIF(Recibos!$D$4:$D$7493,Cobranza!$B20,Recibos!V$4:V$7493) -> 0 | BK20: =SUM(AY20:BJ20) -> 4400 | BL20: =SUMIF(Recibos!$D$4:$D$7493,Cobranza!$B20,Recibos!X$4:X$7493) -> 400 | BM20: =SUMIF(Recibos!$D$4:$D$7493,Cobranza!$B20,Recibos!Y$4:Y$7493) -> 400 | BN20: =SUMIF(Recibos!$D$4:$D$7493,Cobranza!$B20,Recibos!Z$4:Z$7493) -> 400 | BO20: =SUMIF(Recibos!$D$4:$D$7493,Cobranza!$B20,Recibos!AA$4:AA$7493) -> 400 | BP20: =SUMIF(Recibos!$D$4:$D$7493,Cobranza!$B20,Recibos!AB$4:AB$7493) -> 400 | BQ20: =SUMIF(Recibos!$D$4:$D$7493,Cobranza!$B20,Recibos!AC$4:AC$7493) -> 400 | BR20: =SUMIF(Recibos!$D$4:$D$7493,Cobranza!$B20,Recibos!AD$4:AD$7493) -> 400 | BS20: =SUMIF(Recibos!$D$4:$D$7493,Cobranza!$B20,Recibos!AE$4:AE$7493) -> 400 | ... BW20: =SUMIF(Recibos!$D$4:$D$7493,Cobranza!$B20,Recibos!AI$4:AI$7493) -> 0 | BX20: =SUM(BL20:BW20) -> 4400 | BY20: =SUMIF(Recibos!$D$4:$D$7493,Cobranza!$B20,Recibos!AK$4:AK$7493) -> 400 | BZ20: =SUMIF(Recibos!$D$4:$D$7493,Cobranza!$B20,Recibos!AL$4:AL$7493) -> 400 | CA20: =SUMIF(Recibos!$D$4:$D$7493,Cobranza!$B20,Recibos!AM$4:AM$7493) -> 400 | CB20: =SUMIF(Recibos!$D$4:$D$7493,Cobranza!$B20,Recibos!AN$4:AN$7493) -> 400 | CC20: =SUMIF(Recibos!$D$4:$D$7493,Cobranza!$B20,Recibos!AO$4:AO$7493) -> 400 | CD20: =SUMIF(Recibos!$D$4:$D$7493,Cobranza!$B20,Recibos!AP$4:AP$7493) -> 400 | CE20: =SUMIF(Recibos!$D$4:$D$7493,Cobranza!$B20,Recibos!AQ$4:AQ$7493) -> 400 | CF20: =SUMIF(Recibos!$D$4:$D$7493,Cobranza!$B20,Recibos!AR$4:AR$7493) -> 400 | ... CJ20: =SUMIF(Recibos!$D$4:$D$7493,Cobranza!$B20,Recibos!AV$4:AV$7493) -> 0 | CK20: =SUM(BY20:CJ20) -> 4400
B21: CL_23_ | C21: Rancho La Cuchilla No. 23 | D21: Ocampo | E21: 0 | F21: 0 | G21: 0 | H21: 0 | I21: 0 | J21: 200 | K21: =SUM(E21:J21) -> 200 | L21: 200 | M21: 200 | N21: 200 | O21: 0 | P21: 0 | Q21: 0 | R21: 0 | S21: 0 | T21: 0 | U21: 0 | V21: 0 | W21: 0 | X21: =SUM(L21:W21) -> 600 | Y21: 0 | Z21: 0 | AA21: 0 | AB21: 0 | AC21: 0 | AD21: 0 | AE21: 0 | AF21: 0 | AG21: 0 | AH21: 0 | AI21: 0 | AJ21: 0 | AK21: =SUM(Y21:AJ21) -> 0 | AL21: 0 | AM21: 0 | AN21: 0 | AO21: 0 | AP21: 0 | AQ21: 0 | AR21: 0 | AS21: 0 | AT21: 0 | AU21: 0 | AV21: 0 | AW21: 0 | AX21: =SUM(AL21:AW21) -> 0 | AY21: =SUMIF(Recibos!$D$4:$D$7493,Cobranza!$B21,Recibos!K$4:K$7493) -> 0 | AZ21: =SUMIF(Recibos!$D$4:$D$7493,Cobranza!$B21,Recibos!L$4:L$7493) -> 0 | BA21: =SUMIF(Recibos!$D$4:$D$7493,Cobranza!$B21,Recibos!M$4:M$7493) -> 0 | BB21: =SUMIF(Recibos!$D$4:$D$7493,Cobranza!$B21,Recibos!N$4:N$7493) -> 0 | BC21: =SUMIF(Recibos!$D$4:$D$7493,Cobranza!$B21,Recibos!O$4:O$7493) -> 0 | BD21: =SUMIF(Recibos!$D$4:$D$7493,Cobranza!$B21,Recibos!P$4:P$7493) -> 200 | BE21: =SUMIF(Recibos!$D$4:$D$7493,Cobranza!$B21,Recibos!Q$4:Q$7493) -> 200 | BF21: =SUMIF(Recibos!$D$4:$D$7493,Cobranza!$B21,Recibos!R$4:R$7493) -> 200 | ... BJ21: =SUMIF(Recibos!$D$4:$D$7493,Cobranza!$B21,Recibos!V$4:V$7493) -> 200 | BK21: =SUM(AY21:BJ21) -> 1400 | BL21: =SUMIF(Recibos!$D$4:$D$7493,Cobranza!$B21,Recibos!X$4:X$7493) -> 200 | BM21: =SUMIF(Recibos!$D$4:$D$7493,Cobranza!$B21,Recibos!Y$4:Y$7493) -> 200 | BN21: =SUMIF(Recibos!$D$4:$D$7493,Cobranza!$B21,Recibos!Z$4:Z$7493) -> 200 | BO21: =SUMIF(Recibos!$D$4:$D$7493,Cobranza!$B21,Recibos!AA$4:AA$7493) -> 200 | BP21: =SUMIF(Recibos!$D$4:$D$7493,Cobranza!$B21,Recibos!AB$4:AB$7493) -> 200 | BQ21: =SUMIF(Recibos!$D$4:$D$7493,Cobranza!$B21,Recibos!AC$4:AC$7493) -> 200 | BR21: =SUMIF(Recibos!$D$4:$D$7493,Cobranza!$B21,Recibos!AD$4:AD$7493) -> 0 | BS21: =SUMIF(Recibos!$D$4:$D$7493,Cobranza!$B21,Recibos!AE$4:AE$7493) -> 0 | ... BW21: =SUMIF(Recibos!$D$4:$D$7493,Cobranza!$B21,Recibos!AI$4:AI$7493) -> 0 | BX21: =SUM(BL21:BW21) -> 1200 | BY21: =SUMIF(Recibos!$D$4:$D$7493,Cobranza!$B21,Recibos!AK$4:AK$7493) -> 0 | BZ21: =SUMIF(Recibos!$D$4:$D$7493,Cobranza!$B21,Recibos!AL$4:AL$7493) -> 0 | CA21: =SUMIF(Recibos!$D$4:$D$7493,Cobranza!$B21,Recibos!AM$4:AM$7493) -> 0 | CB21: =SUMIF(Recibos!$D$4:$D$7493,Cobranza!$B21,Recibos!AN$4:AN$7493) -> 0 | CC21: =SUMIF(Recibos!$D$4:$D$7493,Cobranza!$B21,Recibos!AO$4:AO$7493) -> 0 | CD21: =SUMIF(Recibos!$D$4:$D$7493,Cobranza!$B21,Recibos!AP$4:AP$7493) -> 0 | CE21: =SUMIF(Recibos!$D$4:$D$7493,Cobranza!$B21,Recibos!AQ$4:AQ$7493) -> 0 | CF21: =SUMIF(Recibos!$D$4:$D$7493,Cobranza!$B21,Recibos!AR$4:AR$7493) -> 0 | ... CJ21: =SUMIF(Recibos!$D$4:$D$7493,Cobranza!$B21,Recibos!AV$4:AV$7493) -> 0 | CK21: =SUM(BY21:CJ21) -> 0
B22: CL_25_ | C22: Rancho La Cuchilla No. 25 | D22: García de León | E22: 0 | F22: 0 | G22: 0 | H22: 0 | I22: 0 | J22: 0 | K22: =SUM(E22:J22) -> 0 | L22: 0 | M22: 0 | N22: 0 | O22: 0 | P22: 0 | Q22: 0 | R22: 0 | S22: 0 | T22: 0 | U22: 0 | V22: 0 | W22: 0 | X22: =SUM(L22:W22) -> 0 | Y22: 0 | Z22: 0 | AA22: 0 | AB22: 0 | AC22: 0 | AD22: 0 | AE22: 0 | AF22: 0 | AG22: 0 | AH22: 0 | AI22: 0 | AJ22: 0 | AK22: =SUM(Y22:AJ22) -> 0 | AL22: 0 | AM22: 0 | AN22: 0 | AO22: 0 | AP22: 0 | AQ22: 0 | AR22: 0 | AS22: 0 | AT22: 0 | AU22: 0 | AV22: 0 | AW22: 0 | AX22: =SUM(AL22:AW22) -> 0 | AY22: =SUMIF(Recibos!$D$4:$D$7493,Cobranza!$B22,Recibos!K$4:K$7493) -> 0 | AZ22: =SUMIF(Recibos!$D$4:$D$7493,Cobranza!$B22,Recibos!L$4:L$7493) -> 0 | BA22: =SUMIF(Recibos!$D$4:$D$7493,Cobranza!$B22,Recibos!M$4:M$7493) -> 0 | BB22: =SUMIF(Recibos!$D$4:$D$7493,Cobranza!$B22,Recibos!N$4:N$7493) -> 0 | BC22: =SUMIF(Recibos!$D$4:$D$7493,Cobranza!$B22,Recibos!O$4:O$7493) -> 0 | BD22: =SUMIF(Recibos!$D$4:$D$7493,Cobranza!$B22,Recibos!P$4:P$7493) -> 0 | BE22: =SUMIF(Recibos!$D$4:$D$7493,Cobranza!$B22,Recibos!Q$4:Q$7493) -> 0 | BF22: =SUMIF(Recibos!$D$4:$D$7493,Cobranza!$B22,Recibos!R$4:R$7493) -> 0 | ... BJ22: =SUMIF(Recibos!$D$4:$D$7493,Cobranza!$B22,Recibos!V$4:V$7493) -> 0 | BK22: =SUM(AY22:BJ22) -> 0 | BL22: =SUMIF(Recibos!$D$4:$D$7493,Cobranza!$B22,Recibos!X$4:X$7493) -> 0 | BM22: =SUMIF(Recibos!$D$4:$D$7493,Cobranza!$B22,Recibos!Y$4:Y$7493) -> 0 | BN22: =SUMIF(Recibos!$D$4:$D$7493,Cobranza!$B22,Recibos!Z$4:Z$7493) -> 0 | BO22: =SUMIF(Recibos!$D$4:$D$7493,Cobranza!$B22,Recibos!AA$4:AA$7493) -> 0 | BP22: =SUMIF(Recibos!$D$4:$D$7493,Cobranza!$B22,Recibos!AB$4:AB$7493) -> 0 | BQ22: =SUMIF(Recibos!$D$4:$D$7493,Cobranza!$B22,Recibos!AC$4:AC$7493) -> 0 | BR22: =SUMIF(Recibos!$D$4:$D$7493,Cobranza!$B22,Recibos!AD$4:AD$7493) -> 0 | BS22: =SUMIF(Recibos!$D$4:$D$7493,Cobranza!$B22,Recibos!AE$4:AE$7493) -> 0 | ... BW22: =SUMIF(Recibos!$D$4:$D$7493,Cobranza!$B22,Recibos!AI$4:AI$7493) -> 0 | BX22: =SUM(BL22:BW22) -> 0 | BY22: =SUMIF(Recibos!$D$4:$D$7493,Cobranza!$B22,Recibos!AK$4:AK$7493) -> 0 | BZ22: =SUMIF(Recibos!$D$4:$D$7493,Cobranza!$B22,Recibos!AL$4:AL$7493) -> 0 | CA22: =SUMIF(Recibos!$D$4:$D$7493,Cobranza!$B22,Recibos!AM$4:AM$7493) -> 0 | CB22: =SUMIF(Recibos!$D$4:$D$7493,Cobranza!$B22,Recibos!AN$4:AN$7493) -> 0 | CC22: =SUMIF(Recibos!$D$4:$D$7493,Cobranza!$B22,Recibos!AO$4:AO$7493) -> 0 | CD22: =SUMIF(Recibos!$D$4:$D$7493,Cobranza!$B22,Recibos!AP$4:AP$7493) -> 0 | CE22: =SUMIF(Recibos!$D$4:$D$7493,Cobranza!$B22,Recibos!AQ$4:AQ$7493) -> 0 | CF22: =SUMIF(Recibos!$D$4:$D$7493,Cobranza!$B22,Recibos!AR$4:AR$7493) -> 0 | ... CJ22: =SUMIF(Recibos!$D$4:$D$7493,Cobranza!$B22,Recibos!AV$4:AV$7493) -> 0 | CK22: =SUM(BY22:CJ22) -> 0
